Workbook

Sheet main
A1: Day | B1: Date | D1: 队 | E1: 剩步 | F1: 1 | G1: 2 | H1: 3 | I1: 4 | J1: 5 | K1: 6 | L1: 7 | M1: 8 | N1: 9 | O1: 10 | P1: 11 | Q1: 12 | R1: 13 | S1: 14 | T1: 15 | U1: 16 | V1: 17 | W1: 18 | X1: 19 | Y1: 20 | Z1: 21 | AA1: 22 | AB1: 23 | AC1: 24 | AD1: 25 | AE1: 跳 | AF1: Note
A2: 1 | B2: =INDEX(data!$I$2:$I$91,MATCH(A2*1,data!$G$2:$G$91,0)) -> 46185 | C2: =HYPERLINK("#'" & A2 & "'!A1", "编辑") -> 编辑 | D2: 1队 | E2: {=INDIRECT("'"&$A3&"'!I2")} -> 6 | F2: {=INDIRECT("'"&$A2&"'!C8")} -> 0 | G2: {=INDIRECT("'"&$A2&"'!D8")} -> 0 | H2: {=INDIRECT("'"&$A2&"'!E8")} -> 0 | I2: {=INDIRECT("'"&$A2&"'!F8")} -> 0 | J2: {=INDIRECT("'"&$A2&"'!G8")} -> 0 | K2: {=INDIRECT("'"&$A2&"'!H8")} -> 0 | L2: {=INDIRECT("'"&$A2&"'!I8")} -> 0 | M2: {=INDIRECT("'"&$A2&"'!J8")} -> 0 | N2: {=INDIRECT("'"&$A2&"'!K8")} -> 0 | O2: {=INDIRECT("'"&$A2&"'!L8")} -> 0 | P2: {=INDIRECT("'"&$A2&"'!M8")} -> 0 | Q2: {=INDIRECT("'"&$A2&"'!N8")} -> 0 | R2: {=INDIRECT("'"&$A2&"'!O8")} -> 0 | S2: {=INDIRECT("'"&$A2&"'!P8")} -> 0 | T2: {=INDIRECT("'"&$A2&"'!Q8")} -> 0 | U2: {=INDIRECT("'"&$A2&"'!R8")} -> 0 | V2: {=INDIRECT("'"&$A2&"'!S8")} -> 0 | W2: {=INDIRECT("'"&$A2&"'!T8")} -> 0 | X2: {=INDIRECT("'"&$A2&"'!U8")} -> 0 | Y2: {=INDIRECT("'"&$A2&"'!V8")} -> 0 | Z2: {=INDIRECT("'"&$A2&"'!W8")} -> 0 | AA2: {=INDIRECT("'"&$A2&"'!X8")} -> 0 | AB2: {=INDIRECT("'"&$A2&"'!Y8")} -> 0 | AC2: {=INDIRECT("'"&$A2&"'!Z8")} -> 0 | AD2: {=INDIRECT("'"&$A2&"'!AA8")} -> 0 | AE2: {=INDIRECT("'"&$A3&"'!J2")} -> 0 | AF2: {=INDIRECT("'"&$A3&"'!AD1")}
A3: 1 | C3: {=CONCATENATE("粮 ",INDIRECT("'"&$A3&"'!D4"))} -> 粮 6800 | D3: 2队 | E3: {=INDIRECT("'"&$A3&"'!I3")} -> 6 | F3: {=INDIRECT("'"&$A3&"'!C11")} -> 0 | G3: {=INDIRECT("'"&$A3&"'!D11")} -> 0 | H3: {=INDIRECT("'"&$A3&"'!E11")} -> 0 | I3: {=INDIRECT("'"&$A3&"'!F11")} -> 0 | J3: {=INDIRECT("'"&$A3&"'!G11")} -> 0 | K3: {=INDIRECT("'"&$A3&"'!H11")} -> 0 | L3: {=INDIRECT("'"&$A3&"'!I11")} -> 0 | M3: {=INDIRECT("'"&$A3&"'!J11")} -> 0 | N3: {=INDIRECT("'"&$A3&"'!K11")} -> 0 | O3: {=INDIRECT("'"&$A3&"'!L11")} -> 0 | P3: {=INDIRECT("'"&$A3&"'!M11")} -> 0 | Q3: {=INDIRECT("'"&$A3&"'!N11")} -> 0 | R3: {=INDIRECT("'"&$A3&"'!O11")} -> 0 | S3: {=INDIRECT("'"&$A3&"'!P11")} -> 0 | T3: {=INDIRECT("'"&$A3&"'!Q11")} -> 0 | U3: {=INDIRECT("'"&$A3&"'!R11")} -> 0 | V3: {=INDIRECT("'"&$A3&"'!S11")} -> 0 | W3: {=INDIRECT("'"&$A3&"'!T11")} -> 0 | X3: {=INDIRECT("'"&$A3&"'!U11")} -> 0 | Y3: {=INDIRECT("'"&$A3&"'!V11")} -> 0 | Z3: {=INDIRECT("'"&$A3&"'!W11")} -> 0 | AA3: {=INDIRECT("'"&$A3&"'!X11")} -> 0 | AB3: {=INDIRECT("'"&$A3&"'!Y11")} -> 0 | AC3: {=INDIRECT("'"&$A3&"'!Z11")} -> 0 | AD3: {=INDIRECT("'"&$A3&"'!AA11")} -> 0 | AE3: {=INDIRECT("'"&$A3&"'!J3")} -> 0 | AF3: {=INDIRECT("'"&$A3&"'!AC1")}
A4: 1 | C4: {=CONCATENATE("分 ",INDIRECT("'"&$A3&"'!D6"))} -> 分 0 | D4: 3队 | E4: {=INDIRECT("'"&$A3&"'!I4")} -> 6 | F4: {=INDIRECT("'"&$A4&"'!C14")} -> 0 | G4: {=INDIRECT("'"&$A4&"'!D14")} -> 0 | H4: {=INDIRECT("'"&$A4&"'!E14")} -> 0 | I4: {=INDIRECT("'"&$A4&"'!F14")} -> 0 | J4: {=INDIRECT("'"&$A4&"'!G14")} -> 0 | K4: {=INDIRECT("'"&$A4&"'!H14")} -> 0 | L4: {=INDIRECT("'"&$A4&"'!I14")} -> 0 | M4: {=INDIRECT("'"&$A4&"'!J14")} -> 0 | N4: {=INDIRECT("'"&$A4&"'!K14")} -> 0 | O4: {=INDIRECT("'"&$A4&"'!L14")} -> 0 | P4: {=INDIRECT("'"&$A4&"'!M14")} -> 0 | Q4: {=INDIRECT("'"&$A4&"'!N14")} -> 0 | R4: {=INDIRECT("'"&$A4&"'!O14")} -> 0 | S4: {=INDIRECT("'"&$A4&"'!P14")} -> 0 | T4: {=INDIRECT("'"&$A4&"'!Q14")} -> 0 | U4: {=INDIRECT("'"&$A4&"'!R14")} -> 0 | V4: {=INDIRECT("'"&$A4&"'!S14")} -> 0 | W4: {=INDIRECT("'"&$A4&"'!T14")} -> 0 | X4: {=INDIRECT("'"&$A4&"'!U14")} -> 0 | Y4: {=INDIRECT("'"&$A4&"'!V14")} -> 0 | Z4: {=INDIRECT("'"&$A4&"'!W14")} -> 0 | AA4: {=INDIRECT("'"&$A4&"'!X14")} -> 0 | AB4: {=INDIRECT("'"&$A4&"'!Y14")} -> 0 | AC4: {=INDIRECT("'"&$A4&"'!Z14")} -> 0 | AD4: {=INDIRECT("'"&$A4&"'!AA14")} -> 0 | AE4: {=INDIRECT("'"&$A3&"'!J4")} -> 0
A5: 2 | B5: =INDEX(data!$I$2:$I$91,MATCH(A5*1,data!$G$2:$G$91,0)) -> 46186 | C5: =HYPERLINK("#'" & A5 & "'!A1", "编辑") -> 编辑 | D5: 1队 | E5: {=INDIRECT("'"&$A6&"'!I2")} -> 12 | F5: {=INDIRECT("'"&$A5&"'!C8")} -> 0 | G5: {=INDIRECT("'"&$A5&"'!D8")} -> 0 | H5: {=INDIRECT("'"&$A5&"'!E8")} -> 0 | I5: {=INDIRECT("'"&$A5&"'!F8")} -> 0 | J5: {=INDIRECT("'"&$A5&"'!G8")} -> 0 | K5: {=INDIRECT("'"&$A5&"'!H8")} -> 0 | L5: {=INDIRECT("'"&$A5&"'!I8")} -> 0 | M5: {=INDIRECT("'"&$A5&"'!J8")} -> 0 | N5: {=INDIRECT("'"&$A5&"'!K8")} -> 0 | O5: {=INDIRECT("'"&$A5&"'!L8")} -> 0 | P5: {=INDIRECT("'"&$A5&"'!M8")} -> 0 | Q5: {=INDIRECT("'"&$A5&"'!N8")} -> 0 | R5: {=INDIRECT("'"&$A5&"'!O8")} -> 0 | S5: {=INDIRECT("'"&$A5&"'!P8")} -> 0 | T5: {=INDIRECT("'"&$A5&"'!Q8")} -> 0 | U5: {=INDIRECT("'"&$A5&"'!R8")} -> 0 | V5: {=INDIRECT("'"&$A5&"'!S8")} -> 0 | W5: {=INDIRECT("'"&$A5&"'!T8")} -> 0 | X5: {=INDIRECT("'"&$A5&"'!U8")} -> 0 | Y5: {=INDIRECT("'"&$A5&"'!V8")} -> 0 | Z5: {=INDIRECT("'"&$A5&"'!W8")} -> 0 | AA5: {=INDIRECT("'"&$A5&"'!X8")} -> 0 | AB5: {=INDIRECT("'"&$A5&"'!Y8")} -> 0 | AC5: {=INDIRECT("'"&$A5&"'!Z8")} -> 0 | AD5: {=INDIRECT("'"&$A5&"'!AA8")} -> 0 | AE5: {=INDIRECT("'"&$A6&"'!J2")} -> 0 | AF5: {=INDIRECT("'"&$A6&"'!AD1")}
A6: 2 | C6: {=CONCATENATE("粮 ",INDIRECT("'"&$A6&"'!D4"))} -> 粮 8400 | D6: 2队 | E6: {=INDIRECT("'"&$A6&"'!I3")} -> 12 | F6: {=INDIRECT("'"&$A6&"'!C11")} -> 0 | G6: {=INDIRECT("'"&$A6&"'!D11")} -> 0 | H6: {=INDIRECT("'"&$A6&"'!E11")} -> 0 | I6: {=INDIRECT("'"&$A6&"'!F11")} -> 0 | J6: {=INDIRECT("'"&$A6&"'!G11")} -> 0 | K6: {=INDIRECT("'"&$A6&"'!H11")} -> 0 | L6: {=INDIRECT("'"&$A6&"'!I11")} -> 0 | M6: {=INDIRECT("'"&$A6&"'!J11")} -> 0 | N6: {=INDIRECT("'"&$A6&"'!K11")} -> 0 | O6: {=INDIRECT("'"&$A6&"'!L11")} -> 0 | P6: {=INDIRECT("'"&$A6&"'!M11")} -> 0 | Q6: {=INDIRECT("'"&$A6&"'!N11")} -> 0 | R6: {=INDIRECT("'"&$A6&"'!O11")} -> 0 | S6: {=INDIRECT("'"&$A6&"'!P11")} -> 0 | T6: {=INDIRECT("'"&$A6&"'!Q11")} -> 0 | U6: {=INDIRECT("'"&$A6&"'!R11")} -> 0 | V6: {=INDIRECT("'"&$A6&"'!S11")} -> 0 | W6: {=INDIRECT("'"&$A6&"'!T11")} -> 0 | X6: {=INDIRECT("'"&$A6&"'!U11")} -> 0 | Y6: {=INDIRECT("'"&$A6&"'!V11")} -> 0 | Z6: {=INDIRECT("'"&$A6&"'!W11")} -> 0 | AA6: {=INDIRECT("'"&$A6&"'!X11")} -> 0 | AB6: {=INDIRECT("'"&$A6&"'!Y11")} -> 0 | AC6: {=INDIRECT("'"&$A6&"'!Z11")} -> 0 | AD6: {=INDIRECT("'"&$A6&"'!AA11")} -> 0 | AE6: {=INDIRECT("'"&$A6&"'!J3")} -> 0 | AF6: {=INDIRECT("'"&$A6&"'!AC1")}
A7: 2 | C7: {=CONCATENATE("分 ",INDIRECT("'"&$A6&"'!D6"))} -> 分 0 | D7: 3队 | E7: {=INDIRECT("'"&$A6&"'!I4")} -> 12 | F7: {=INDIRECT("'"&$A7&"'!C14")} -> 0 | G7: {=INDIRECT("'"&$A7&"'!D14")} -> 0 | H7: {=INDIRECT("'"&$A7&"'!E14")} -> 0 | I7: {=INDIRECT("'"&$A7&"'!F14")} -> 0 | J7: {=INDIRECT("'"&$A7&"'!G14")} -> 0 | K7: {=INDIRECT("'"&$A7&"'!H14")} -> 0 | L7: {=INDIRECT("'"&$A7&"'!I14")} -> 0 | M7: {=INDIRECT("'"&$A7&"'!J14")} -> 0 | N7: {=INDIRECT("'"&$A7&"'!K14")} -> 0 | O7: {=INDIRECT("'"&$A7&"'!L14")} -> 0 | P7: {=INDIRECT("'"&$A7&"'!M14")} -> 0 | Q7: {=INDIRECT("'"&$A7&"'!N14")} -> 0 | R7: {=INDIRECT("'"&$A7&"'!O14")} -> 0 | S7: {=INDIRECT("'"&$A7&"'!P14")} -> 0 | T7: {=INDIRECT("'"&$A7&"'!Q14")} -> 0 | U7: {=INDIRECT("'"&$A7&"'!R14")} -> 0 | V7: {=INDIRECT("'"&$A7&"'!S14")} -> 0 | W7: {=INDIRECT("'"&$A7&"'!T14")} -> 0 | X7: {=INDIRECT("'"&$A7&"'!U14")} -> 0 | Y7: {=INDIRECT("'"&$A7&"'!V14")} -> 0 | Z7: {=INDIRECT("'"&$A7&"'!W14")} -> 0 | AA7: {=INDIRECT("'"&$A7&"'!X14")} -> 0 | AB7: {=INDIRECT("'"&$A7&"'!Y14")} -> 0 | AC7: {=INDIRECT("'"&$A7&"'!Z14")} -> 0 | AD7: {=INDIRECT("'"&$A7&"'!AA14")} -> 0 | AE7: {=INDIRECT("'"&$A6&"'!J4")} -> 0
A8: 3 | B8: =INDEX(data!$I$2:$I$91,MATCH(A8*1,data!$G$2:$G$91,0)) -> 46187 | C8: =HYPERLINK("#'" & A8 & "'!A1", "编辑") -> 编辑 | D8: 1队 | E8: {=INDIRECT("'"&$A9&"'!I2")} -> 18 | F8: {=INDIRECT("'"&$A8&"'!C8")} -> 0 | G8: {=INDIRECT("'"&$A8&"'!D8")} -> 0 | H8: {=INDIRECT("'"&$A8&"'!E8")} -> 0 | I8: {=INDIRECT("'"&$A8&"'!F8")} -> 0 | J8: {=INDIRECT("'"&$A8&"'!G8")} -> 0 | K8: {=INDIRECT("'"&$A8&"'!H8")} -> 0 | L8: {=INDIRECT("'"&$A8&"'!I8")} -> 0 | M8: {=INDIRECT("'"&$A8&"'!J8")} -> 0 | N8: {=INDIRECT("'"&$A8&"'!K8")} -> 0 | O8: {=INDIRECT("'"&$A8&"'!L8")} -> 0 | P8: {=INDIRECT("'"&$A8&"'!M8")} -> 0 | Q8: {=INDIRECT("'"&$A8&"'!N8")} -> 0 | R8: {=INDIRECT("'"&$A8&"'!O8")} -> 0 | S8: {=INDIRECT("'"&$A8&"'!P8")} -> 0 | T8: {=INDIRECT("'"&$A8&"'!Q8")} -> 0 | U8: {=INDIRECT("'"&$A8&"'!R8")} -> 0 | V8: {=INDIRECT("'"&$A8&"'!S8")} -> 0 | W8: {=INDIRECT("'"&$A8&"'!T8")} -> 0 | X8: {=INDIRECT("'"&$A8&"'!U8")} -> 0 | Y8: {=INDIRECT("'"&$A8&"'!V8")} -> 0 | Z8: {=INDIRECT("'"&$A8&"'!W8")} -> 0 | AA8: {=INDIRECT("'"&$A8&"'!X8")} -> 0 | AB8: {=INDIRECT("'"&$A8&"'!Y8")} -> 0 | AC8: {=INDIRECT("'"&$A8&"'!Z8")} -> 0 | AD8: {=INDIRECT("'"&$A8&"'!AA8")} -> 0 | AE8: {=INDIRECT("'"&$A9&"'!J2")} -> 0 | AF8: {=INDIRECT("'"&$A9&"'!AD1")}
A9: 3 | C9: {=CONCATENATE("粮 ",INDIRECT("'"&$A9&"'!D4"))} -> 粮 10000 | D9: 2队 | E9: {=INDIRECT("'"&$A9&"'!I3")} -> 18 | F9: {=INDIRECT("'"&$A9&"'!C11")} -> 0 | G9: {=INDIRECT("'"&$A9&"'!D11")} -> 0 | H9: {=INDIRECT("'"&$A9&"'!E11")} -> 0 | I9: {=INDIRECT("'"&$A9&"'!F11")} -> 0 | J9: {=INDIRECT("'"&$A9&"'!G11")} -> 0 | K9: {=INDIRECT("'"&$A9&"'!H11")} -> 0 | L9: {=INDIRECT("'"&$A9&"'!I11")} -> 0 | M9: {=INDIRECT("'"&$A9&"'!J11")} -> 0 | N9: {=INDIRECT("'"&$A9&"'!K11")} -> 0 | O9: {=INDIRECT("'"&$A9&"'!L11")} -> 0 | P9: {=INDIRECT("'"&$A9&"'!M11")} -> 0 | Q9: {=INDIRECT("'"&$A9&"'!N11")} -> 0 | R9: {=INDIRECT("'"&$A9&"'!O11")} -> 0 | S9: {=INDIRECT("'"&$A9&"'!P11")} -> 0 | T9: {=INDIRECT("'"&$A9&"'!Q11")} -> 0 | U9: {=INDIRECT("'"&$A9&"'!R11")} -> 0 | V9: {=INDIRECT("'"&$A9&"'!S11")} -> 0 | W9: {=INDIRECT("'"&$A9&"'!T11")} -> 0 | X9: {=INDIRECT("'"&$A9&"'!U11")} -> 0 | Y9: {=INDIRECT("'"&$A9&"'!V11")} -> 0 | Z9: {=INDIRECT("'"&$A9&"'!W11")} -> 0 | AA9: {=INDIRECT("'"&$A9&"'!X11")} -> 0 | AB9: {=INDIRECT("'"&$A9&"'!Y11")} -> 0 | AC9: {=INDIRECT("'"&$A9&"'!Z11")} -> 0 | AD9: {=INDIRECT("'"&$A9&"'!AA11")} -> 0 | AE9: {=INDIRECT("'"&$A9&"'!J3")} -> 0 | AF9: {=INDIRECT("'"&$A9&"'!AC1")}
A10: 3 | C10: {=CONCATENATE("分 ",INDIRECT("'"&$A9&"'!D6"))} -> 分 0 | D10: 3队 | E10: {=INDIRECT("'"&$A9&"'!I4")} -> 23 | F10: {=INDIRECT("'"&$A10&"'!C14")} -> 0 | G10: {=INDIRECT("'"&$A10&"'!D14")} -> 0 | H10: {=INDIRECT("'"&$A10&"'!E14")} -> 0 | I10: {=INDIRECT("'"&$A10&"'!F14")} -> 0 | J10: {=INDIRECT("'"&$A10&"'!G14")} -> 0 | K10: {=INDIRECT("'"&$A10&"'!H14")} -> 0 | L10: {=INDIRECT("'"&$A10&"'!I14")} -> 0 | M10: {=INDIRECT("'"&$A10&"'!J14")} -> 0 | N10: {=INDIRECT("'"&$A10&"'!K14")} -> 0 | O10: {=INDIRECT("'"&$A10&"'!L14")} -> 0 | P10: {=INDIRECT("'"&$A10&"'!M14")} -> 0 | Q10: {=INDIRECT("'"&$A10&"'!N14")} -> 0 | R10: {=INDIRECT("'"&$A10&"'!O14")} -> 0 | S10: {=INDIRECT("'"&$A10&"'!P14")} -> 0 | T10: {=INDIRECT("'"&$A10&"'!Q14")} -> 0 | U10: {=INDIRECT("'"&$A10&"'!R14")} -> 0 | V10: {=INDIRECT("'"&$A10&"'!S14")} -> 0 | W10: {=INDIRECT("'"&$A10&"'!T14")} -> 0 | X10: {=INDIRECT("'"&$A10&"'!U14")} -> 0 | Y10: {=INDIRECT("'"&$A10&"'!V14")} -> 0 | Z10: {=INDIRECT("'"&$A10&"'!W14")} -> 0 | AA10: {=INDIRECT("'"&$A10&"'!X14")} -> 0 | AB10: {=INDIRECT("'"&$A10&"'!Y14")} -> 0 | AC10: {=INDIRECT("'"&$A10&"'!Z14")} -> 0 | AD10: {=INDIRECT("'"&$A10&"'!AA14")} -> 0 | AE10: {=INDIRECT("'"&$A9&"'!J4")} -> 0
A11: 4 | B11: =INDEX(data!$I$2:$I$91,MATCH(A11*1,data!$G$2:$G$91,0)) -> 46188 | C11: =HYPERLINK("#'" & A11 & "'!A1", "编辑") -> 编辑 | D11: 1队 | E11: {=INDIRECT("'"&$A12&"'!I2")} -> 18 | F11: {=INDIRECT("'"&$A11&"'!C8")} -> 0 | G11: {=INDIRECT("'"&$A11&"'!D8")} -> 0 | H11: {=INDIRECT("'"&$A11&"'!E8")} -> 0 | I11: {=INDIRECT("'"&$A11&"'!F8")} -> 0 | J11: {=INDIRECT("'"&$A11&"'!G8")} -> 0 | K11: {=INDIRECT("'"&$A11&"'!H8")} -> 0 | L11: {=INDIRECT("'"&$A11&"'!I8")} -> 0 | M11: {=INDIRECT("'"&$A11&"'!J8")} -> 0 | N11: {=INDIRECT("'"&$A11&"'!K8")} -> 0 | O11: {=INDIRECT("'"&$A11&"'!L8")} -> 0 | P11: {=INDIRECT("'"&$A11&"'!M8")} -> 0 | Q11: {=INDIRECT("'"&$A11&"'!N8")} -> 0 | R11: {=INDIRECT("'"&$A11&"'!O8")} -> 0 | S11: {=INDIRECT("'"&$A11&"'!P8")} -> 0 | T11: {=INDIRECT("'"&$A11&"'!Q8")} -> 0 | U11: {=INDIRECT("'"&$A11&"'!R8")} -> 0 | V11: {=INDIRECT("'"&$A11&"'!S8")} -> 0 | W11: {=INDIRECT("'"&$A11&"'!T8")} -> 0 | X11: {=INDIRECT("'"&$A11&"'!U8")} -> 0 | Y11: {=INDIRECT("'"&$A11&"'!V8")} -> 0 | Z11: {=INDIRECT("'"&$A11&"'!W8")} -> 0 | AA11: {=INDIRECT("'"&$A11&"'!X8")} -> 0 | AB11: {=INDIRECT("'"&$A11&"'!Y8")} -> 0 | AC11: {=INDIRECT("'"&$A11&"'!Z8")} -> 0 | AD11: {=INDIRECT("'"&$A11&"'!AA8")} -> 0 | AE11: {=INDIRECT("'"&$A12&"'!J2")} -> 0 | AF11: {=INDIRECT("'"&$A12&"'!AD1")}
A12: 4 | C12: {=CONCATENATE("粮 ",INDIRECT("'"&$A12&"'!D4"))} -> 粮 11600 | D12: 2队 | E12: {=INDIRECT("'"&$A12&"'!I3")} -> 18 | F12: {=INDIRECT("'"&$A12&"'!C11")} -> 0 | G12: {=INDIRECT("'"&$A12&"'!D11")} -> 0 | H12: {=INDIRECT("'"&$A12&"'!E11")} -> 0 | I12: {=INDIRECT("'"&$A12&"'!F11")} -> 0 | J12: {=INDIRECT("'"&$A12&"'!G11")} -> 0 | K12: {=INDIRECT("'"&$A12&"'!H11")} -> 0 | L12: {=INDIRECT("'"&$A12&"'!I11")} -> 0 | M12: {=INDIRECT("'"&$A12&"'!J11")} -> 0 | N12: {=INDIRECT("'"&$A12&"'!K11")} -> 0 | O12: {=INDIRECT("'"&$A12&"'!L11")} -> 0 | P12: {=INDIRECT("'"&$A12&"'!M11")} -> 0 | Q12: {=INDIRECT("'"&$A12&"'!N11")} -> 0 | R12: {=INDIRECT("'"&$A12&"'!O11")} -> 0 | S12: {=INDIRECT("'"&$A12&"'!P11")} -> 0 | T12: {=INDIRECT("'"&$A12&"'!Q11")} -> 0 | U12: {=INDIRECT("'"&$A12&"'!R11")} -> 0 | V12: {=INDIRECT("'"&$A12&"'!S11")} -> 0 | W12: {=INDIRECT("'"&$A12&"'!T11")} -> 0 | X12: {=INDIRECT("'"&$A12&"'!U11")} -> 0 | Y12: {=INDIRECT("'"&$A12&"'!V11")} -> 0 | Z12: {=INDIRECT("'"&$A12&"'!W11")} -> 0 | AA12: {=INDIRECT("'"&$A12&"'!X11")} -> 0 | AB12: {=INDIRECT("'"&$A12&"'!Y11")} -> 0 | AC12: {=INDIRECT("'"&$A12&"'!Z11")} -> 0 | AD12: {=INDIRECT("'"&$A12&"'!AA11")} -> 0 | AE12: {=INDIRECT("'"&$A12&"'!J3")} -> 0 | AF12: {=INDIRECT("'"&$A12&"'!AC1")}
A13: 4 | C13: {=CONCATENATE("分 ",INDIRECT("'"&$A12&"'!D6"))} -> 分 0 | D13: 3队 | E13: {=INDIRECT("'"&$A12&"'!I4")} -> 18 | F13: {=INDIRECT("'"&$A13&"'!C14")} -> 0 | G13: {=INDIRECT("'"&$A13&"'!D14")} -> 0 | H13: {=INDIRECT("'"&$A13&"'!E14")} -> 0 | I13: {=INDIRECT("'"&$A13&"'!F14")} -> 0 | J13: {=INDIRECT("'"&$A13&"'!G14")} -> 0 | K13: {=INDIRECT("'"&$A13&"'!H14")} -> 0 | L13: {=INDIRECT("'"&$A13&"'!I14")} -> 0 | M13: {=INDIRECT("'"&$A13&"'!J14")} -> 0 | N13: {=INDIRECT("'"&$A13&"'!K14")} -> 0 | O13: {=INDIRECT("'"&$A13&"'!L14")} -> 0 | P13: {=INDIRECT("'"&$A13&"'!M14")} -> 0 | Q13: {=INDIRECT("'"&$A13&"'!N14")} -> 0 | R13: {=INDIRECT("'"&$A13&"'!O14")} -> 0 | S13: {=INDIRECT("'"&$A13&"'!P14")} -> 0 | T13: {=INDIRECT("'"&$A13&"'!Q14")} -> 0 | U13: {=INDIRECT("'"&$A13&"'!R14")} -> 0 | V13: {=INDIRECT("'"&$A13&"'!S14")} -> 0 | W13: {=INDIRECT("'"&$A13&"'!T14")} -> 0 | X13: {=INDIRECT("'"&$A13&"'!U14")} -> 0 | Y13: {=INDIRECT("'"&$A13&"'!V14")} -> 0 | Z13: {=INDIRECT("'"&$A13&"'!W14")} -> 0 | AA13: {=INDIRECT("'"&$A13&"'!X14")} -> 0 | AB13: {=INDIRECT("'"&$A13&"'!Y14")} -> 0 | AC13: {=INDIRECT("'"&$A13&"'!Z14")} -> 0 | AD13: {=INDIRECT("'"&$A13&"'!AA14")} -> 0 | AE13: {=INDIRECT("'"&$A12&"'!J4")} -> 0
A14: 5 | B14: =INDEX(data!$I$2:$I$91,MATCH(A14*1,data!$G$2:$G$91,0)) -> 46189 | C14: =HYPERLINK("#'" & A14 & "'!A1", "编辑") -> 编辑 | D14: 1队 | E14: {=INDIRECT("'"&$A15&"'!I2")} -> 18 | F14: {=INDIRECT("'"&$A14&"'!C8")} -> 0 | G14: {=INDIRECT("'"&$A14&"'!D8")} -> 0 | H14: {=INDIRECT("'"&$A14&"'!E8")} -> 0 | I14: {=INDIRECT("'"&$A14&"'!F8")} -> 0 | J14: {=INDIRECT("'"&$A14&"'!G8")} -> 0 | K14: {=INDIRECT("'"&$A14&"'!H8")} -> 0 | L14: {=INDIRECT("'"&$A14&"'!I8")} -> 0 | M14: {=INDIRECT("'"&$A14&"'!J8")} -> 0 | N14: {=INDIRECT("'"&$A14&"'!K8")} -> 0 | O14: {=INDIRECT("'"&$A14&"'!L8")} -> 0 | P14: {=INDIRECT("'"&$A14&"'!M8")} -> 0 | Q14: {=INDIRECT("'"&$A14&"'!N8")} -> 0 | R14: {=INDIRECT("'"&$A14&"'!O8")} -> 0 | S14: {=INDIRECT("'"&$A14&"'!P8")} -> 0 | T14: {=INDIRECT("'"&$A14&"'!Q8")} -> 0 | U14: {=INDIRECT("'"&$A14&"'!R8")} -> 0 | V14: {=INDIRECT("'"&$A14&"'!S8")} -> 0 | W14: {=INDIRECT("'"&$A14&"'!T8")} -> 0 | X14: {=INDIRECT("'"&$A14&"'!U8")} -> 0 | Y14: {=INDIRECT("'"&$A14&"'!V8")} -> 0 | Z14: {=INDIRECT("'"&$A14&"'!W8")} -> 0 | AA14: {=INDIRECT("'"&$A14&"'!X8")} -> 0 | AB14: {=INDIRECT("'"&$A14&"'!Y8")} -> 0 | AC14: {=INDIRECT("'"&$A14&"'!Z8")} -> 0 | AD14: {=INDIRECT("'"&$A14&"'!AA8")} -> 0 | AE14: {=INDIRECT("'"&$A15&"'!J2")} -> 0 | AF14: {=INDIRECT("'"&$A15&"'!AD1")}
A15: 5 | C15: {=CONCATENATE("粮 ",INDIRECT("'"&$A15&"'!D4"))} -> 粮 13200 | D15: 2队 | E15: {=INDIRECT("'"&$A15&"'!I3")} -> 18 | F15: {=INDIRECT("'"&$A15&"'!C11")} -> 0 | G15: {=INDIRECT("'"&$A15&"'!D11")} -> 0 | H15: {=INDIRECT("'"&$A15&"'!E11")} -> 0 | I15: {=INDIRECT("'"&$A15&"'!F11")} -> 0 | J15: {=INDIRECT("'"&$A15&"'!G11")} -> 0 | K15: {=INDIRECT("'"&$A15&"'!H11")} -> 0 | L15: {=INDIRECT("'"&$A15&"'!I11")} -> 0 | M15: {=INDIRECT("'"&$A15&"'!J11")} -> 0 | N15: {=INDIRECT("'"&$A15&"'!K11")} -> 0 | O15: {=INDIRECT("'"&$A15&"'!L11")} -> 0 | P15: {=INDIRECT("'"&$A15&"'!M11")} -> 0 | Q15: {=INDIRECT("'"&$A15&"'!N11")} -> 0 | R15: {=INDIRECT("'"&$A15&"'!O11")} -> 0 | S15: {=INDIRECT("'"&$A15&"'!P11")} -> 0 | T15: {=INDIRECT("'"&$A15&"'!Q11")} -> 0 | U15: {=INDIRECT("'"&$A15&"'!R11")} -> 0 | V15: {=INDIRECT("'"&$A15&"'!S11")} -> 0 | W15: {=INDIRECT("'"&$A15&"'!T11")} -> 0 | X15: {=INDIRECT("'"&$A15&"'!U11")} -> 0 | Y15: {=INDIRECT("'"&$A15&"'!V11")} -> 0 | Z15: {=INDIRECT("'"&$A15&"'!W11")} -> 0 | AA15: {=INDIRECT("'"&$A15&"'!X11")} -> 0 | AB15: {=INDIRECT("'"&$A15&"'!Y11")} -> 0 | AC15: {=INDIRECT("'"&$A15&"'!Z11")} -> 0 | AD15: {=INDIRECT("'"&$A15&"'!AA11")} -> 0 | AE15: {=INDIRECT("'"&$A15&"'!J3")} -> 0 | AF15: {=INDIRECT("'"&$A15&"'!AC1")}
A16: 5 | C16: {=CONCATENATE("分 ",INDIRECT("'"&$A15&"'!D6"))} -> 分 0 | D16: 3队 | E16: {=INDIRECT("'"&$A15&"'!I4")} -> 18 | F16: {=INDIRECT("'"&$A16&"'!C14")} -> 0 | G16: {=INDIRECT("'"&$A16&"'!D14")} -> 0 | H16: {=INDIRECT("'"&$A16&"'!E14")} -> 0 | I16: {=INDIRECT("'"&$A16&"'!F14")} -> 0 | J16: {=INDIRECT("'"&$A16&"'!G14")} -> 0 | K16: {=INDIRECT("'"&$A16&"'!H14")} -> 0 | L16: {=INDIRECT("'"&$A16&"'!I14")} -> 0 | M16: {=INDIRECT("'"&$A16&"'!J14")} -> 0 | N16: {=INDIRECT("'"&$A16&"'!K14")} -> 0 | O16: {=INDIRECT("'"&$A16&"'!L14")} -> 0 | P16: {=INDIRECT("'"&$A16&"'!M14")} -> 0 | Q16: {=INDIRECT("'"&$A16&"'!N14")} -> 0 | R16: {=INDIRECT("'"&$A16&"'!O14")} -> 0 | S16: {=INDIRECT("'"&$A16&"'!P14")} -> 0 | T16: {=INDIRECT("'"&$A16&"'!Q14")} -> 0 | U16: {=INDIRECT("'"&$A16&"'!R14")} -> 0 | V16: {=INDIRECT("'"&$A16&"'!S14")} -> 0 | W16: {=INDIRECT("'"&$A16&"'!T14")} -> 0 | X16: {=INDIRECT("'"&$A16&"'!U14")} -> 0 | Y16: {=INDIRECT("'"&$A16&"'!V14")} -> 0 | Z16: {=INDIRECT("'"&$A16&"'!W14")} -> 0 | AA16: {=INDIRECT("'"&$A16&"'!X14")} -> 0 | AB16: {=INDIRECT("'"&$A16&"'!Y14")} -> 0 | AC16: {=INDIRECT("'"&$A16&"'!Z14")} -> 0 | AD16: {=INDIRECT("'"&$A16&"'!AA14")} -> 0 | AE16: {=INDIRECT("'"&$A15&"'!J4")} -> 0
A17: 6 | B17: =INDEX(data!$I$2:$I$91,MATCH(A17*1,data!$G$2:$G$91,0)) -> 46190 | C17: =HYPERLINK("#'" & A17 & "'!A1", "编辑") -> 编辑 | D17: 1队 | E17: {=INDIRECT("'"&$A18&"'!I2")} -> 18 | F17: {=INDIRECT("'"&$A17&"'!C8")} -> 0 | G17: {=INDIRECT("'"&$A17&"'!D8")} -> 0 | H17: {=INDIRECT("'"&$A17&"'!E8")} -> 0 | I17: {=INDIRECT("'"&$A17&"'!F8")} -> 0 | J17: {=INDIRECT("'"&$A17&"'!G8")} -> 0 | K17: {=INDIRECT("'"&$A17&"'!H8")} -> 0 | L17: {=INDIRECT("'"&$A17&"'!I8")} -> 0 | M17: {=INDIRECT("'"&$A17&"'!J8")} -> 0 | N17: {=INDIRECT("'"&$A17&"'!K8")} -> 0 | O17: {=INDIRECT("'"&$A17&"'!L8")} -> 0 | P17: {=INDIRECT("'"&$A17&"'!M8")} -> 0 | Q17: {=INDIRECT("'"&$A17&"'!N8")} -> 0 | R17: {=INDIRECT("'"&$A17&"'!O8")} -> 0 | S17: {=INDIRECT("'"&$A17&"'!P8")} -> 0 | T17: {=INDIRECT("'"&$A17&"'!Q8")} -> 0 | U17: {=INDIRECT("'"&$A17&"'!R8")} -> 0 | V17: {=INDIRECT("'"&$A17&"'!S8")} -> 0 | W17: {=INDIRECT("'"&$A17&"'!T8")} -> 0 | X17: {=INDIRECT("'"&$A17&"'!U8")} -> 0 | Y17: {=INDIRECT("'"&$A17&"'!V8")} -> 0 | Z17: {=INDIRECT("'"&$A17&"'!W8")} -> 0 | AA17: {=INDIRECT("'"&$A17&"'!X8")} -> 0 | AB17: {=INDIRECT("'"&$A17&"'!Y8")} -> 0 | AC17: {=INDIRECT("'"&$A17&"'!Z8")} -> 0 | AD17: {=INDIRECT("'"&$A17&"'!AA8")} -> 0 | AE17: {=INDIRECT("'"&$A18&"'!J2")} -> 0 | AF17: {=INDIRECT("'"&$A18&"'!AD1")}
A18: 6 | C18: {=CONCATENATE("粮 ",INDIRECT("'"&$A18&"'!D4"))} -> 粮 14800 | D18: 2队 | E18: {=INDIRECT("'"&$A18&"'!I3")} -> 18 | F18: {=INDIRECT("'"&$A18&"'!C11")} -> 0 | G18: {=INDIRECT("'"&$A18&"'!D11")} -> 0 | H18: {=INDIRECT("'"&$A18&"'!E11")} -> 0 | I18: {=INDIRECT("'"&$A18&"'!F11")} -> 0 | J18: {=INDIRECT("'"&$A18&"'!G11")} -> 0 | K18: {=INDIRECT("'"&$A18&"'!H11")} -> 0 | L18: {=INDIRECT("'"&$A18&"'!I11")} -> 0 | M18: {=INDIRECT("'"&$A18&"'!J11")} -> 0 | N18: {=INDIRECT("'"&$A18&"'!K11")} -> 0 | O18: {=INDIRECT("'"&$A18&"'!L11")} -> 0 | P18: {=INDIRECT("'"&$A18&"'!M11")} -> 0 | Q18: {=INDIRECT("'"&$A18&"'!N11")} -> 0 | R18: {=INDIRECT("'"&$A18&"'!O11")} -> 0 | S18: {=INDIRECT("'"&$A18&"'!P11")} -> 0 | T18: {=INDIRECT("'"&$A18&"'!Q11")} -> 0 | U18: {=INDIRECT("'"&$A18&"'!R11")} -> 0 | V18: {=INDIRECT("'"&$A18&"'!S11")} -> 0 | W18: {=INDIRECT("'"&$A18&"'!T11")} -> 0 | X18: {=INDIRECT("'"&$A18&"'!U11")} -> 0 | Y18: {=INDIRECT("'"&$A18&"'!V11")} -> 0 | Z18: {=INDIRECT("'"&$A18&"'!W11")} -> 0 | AA18: {=INDIRECT("'"&$A18&"'!X11")} -> 0 | AB18: {=INDIRECT("'"&$A18&"'!Y11")} -> 0 | AC18: {=INDIRECT("'"&$A18&"'!Z11")} -> 0 | AD18: {=INDIRECT("'"&$A18&"'!AA11")} -> 0 | AE18: {=INDIRECT("'"&$A18&"'!J3")} -> 0 | AF18: {=INDIRECT("'"&$A18&"'!AC1")}
A19: 6 | C19: {=CONCATENATE("分 ",INDIRECT("'"&$A18&"'!D6"))} -> 分 0 | D19: 3队 | E19: {=INDIRECT("'"&$A18&"'!I4")} -> 18 | F19: {=INDIRECT("'"&$A19&"'!C14")} -> 0 | G19: {=INDIRECT("'"&$A19&"'!D14")} -> 0 | H19: {=INDIRECT("'"&$A19&"'!E14")} -> 0 | I19: {=INDIRECT("'"&$A19&"'!F14")} -> 0 | J19: {=INDIRECT("'"&$A19&"'!G14")} -> 0 | K19: {=INDIRECT("'"&$A19&"'!H14")} -> 0 | L19: {=INDIRECT("'"&$A19&"'!I14")} -> 0 | M19: {=INDIRECT("'"&$A19&"'!J14")} -> 0 | N19: {=INDIRECT("'"&$A19&"'!K14")} -> 0 | O19: {=INDIRECT("'"&$A19&"'!L14")} -> 0 | P19: {=INDIRECT("'"&$A19&"'!M14")} -> 0 | Q19: {=INDIRECT("'"&$A19&"'!N14")} -> 0 | R19: {=INDIRECT("'"&$A19&"'!O14")} -> 0 | S19: {=INDIRECT("'"&$A19&"'!P14")} -> 0 | T19: {=INDIRECT("'"&$A19&"'!Q14")} -> 0 | U19: {=INDIRECT("'"&$A19&"'!R14")} -> 0 | V19: {=INDIRECT("'"&$A19&"'!S14")} -> 0 | W19: {=INDIRECT("'"&$A19&"'!T14")} -> 0 | X19: {=INDIRECT("'"&$A19&"'!U14")} -> 0 | Y19: {=INDIRECT("'"&$A19&"'!V14")} -> 0 | Z19: {=INDIRECT("'"&$A19&"'!W14")} -> 0 | AA19: {=INDIRECT("'"&$A19&"'!X14")} -> 0 | AB19: {=INDIRECT("'"&$A19&"'!Y14")} -> 0 | AC19: {=INDIRECT("'"&$A19&"'!Z14")} -> 0 | AD19: {=INDIRECT("'"&$A19&"'!AA14")} -> 0 | AE19: {=INDIRECT("'"&$A18&"'!J4")} -> 0
A20: 7 | B20: =INDEX(data!$I$2:$I$91,MATCH(A20*1,data!$G$2:$G$91,0)) -> 46191 | C20: =HYPERLINK("#'" & A20 & "'!A1", "编辑") -> 编辑 | D20: 1队 | E20: {=INDIRECT("'"&$A21&"'!I2")} -> 18 | F20: {=INDIRECT("'"&$A20&"'!C8")} -> 0 | G20: {=INDIRECT("'"&$A20&"'!D8")} -> 0 | H20: {=INDIRECT("'"&$A20&"'!E8")} -> 0 | I20: {=INDIRECT("'"&$A20&"'!F8")} -> 0 | J20: {=INDIRECT("'"&$A20&"'!G8")} -> 0 | K20: {=INDIRECT("'"&$A20&"'!H8")} -> 0 | L20: {=INDIRECT("'"&$A20&"'!I8")} -> 0 | M20: {=INDIRECT("'"&$A20&"'!J8")} -> 0 | N20: {=INDIRECT("'"&$A20&"'!K8")} -> 0 | O20: {=INDIRECT("'"&$A20&"'!L8")} -> 0 | P20: {=INDIRECT("'"&$A20&"'!M8")} -> 0 | Q20: {=INDIRECT("'"&$A20&"'!N8")} -> 0 | R20: {=INDIRECT("'"&$A20&"'!O8")} -> 0 | S20: {=INDIRECT("'"&$A20&"'!P8")} -> 0 | T20: {=INDIRECT("'"&$A20&"'!Q8")} -> 0 | U20: {=INDIRECT("'"&$A20&"'!R8")} -> 0 | V20: {=INDIRECT("'"&$A20&"'!S8")} -> 0 | W20: {=INDIRECT("'"&$A20&"'!T8")} -> 0 | X20: {=INDIRECT("'"&$A20&"'!U8")} -> 0 | Y20: {=INDIRECT("'"&$A20&"'!V8")} -> 0 | Z20: {=INDIRECT("'"&$A20&"'!W8")} -> 0 | AA20: {=INDIRECT("'"&$A20&"'!X8")} -> 0 | AB20: {=INDIRECT("'"&$A20&"'!Y8")} -> 0 | AC20: {=INDIRECT("'"&$A20&"'!Z8")} -> 0 | AD20: {=INDIRECT("'"&$A20&"'!AA8")} -> 0 | AE20: {=INDIRECT("'"&$A21&"'!J2")} -> 0 | AF20: {=INDIRECT("'"&$A21&"'!AD1")}
A21: 7 | C21: {=CONCATENATE("粮 ",INDIRECT("'"&$A21&"'!D4"))} -> 粮 16400 | D21: 2队 | E21: {=INDIRECT("'"&$A21&"'!I3")} -> 18 | F21: {=INDIRECT("'"&$A21&"'!C11")} -> 0 | G21: {=INDIRECT("'"&$A21&"'!D11")} -> 0 | H21: {=INDIRECT("'"&$A21&"'!E11")} -> 0 | I21: {=INDIRECT("'"&$A21&"'!F11")} -> 0 | J21: {=INDIRECT("'"&$A21&"'!G11")} -> 0 | K21: {=INDIRECT("'"&$A21&"'!H11")} -> 0 | L21: {=INDIRECT("'"&$A21&"'!I11")} -> 0 | M21: {=INDIRECT("'"&$A21&"'!J11")} -> 0 | N21: {=INDIRECT("'"&$A21&"'!K11")} -> 0 | O21: {=INDIRECT("'"&$A21&"'!L11")} -> 0 | P21: {=INDIRECT("'"&$A21&"'!M11")} -> 0 | Q21: {=INDIRECT("'"&$A21&"'!N11")} -> 0 | R21: {=INDIRECT("'"&$A21&"'!O11")} -> 0 | S21: {=INDIRECT("'"&$A21&"'!P11")} -> 0 | T21: {=INDIRECT("'"&$A21&"'!Q11")} -> 0 | U21: {=INDIRECT("'"&$A21&"'!R11")} -> 0 | V21: {=INDIRECT("'"&$A21&"'!S11")} -> 0 | W21: {=INDIRECT("'"&$A21&"'!T11")} -> 0 | X21: {=INDIRECT("'"&$A21&"'!U11")} -> 0 | Y21: {=INDIRECT("'"&$A21&"'!V11")} -> 0 | Z21: {=INDIRECT("'"&$A21&"'!W11")} -> 0 | AA21: {=INDIRECT("'"&$A21&"'!X11")} -> 0 | AB21: {=INDIRECT("'"&$A21&"'!Y11")} -> 0 | AC21: {=INDIRECT("'"&$A21&"'!Z11")} -> 0 | AD21: {=INDIRECT("'"&$A21&"'!AA11")} -> 0 | AE21: {=INDIRECT("'"&$A21&"'!J3")} -> 0 | AF21: {=INDIRECT("'"&$A21&"'!AC1")}
A22: 7 | C22: {=CONCATENATE("分 ",INDIRECT("'"&$A21&"'!D6"))} -> 分 0 | D22: 3队 | E22: {=INDIRECT("'"&$A21&"'!I4")} -> 18 | F22: {=INDIRECT("'"&$A22&"'!C14")} -> 0 | G22: {=INDIRECT("'"&$A22&"'!D14")} -> 0 | H22: {=INDIRECT("'"&$A22&"'!E14")} -> 0 | I22: {=INDIRECT("'"&$A22&"'!F14")} -> 0 | J22: {=INDIRECT("'"&$A22&"'!G14")} -> 0 | K22: {=INDIRECT("'"&$A22&"'!H14")} -> 0 | L22: {=INDIRECT("'"&$A22&"'!I14")} -> 0 | M22: {=INDIRECT("'"&$A22&"'!J14")} -> 0 | N22: {=INDIRECT("'"&$A22&"'!K14")} -> 0 | O22: {=INDIRECT("'"&$A22&"'!L14")} -> 0 | P22: {=INDIRECT("'"&$A22&"'!M14")} -> 0 | Q22: {=INDIRECT("'"&$A22&"'!N14")} -> 0 | R22: {=INDIRECT("'"&$A22&"'!O14")} -> 0 | S22: {=INDIRECT("'"&$A22&"'!P14")} -> 0 | T22: {=INDIRECT("'"&$A22&"'!Q14")} -> 0 | U22: {=INDIRECT("'"&$A22&"'!R14")} -> 0 | V22: {=INDIRECT("'"&$A22&"'!S14")} -> 0 | W22: {=INDIRECT("'"&$A22&"'!T14")} -> 0 | X22: {=INDIRECT("'"&$A22&"'!U14")} -> 0 | Y22: {=INDIRECT("'"&$A22&"'!V14")} -> 0 | Z22: {=INDIRECT("'"&$A22&"'!W14")} -> 0 | AA22: {=INDIRECT("'"&$A22&"'!X14")} -> 0 | AB22: {=INDIRECT("'"&$A22&"'!Y14")} -> 0 | AC22: {=INDIRECT("'"&$A22&"'!Z14")} -> 0 | AD22: {=INDIRECT("'"&$A22&"'!AA14")} -> 0 | AE22: {=INDIRECT("'"&$A21&"'!J4")} -> 0
A23: 8 | B23: =INDEX(data!$I$2:$I$91,MATCH(A23*1,data!$G$2:$G$91,0)) -> 46192 | C23: =HYPERLINK("#'" & A23 & "'!A1", "编辑") -> 编辑 | D23: 1队 | E23: {=INDIRECT("'"&$A24&"'!I2")} -> 18 | F23: {=INDIRECT("'"&$A23&"'!C8")} -> 0 | G23: {=INDIRECT("'"&$A23&"'!D8")} -> 0 | H23: {=INDIRECT("'"&$A23&"'!E8")} -> 0 | I23: {=INDIRECT("'"&$A23&"'!F8")} -> 0 | J23: {=INDIRECT("'"&$A23&"'!G8")} -> 0 | K23: {=INDIRECT("'"&$A23&"'!H8")} -> 0 | L23: {=INDIRECT("'"&$A23&"'!I8")} -> 0 | M23: {=INDIRECT("'"&$A23&"'!J8")} -> 0 | N23: {=INDIRECT("'"&$A23&"'!K8")} -> 0 | O23: {=INDIRECT("'"&$A23&"'!L8")} -> 0 | P23: {=INDIRECT("'"&$A23&"'!M8")} -> 0 | Q23: {=INDIRECT("'"&$A23&"'!N8")} -> 0 | R23: {=INDIRECT("'"&$A23&"'!O8")} -> 0 | S23: {=INDIRECT("'"&$A23&"'!P8")} -> 0 | T23: {=INDIRECT("'"&$A23&"'!Q8")} -> 0 | U23: {=INDIRECT("'"&$A23&"'!R8")} -> 0 | V23: {=INDIRECT("'"&$A23&"'!S8")} -> 0 | W23: {=INDIRECT("'"&$A23&"'!T8")} -> 0 | X23: {=INDIRECT("'"&$A23&"'!U8")} -> 0 | Y23: {=INDIRECT("'"&$A23&"'!V8")} -> 0 | Z23: {=INDIRECT("'"&$A23&"'!W8")} -> 0 | AA23: {=INDIRECT("'"&$A23&"'!X8")} -> 0 | AB23: {=INDIRECT("'"&$A23&"'!Y8")} -> 0 | AC23: {=INDIRECT("'"&$A23&"'!Z8")} -> 0 | AD23: {=INDIRECT("'"&$A23&"'!AA8")} -> 0 | AE23: {=INDIRECT("'"&$A24&"'!J2")} -> 0 | AF23: {=INDIRECT("'"&$A24&"'!AD1")}
A24: 8 | C24: {=CONCATENATE("粮 ",INDIRECT("'"&$A24&"'!D4"))} -> 粮 18000 | D24: 2队 | E24: {=INDIRECT("'"&$A24&"'!I3")} -> 18 | F24: {=INDIRECT("'"&$A24&"'!C11")} -> 0 | G24: {=INDIRECT("'"&$A24&"'!D11")} -> 0 | H24: {=INDIRECT("'"&$A24&"'!E11")} -> 0 | I24: {=INDIRECT("'"&$A24&"'!F11")} -> 0 | J24: {=INDIRECT("'"&$A24&"'!G11")} -> 0 | K24: {=INDIRECT("'"&$A24&"'!H11")} -> 0 | L24: {=INDIRECT("'"&$A24&"'!I11")} -> 0 | M24: {=INDIRECT("'"&$A24&"'!J11")} -> 0 | N24: {=INDIRECT("'"&$A24&"'!K11")} -> 0 | O24: {=INDIRECT("'"&$A24&"'!L11")} -> 0 | P24: {=INDIRECT("'"&$A24&"'!M11")} -> 0 | Q24: {=INDIRECT("'"&$A24&"'!N11")} -> 0 | R24: {=INDIRECT("'"&$A24&"'!O11")} -> 0 | S24: {=INDIRECT("'"&$A24&"'!P11")} -> 0 | T24: {=INDIRECT("'"&$A24&"'!Q11")} -> 0 | U24: {=INDIRECT("'"&$A24&"'!R11")} -> 0 | V24: {=INDIRECT("'"&$A24&"'!S11")} -> 0 | W24: {=INDIRECT("'"&$A24&"'!T11")} -> 0 | X24: {=INDIRECT("'"&$A24&"'!U11")} -> 0 | Y24: {=INDIRECT("'"&$A24&"'!V11")} -> 0 | Z24: {=INDIRECT("'"&$A24&"'!W11")} -> 0 | AA24: {=INDIRECT("'"&$A24&"'!X11")} -> 0 | AB24: {=INDIRECT("'"&$A24&"'!Y11")} -> 0 | AC24: {=INDIRECT("'"&$A24&"'!Z11")} -> 0 | AD24: {=INDIRECT("'"&$A24&"'!AA11")} -> 0 | AE24: {=INDIRECT("'"&$A24&"'!J3")} -> 0 | AF24: {=INDIRECT("'"&$A24&"'!AC1")}
A25: 8 | C25: {=CONCATENATE("分 ",INDIRECT("'"&$A24&"'!D6"))} -> 分 0 | D25: 3队 | E25: {=INDIRECT("'"&$A24&"'!I4")} -> 18 | F25: {=INDIRECT("'"&$A25&"'!C14")} -> 0 | G25: {=INDIRECT("'"&$A25&"'!D14")} -> 0 | H25: {=INDIRECT("'"&$A25&"'!E14")} -> 0 | I25: {=INDIRECT("'"&$A25&"'!F14")} -> 0 | J25: {=INDIRECT("'"&$A25&"'!G14")} -> 0 | K25: {=INDIRECT("'"&$A25&"'!H14")} -> 0 | L25: {=INDIRECT("'"&$A25&"'!I14")} -> 0 | M25: {=INDIRECT("'"&$A25&"'!J14")} -> 0 | N25: {=INDIRECT("'"&$A25&"'!K14")} -> 0 | O25: {=INDIRECT("'"&$A25&"'!L14")} -> 0 | P25: {=INDIRECT("'"&$A25&"'!M14")} -> 0 | Q25: {=INDIRECT("'"&$A25&"'!N14")} -> 0 | R25: {=INDIRECT("'"&$A25&"'!O14")} -> 0 | S25: {=INDIRECT("'"&$A25&"'!P14")} -> 0 | T25: {=INDIRECT("'"&$A25&"'!Q14")} -> 0 | U25: {=INDIRECT("'"&$A25&"'!R14")} -> 0 | V25: {=INDIRECT("'"&$A25&"'!S14")} -> 0 | W25: {=INDIRECT("'"&$A25&"'!T14")} -> 0 | X25: {=INDIRECT("'"&$A25&"'!U14")} -> 0 | Y25: {=INDIRECT("'"&$A25&"'!V14")} -> 0 | Z25: {=INDIRECT("'"&$A25&"'!W14")} -> 0 | AA25: {=INDIRECT("'"&$A25&"'!X14")} -> 0 | AB25: {=INDIRECT("'"&$A25&"'!Y14")} -> 0 | AC25: {=INDIRECT("'"&$A25&"'!Z14")} -> 0 | AD25: {=INDIRECT("'"&$A25&"'!AA14")} -> 0 | AE25: {=INDIRECT("'"&$A24&"'!J4")} -> 0
A26: 9 | B26: =INDEX(data!$I$2:$I$91,MATCH(A26*1,data!$G$2:$G$91,0)) -> 46193 | C26: =HYPERLINK("#'" & A26 & "'!A1", "编辑") -> 编辑 | D26: 1队 | E26: {=INDIRECT("'"&$A27&"'!I2")} -> 18 | F26: {=INDIRECT("'"&$A26&"'!C8")} -> 0 | G26: {=INDIRECT("'"&$A26&"'!D8")} -> 0 | H26: {=INDIRECT("'"&$A26&"'!E8")} -> 0 | I26: {=INDIRECT("'"&$A26&"'!F8")} -> 0 | J26: {=INDIRECT("'"&$A26&"'!G8")} -> 0 | K26: {=INDIRECT("'"&$A26&"'!H8")} -> 0 | L26: {=INDIRECT("'"&$A26&"'!I8")} -> 0 | M26: {=INDIRECT("'"&$A26&"'!J8")} -> 0 | N26: {=INDIRECT("'"&$A26&"'!K8")} -> 0 | O26: {=INDIRECT("'"&$A26&"'!L8")} -> 0 | P26: {=INDIRECT("'"&$A26&"'!M8")} -> 0 | Q26: {=INDIRECT("'"&$A26&"'!N8")} -> 0 | R26: {=INDIRECT("'"&$A26&"'!O8")} -> 0 | S26: {=INDIRECT("'"&$A26&"'!P8")} -> 0 | T26: {=INDIRECT("'"&$A26&"'!Q8")} -> 0 | U26: {=INDIRECT("'"&$A26&"'!R8")} -> 0 | V26: {=INDIRECT("'"&$A26&"'!S8")} -> 0 | W26: {=INDIRECT("'"&$A26&"'!T8")} -> 0 | X26: {=INDIRECT("'"&$A26&"'!U8")} -> 0 | Y26: {=INDIRECT("'"&$A26&"'!V8")} -> 0 | Z26: {=INDIRECT("'"&$A26&"'!W8")} -> 0 | AA26: {=INDIRECT("'"&$A26&"'!X8")} -> 0 | AB26: {=INDIRECT("'"&$A26&"'!Y8")} -> 0 | AC26: {=INDIRECT("'"&$A26&"'!Z8")} -> 0 | AD26: {=INDIRECT("'"&$A26&"'!AA8")} -> 0 | AE26: {=INDIRECT("'"&$A27&"'!J2")} -> 0 | AF26: {=INDIRECT("'"&$A27&"'!AD1")}
A27: 9 | C27: {=CONCATENATE("粮 ",INDIRECT("'"&$A27&"'!D4"))} -> 粮 19600 | D27: 2队 | E27: {=INDIRECT("'"&$A27&"'!I3")} -> 18 | F27: {=INDIRECT("'"&$A27&"'!C11")} -> 0 | G27: {=INDIRECT("'"&$A27&"'!D11")} -> 0 | H27: {=INDIRECT("'"&$A27&"'!E11")} -> 0 | I27: {=INDIRECT("'"&$A27&"'!F11")} -> 0 | J27: {=INDIRECT("'"&$A27&"'!G11")} -> 0 | K27: {=INDIRECT("'"&$A27&"'!H11")} -> 0 | L27: {=INDIRECT("'"&$A27&"'!I11")} -> 0 | M27: {=INDIRECT("'"&$A27&"'!J11")} -> 0 | N27: {=INDIRECT("'"&$A27&"'!K11")} -> 0 | O27: {=INDIRECT("'"&$A27&"'!L11")} -> 0 | P27: {=INDIRECT("'"&$A27&"'!M11")} -> 0 | Q27: {=INDIRECT("'"&$A27&"'!N11")} -> 0 | R27: {=INDIRECT("'"&$A27&"'!O11")} -> 0 | S27: {=INDIRECT("'"&$A27&"'!P11")} -> 0 | T27: {=INDIRECT("'"&$A27&"'!Q11")} -> 0 | U27: {=INDIRECT("'"&$A27&"'!R11")} -> 0 | V27: {=INDIRECT("'"&$A27&"'!S11")} -> 0 | W27: {=INDIRECT("'"&$A27&"'!T11")} -> 0 | X27: {=INDIRECT("'"&$A27&"'!U11")} -> 0 | Y27: {=INDIRECT("'"&$A27&"'!V11")} -> 0 | Z27: {=INDIRECT("'"&$A27&"'!W11")} -> 0 | AA27: {=INDIRECT("'"&$A27&"'!X11")} -> 0 | AB27: {=INDIRECT("'"&$A27&"'!Y11")} -> 0 | AC27: {=INDIRECT("'"&$A27&"'!Z11")} -> 0 | AD27: {=INDIRECT("'"&$A27&"'!AA11")} -> 0 | AE27: {=INDIRECT("'"&$A27&"'!J3")} -> 0 | AF27: {=INDIRECT("'"&$A27&"'!AC1")}
A28: 9 | C28: {=CONCATENATE("分 ",INDIRECT("'"&$A27&"'!D6"))} -> 分 0 | D28: 3队 | E28: {=INDIRECT("'"&$A27&"'!I4")} -> 18 | F28: {=INDIRECT("'"&$A28&"'!C14")} -> 0 | G28: {=INDIRECT("'"&$A28&"'!D14")} -> 0 | H28: {=INDIRECT("'"&$A28&"'!E14")} -> 0 | I28: {=INDIRECT("'"&$A28&"'!F14")} -> 0 | J28: {=INDIRECT("'"&$A28&"'!G14")} -> 0 | K28: {=INDIRECT("'"&$A28&"'!H14")} -> 0 | L28: {=INDIRECT("'"&$A28&"'!I14")} -> 0 | M28: {=INDIRECT("'"&$A28&"'!J14")} -> 0 | N28: {=INDIRECT("'"&$A28&"'!K14")} -> 0 | O28: {=INDIRECT("'"&$A28&"'!L14")} -> 0 | P28: {=INDIRECT("'"&$A28&"'!M14")} -> 0 | Q28: {=INDIRECT("'"&$A28&"'!N14")} -> 0 | R28: {=INDIRECT("'"&$A28&"'!O14")} -> 0 | S28: {=INDIRECT("'"&$A28&"'!P14")} -> 0 | T28: {=INDIRECT("'"&$A28&"'!Q14")} -> 0 | U28: {=INDIRECT("'"&$A28&"'!R14")} -> 0 | V28: {=INDIRECT("'"&$A28&"'!S14")} -> 0 | W28: {=INDIRECT("'"&$A28&"'!T14")} -> 0 | X28: {=INDIRECT("'"&$A28&"'!U14")} -> 0 | Y28: {=INDIRECT("'"&$A28&"'!V14")} -> 0 | Z28: {=INDIRECT("'"&$A28&"'!W14")} -> 0 | AA28: {=INDIRECT("'"&$A28&"'!X14")} -> 0 | AB28: {=INDIRECT("'"&$A28&"'!Y14")} -> 0 | AC28: {=INDIRECT("'"&$A28&"'!Z14")} -> 0 | AD28: {=INDIRECT("'"&$A28&"'!AA14")} -> 0 | AE28: {=INDIRECT("'"&$A27&"'!J4")} -> 0
A29: 10 | B29: =INDEX(data!$I$2:$I$91,MATCH(A29*1,data!$G$2:$G$91,0)) -> 46194 | C29: =HYPERLINK("#'" & A29 & "'!A1", "编辑") -> 编辑 | D29: 1队 | E29: {=INDIRECT("'"&$A30&"'!I2")} -> 18 | F29: {=INDIRECT("'"&$A29&"'!C8")} -> 0 | G29: {=INDIRECT("'"&$A29&"'!D8")} -> 0 | H29: {=INDIRECT("'"&$A29&"'!E8")} -> 0 | I29: {=INDIRECT("'"&$A29&"'!F8")} -> 0 | J29: {=INDIRECT("'"&$A29&"'!G8")} -> 0 | K29: {=INDIRECT("'"&$A29&"'!H8")} -> 0 | L29: {=INDIRECT("'"&$A29&"'!I8")} -> 0 | M29: {=INDIRECT("'"&$A29&"'!J8")} -> 0 | N29: {=INDIRECT("'"&$A29&"'!K8")} -> 0 | O29: {=INDIRECT("'"&$A29&"'!L8")} -> 0 | P29: {=INDIRECT("'"&$A29&"'!M8")} -> 0 | Q29: {=INDIRECT("'"&$A29&"'!N8")} -> 0 | R29: {=INDIRECT("'"&$A29&"'!O8")} -> 0 | S29: {=INDIRECT("'"&$A29&"'!P8")} -> 0 | T29: {=INDIRECT("'"&$A29&"'!Q8")} -> 0 | U29: {=INDIRECT("'"&$A29&"'!R8")} -> 0 | V29: {=INDIRECT("'"&$A29&"'!S8")} -> 0 | W29: {=INDIRECT("'"&$A29&"'!T8")} -> 0 | X29: {=INDIRECT("'"&$A29&"'!U8")} -> 0 | Y29: {=INDIRECT("'"&$A29&"'!V8")} -> 0 | Z29: {=INDIRECT("'"&$A29&"'!W8")} -> 0 | AA29: {=INDIRECT("'"&$A29&"'!X8")} -> 0 | AB29: {=INDIRECT("'"&$A29&"'!Y8")} -> 0 | AC29: {=INDIRECT("'"&$A29&"'!Z8")} -> 0 | AD29: {=INDIRECT("'"&$A29&"'!AA8")} -> 0 | AE29: {=INDIRECT("'"&$A30&"'!J2")} -> 0 | AF29: {=INDIRECT("'"&$A30&"'!AD1")}
A30: 10 | C30: {=CONCATENATE("粮 ",INDIRECT("'"&$A30&"'!D4"))} -> 粮 21200 | D30: 2队 | E30: {=INDIRECT("'"&$A30&"'!I3")} -> 18 | F30: {=INDIRECT("'"&$A30&"'!C11")} -> 0 | G30: {=INDIRECT("'"&$A30&"'!D11")} -> 0 | H30: {=INDIRECT("'"&$A30&"'!E11")} -> 0 | I30: {=INDIRECT("'"&$A30&"'!F11")} -> 0 | J30: {=INDIRECT("'"&$A30&"'!G11")} -> 0 | K30: {=INDIRECT("'"&$A30&"'!H11")} -> 0 | L30: {=INDIRECT("'"&$A30&"'!I11")} -> 0 | M30: {=INDIRECT("'"&$A30&"'!J11")} -> 0 | N30: {=INDIRECT("'"&$A30&"'!K11")} -> 0 | O30: {=INDIRECT("'"&$A30&"'!L11")} -> 0 | P30: {=INDIRECT("'"&$A30&"'!M11")} -> 0 | Q30: {=INDIRECT("'"&$A30&"'!N11")} -> 0 | R30: {=INDIRECT("'"&$A30&"'!O11")} -> 0 | S30: {=INDIRECT("'"&$A30&"'!P11")} -> 0 | T30: {=INDIRECT("'"&$A30&"'!Q11")} -> 0 | U30: {=INDIRECT("'"&$A30&"'!R11")} -> 0 | V30: {=INDIRECT("'"&$A30&"'!S11")} -> 0 | W30: {=INDIRECT("'"&$A30&"'!T11")} -> 0 | X30: {=INDIRECT("'"&$A30&"'!U11")} -> 0 | Y30: {=INDIRECT("'"&$A30&"'!V11")} -> 0 | Z30: {=INDIRECT("'"&$A30&"'!W11")} -> 0 | AA30: {=INDIRECT("'"&$A30&"'!X11")} -> 0 | AB30: {=INDIRECT("'"&$A30&"'!Y11")} -> 0 | AC30: {=INDIRECT("'"&$A30&"'!Z11")} -> 0 | AD30: {=INDIRECT("'"&$A30&"'!AA11")} -> 0 | AE30: {=INDIRECT("'"&$A30&"'!J3")} -> 0 | AF30: {=INDIRECT("'"&$A30&"'!AC1")}
A31: 10 | C31: {=CONCATENATE("分 ",INDIRECT("'"&$A30&"'!D6"))} -> 分 0 | D31: 3队 | E31: {=INDIRECT("'"&$A30&"'!I4")} -> 18 | F31: {=INDIRECT("'"&$A31&"'!C14")} -> 0 | G31: {=INDIRECT("'"&$A31&"'!D14")} -> 0 | H31: {=INDIRECT("'"&$A31&"'!E14")} -> 0 | I31: {=INDIRECT("'"&$A31&"'!F14")} -> 0 | J31: {=INDIRECT("'"&$A31&"'!G14")} -> 0 | K31: {=INDIRECT("'"&$A31&"'!H14")} -> 0 | L31: {=INDIRECT("'"&$A31&"'!I14")} -> 0 | M31: {=INDIRECT("'"&$A31&"'!J14")} -> 0 | N31: {=INDIRECT("'"&$A31&"'!K14")} -> 0 | O31: {=INDIRECT("'"&$A31&"'!L14")} -> 0 | P31: {=INDIRECT("'"&$A31&"'!M14")} -> 0 | Q31: {=INDIRECT("'"&$A31&"'!N14")} -> 0 | R31: {=INDIRECT("'"&$A31&"'!O14")} -> 0 | S31: {=INDIRECT("'"&$A31&"'!P14")} -> 0 | T31: {=INDIRECT("'"&$A31&"'!Q14")} -> 0 | U31: {=INDIRECT("'"&$A31&"'!R14")} -> 0 | V31: {=INDIRECT("'"&$A31&"'!S14")} -> 0 | W31: {=INDIRECT("'"&$A31&"'!T14")} -> 0 | X31: {=INDIRECT("'"&$A31&"'!U14")} -> 0 | Y31: {=INDIRECT("'"&$A31&"'!V14")} -> 0 | Z31: {=INDIRECT("'"&$A31&"'!W14")} -> 0 | AA31: {=INDIRECT("'"&$A31&"'!X14")} -> 0 | AB31: {=INDIRECT("'"&$A31&"'!Y14")} -> 0 | AC31: {=INDIRECT("'"&$A31&"'!Z14")} -> 0 | AD31: {=INDIRECT("'"&$A31&"'!AA14")} -> 0 | AE31: {=INDIRECT("'"&$A30&"'!J4")} -> 0
A32: 11 | B32: =INDEX(data!$I$2:$I$91,MATCH(A32*1,data!$G$2:$G$91,0)) -> 46195 | C32: =HYPERLINK("#'" & A32 & "'!A1", "编辑") -> 编辑 | D32: 1队 | E32: {=INDIRECT("'"&$A33&"'!I2")} -> 18 | F32: {=INDIRECT("'"&$A32&"'!C8")} -> 0 | G32: {=INDIRECT("'"&$A32&"'!D8")} -> 0 | H32: {=INDIRECT("'"&$A32&"'!E8")} -> 0 | I32: {=INDIRECT("'"&$A32&"'!F8")} -> 0 | J32: {=INDIRECT("'"&$A32&"'!G8")} -> 0 | K32: {=INDIRECT("'"&$A32&"'!H8")} -> 0 | L32: {=INDIRECT("'"&$A32&"'!I8")} -> 0 | M32: {=INDIRECT("'"&$A32&"'!J8")} -> 0 | N32: {=INDIRECT("'"&$A32&"'!K8")} -> 0 | O32: {=INDIRECT("'"&$A32&"'!L8")} -> 0 | P32: {=INDIRECT("'"&$A32&"'!M8")} -> 0 | Q32: {=INDIRECT("'"&$A32&"'!N8")} -> 0 | R32: {=INDIRECT("'"&$A32&"'!O8")} -> 0 | S32: {=INDIRECT("'"&$A32&"'!P8")} -> 0 | T32: {=INDIRECT("'"&$A32&"'!Q8")} -> 0 | U32: {=INDIRECT("'"&$A32&"'!R8")} -> 0 | V32: {=INDIRECT("'"&$A32&"'!S8")} -> 0 | W32: {=INDIRECT("'"&$A32&"'!T8")} -> 0 | X32: {=INDIRECT("'"&$A32&"'!U8")} -> 0 | Y32: {=INDIRECT("'"&$A32&"'!V8")} -> 0 | Z32: {=INDIRECT("'"&$A32&"'!W8")} -> 0 | AA32: {=INDIRECT("'"&$A32&"'!X8")} -> 0 | AB32: {=INDIRECT("'"&$A32&"'!Y8")} -> 0 | AC32: {=INDIRECT("'"&$A32&"'!Z8")} -> 0 | AD32: {=INDIRECT("'"&$A32&"'!AA8")} -> 0 | AE32: {=INDIRECT("'"&$A33&"'!J2")} -> 0 | AF32: {=INDIRECT("'"&$A33&"'!AD1")}
A33: 11 | C33: {=CONCATENATE("粮 ",INDIRECT("'"&$A33&"'!D4"))} -> 粮 22800 | D33: 2队 | E33: {=INDIRECT("'"&$A33&"'!I3")} -> 18 | F33: {=INDIRECT("'"&$A33&"'!C11")} -> 0 | G33: {=INDIRECT("'"&$A33&"'!D11")} -> 0 | H33: {=INDIRECT("'"&$A33&"'!E11")} -> 0 | I33: {=INDIRECT("'"&$A33&"'!F11")} -> 0 | J33: {=INDIRECT("'"&$A33&"'!G11")} -> 0 | K33: {=INDIRECT("'"&$A33&"'!H11")} -> 0 | L33: {=INDIRECT("'"&$A33&"'!I11")} -> 0 | M33: {=INDIRECT("'"&$A33&"'!J11")} -> 0 | N33: {=INDIRECT("'"&$A33&"'!K11")} -> 0 | O33: {=INDIRECT("'"&$A33&"'!L11")} -> 0 | P33: {=INDIRECT("'"&$A33&"'!M11")} -> 0 | Q33: {=INDIRECT("'"&$A33&"'!N11")} -> 0 | R33: {=INDIRECT("'"&$A33&"'!O11")} -> 0 | S33: {=INDIRECT("'"&$A33&"'!P11")} -> 0 | T33: {=INDIRECT("'"&$A33&"'!Q11")} -> 0 | U33: {=INDIRECT("'"&$A33&"'!R11")} -> 0 | V33: {=INDIRECT("'"&$A33&"'!S11")} -> 0 | W33: {=INDIRECT("'"&$A33&"'!T11")} -> 0 | X33: {=INDIRECT("'"&$A33&"'!U11")} -> 0 | Y33: {=INDIRECT("'"&$A33&"'!V11")} -> 0 | Z33: {=INDIRECT("'"&$A33&"'!W11")} -> 0 | AA33: {=INDIRECT("'"&$A33&"'!X11")} -> 0 | AB33: {=INDIRECT("'"&$A33&"'!Y11")} -> 0 | AC33: {=INDIRECT("'"&$A33&"'!Z11")} -> 0 | AD33: {=INDIRECT("'"&$A33&"'!AA11")} -> 0 | AE33: {=INDIRECT("'"&$A33&"'!J3")} -> 0 | AF33: {=INDIRECT("'"&$A33&"'!AC1")}
A34: 11 | C34: {=CONCATENATE("分 ",INDIRECT("'"&$A33&"'!D6"))} -> 分 0 | D34: 3队 | E34: {=INDIRECT("'"&$A33&"'!I4")} -> 18 | F34: {=INDIRECT("'"&$A34&"'!C14")} -> 0 | G34: {=INDIRECT("'"&$A34&"'!D14")} -> 0 | H34: {=INDIRECT("'"&$A34&"'!E14")} -> 0 | I34: {=INDIRECT("'"&$A34&"'!F14")} -> 0 | J34: {=INDIRECT("'"&$A34&"'!G14")} -> 0 | K34: {=INDIRECT("'"&$A34&"'!H14")} -> 0 | L34: {=INDIRECT("'"&$A34&"'!I14")} -> 0 | M34: {=INDIRECT("'"&$A34&"'!J14")} -> 0 | N34: {=INDIRECT("'"&$A34&"'!K14")} -> 0 | O34: {=INDIRECT("'"&$A34&"'!L14")} -> 0 | P34: {=INDIRECT("'"&$A34&"'!M14")} -> 0 | Q34: {=INDIRECT("'"&$A34&"'!N14")} -> 0 | R34: {=INDIRECT("'"&$A34&"'!O14")} -> 0 | S34: {=INDIRECT("'"&$A34&"'!P14")} -> 0 | T34: {=INDIRECT("'"&$A34&"'!Q14")} -> 0 | U34: {=INDIRECT("'"&$A34&"'!R14")} -> 0 | V34: {=INDIRECT("'"&$A34&"'!S14")} -> 0 | W34: {=INDIRECT("'"&$A34&"'!T14")} -> 0 | X34: {=INDIRECT("'"&$A34&"'!U14")} -> 0 | Y34: {=INDIRECT("'"&$A34&"'!V14")} -> 0 | Z34: {=INDIRECT("'"&$A34&"'!W14")} -> 0 | AA34: {=INDIRECT("'"&$A34&"'!X14")} -> 0 | AB34: {=INDIRECT("'"&$A34&"'!Y14")} -> 0 | AC34: {=INDIRECT("'"&$A34&"'!Z14")} -> 0 | AD34: {=INDIRECT("'"&$A34&"'!AA14")} -> 0 | AE34: {=INDIRECT("'"&$A33&"'!J4")} -> 0
A35: 12 | B35: =INDEX(data!$I$2:$I$91,MATCH(A35*1,data!$G$2:$G$91,0)) -> 46196 | C35: =HYPERLINK("#'" & A35 & "'!A1", "编辑") -> 编辑 | D35: 1队 | E35: {=INDIRECT("'"&$A36&"'!I2")} -> 18 | F35: {=INDIRECT("'"&$A35&"'!C8")} -> 0 | G35: {=INDIRECT("'"&$A35&"'!D8")} -> 0 | H35: {=INDIRECT("'"&$A35&"'!E8")} -> 0 | I35: {=INDIRECT("'"&$A35&"'!F8")} -> 0 | J35: {=INDIRECT("'"&$A35&"'!G8")} -> 0 | K35: {=INDIRECT("'"&$A35&"'!H8")} -> 0 | L35: {=INDIRECT("'"&$A35&"'!I8")} -> 0 | M35: {=INDIRECT("'"&$A35&"'!J8")} -> 0 | N35: {=INDIRECT("'"&$A35&"'!K8")} -> 0 | O35: {=INDIRECT("'"&$A35&"'!L8")} -> 0 | P35: {=INDIRECT("'"&$A35&"'!M8")} -> 0 | Q35: {=INDIRECT("'"&$A35&"'!N8")} -> 0 | R35: {=INDIRECT("'"&$A35&"'!O8")} -> 0 | S35: {=INDIRECT("'"&$A35&"'!P8")} -> 0 | T35: {=INDIRECT("'"&$A35&"'!Q8")} -> 0 | U35: {=INDIRECT("'"&$A35&"'!R8")} -> 0 | V35: {=INDIRECT("'"&$A35&"'!S8")} -> 0 | W35: {=INDIRECT("'"&$A35&"'!T8")} -> 0 | X35: {=INDIRECT("'"&$A35&"'!U8")} -> 0 | Y35: {=INDIRECT("'"&$A35&"'!V8")} -> 0 | Z35: {=INDIRECT("'"&$A35&"'!W8")} -> 0 | AA35: {=INDIRECT("'"&$A35&"'!X8")} -> 0 | AB35: {=INDIRECT("'"&$A35&"'!Y8")} -> 0 | AC35: {=INDIRECT("'"&$A35&"'!Z8")} -> 0 | AD35: {=INDIRECT("'"&$A35&"'!AA8")} -> 0 | AE35: {=INDIRECT("'"&$A36&"'!J2")} -> 0 | AF35: {=INDIRECT("'"&$A36&"'!AD1")}
A36: 12 | C36: {=CONCATENATE("粮 ",INDIRECT("'"&$A36&"'!D4"))} -> 粮 24400 | D36: 2队 | E36: {=INDIRECT("'"&$A36&"'!I3")} -> 18 | F36: {=INDIRECT("'"&$A36&"'!C11")} -> 0 | G36: {=INDIRECT("'"&$A36&"'!D11")} -> 0 | H36: {=INDIRECT("'"&$A36&"'!E11")} -> 0 | I36: {=INDIRECT("'"&$A36&"'!F11")} -> 0 | J36: {=INDIRECT("'"&$A36&"'!G11")} -> 0 | K36: {=INDIRECT("'"&$A36&"'!H11")} -> 0 | L36: {=INDIRECT("'"&$A36&"'!I11")} -> 0 | M36: {=INDIRECT("'"&$A36&"'!J11")} -> 0 | N36: {=INDIRECT("'"&$A36&"'!K11")} -> 0 | O36: {=INDIRECT("'"&$A36&"'!L11")} -> 0 | P36: {=INDIRECT("'"&$A36&"'!M11")} -> 0 | Q36: {=INDIRECT("'"&$A36&"'!N11")} -> 0 | R36: {=INDIRECT("'"&$A36&"'!O11")} -> 0 | S36: {=INDIRECT("'"&$A36&"'!P11")} -> 0 | T36: {=INDIRECT("'"&$A36&"'!Q11")} -> 0 | U36: {=INDIRECT("'"&$A36&"'!R11")} -> 0 | V36: {=INDIRECT("'"&$A36&"'!S11")} -> 0 | W36: {=INDIRECT("'"&$A36&"'!T11")} -> 0 | X36: {=INDIRECT("'"&$A36&"'!U11")} -> 0 | Y36: {=INDIRECT("'"&$A36&"'!V11")} -> 0 | Z36: {=INDIRECT("'"&$A36&"'!W11")} -> 0 | AA36: {=INDIRECT("'"&$A36&"'!X11")} -> 0 | AB36: {=INDIRECT("'"&$A36&"'!Y11")} -> 0 | AC36: {=INDIRECT("'"&$A36&"'!Z11")} -> 0 | AD36: {=INDIRECT("'"&$A36&"'!AA11")} -> 0 | AE36: {=INDIRECT("'"&$A36&"'!J3")} -> 0 | AF36: {=INDIRECT("'"&$A36&"'!AC1")}
A37: 12 | C37: {=CONCATENATE("分 ",INDIRECT("'"&$A36&"'!D6"))} -> 分 0 | D37: 3队 | E37: {=INDIRECT("'"&$A36&"'!I4")} -> 18 | F37: {=INDIRECT("'"&$A37&"'!C14")} -> 0 | G37: {=INDIRECT("'"&$A37&"'!D14")} -> 0 | H37: {=INDIRECT("'"&$A37&"'!E14")} -> 0 | I37: {=INDIRECT("'"&$A37&"'!F14")} -> 0 | J37: {=INDIRECT("'"&$A37&"'!G14")} -> 0 | K37: {=INDIRECT("'"&$A37&"'!H14")} -> 0 | L37: {=INDIRECT("'"&$A37&"'!I14")} -> 0 | M37: {=INDIRECT("'"&$A37&"'!J14")} -> 0 | N37: {=INDIRECT("'"&$A37&"'!K14")} -> 0 | O37: {=INDIRECT("'"&$A37&"'!L14")} -> 0 | P37: {=INDIRECT("'"&$A37&"'!M14")} -> 0 | Q37: {=INDIRECT("'"&$A37&"'!N14")} -> 0 | R37: {=INDIRECT("'"&$A37&"'!O14")} -> 0 | S37: {=INDIRECT("'"&$A37&"'!P14")} -> 0 | T37: {=INDIRECT("'"&$A37&"'!Q14")} -> 0 | U37: {=INDIRECT("'"&$A37&"'!R14")} -> 0 | V37: {=INDIRECT("'"&$A37&"'!S14")} -> 0 | W37: {=INDIRECT("'"&$A37&"'!T14")} -> 0 | X37: {=INDIRECT("'"&$A37&"'!U14")} -> 0 | Y37: {=INDIRECT("'"&$A37&"'!V14")} -> 0 | Z37: {=INDIRECT("'"&$A37&"'!W14")} -> 0 | AA37: {=INDIRECT("'"&$A37&"'!X14")} -> 0 | AB37: {=INDIRECT("'"&$A37&"'!Y14")} -> 0 | AC37: {=INDIRECT("'"&$A37&"'!Z14")} -> 0 | AD37: {=INDIRECT("'"&$A37&"'!AA14")} -> 0 | AE37: {=INDIRECT("'"&$A36&"'!J4")} -> 0
A38: 13 | B38: =INDEX(data!$I$2:$I$91,MATCH(A38*1,data!$G$2:$G$91,0)) -> 46197 | C38: =HYPERLINK("#'" & A38 & "'!A1", "编辑") -> 编辑 | D38: 1队 | E38: {=INDIRECT("'"&$A39&"'!I2")} -> 18 | F38: {=INDIRECT("'"&$A38&"'!C8")} -> 0 | G38: {=INDIRECT("'"&$A38&"'!D8")} -> 0 | H38: {=INDIRECT("'"&$A38&"'!E8")} -> 0 | I38: {=INDIRECT("'"&$A38&"'!F8")} -> 0 | J38: {=INDIRECT("'"&$A38&"'!G8")} -> 0 | K38: {=INDIRECT("'"&$A38&"'!H8")} -> 0 | L38: {=INDIRECT("'"&$A38&"'!I8")} -> 0 | M38: {=INDIRECT("'"&$A38&"'!J8")} -> 0 | N38: {=INDIRECT("'"&$A38&"'!K8")} -> 0 | O38: {=INDIRECT("'"&$A38&"'!L8")} -> 0 | P38: {=INDIRECT("'"&$A38&"'!M8")} -> 0 | Q38: {=INDIRECT("'"&$A38&"'!N8")} -> 0 | R38: {=INDIRECT("'"&$A38&"'!O8")} -> 0 | S38: {=INDIRECT("'"&$A38&"'!P8")} -> 0 | T38: {=INDIRECT("'"&$A38&"'!Q8")} -> 0 | U38: {=INDIRECT("'"&$A38&"'!R8")} -> 0 | V38: {=INDIRECT("'"&$A38&"'!S8")} -> 0 | W38: {=INDIRECT("'"&$A38&"'!T8")} -> 0 | X38: {=INDIRECT("'"&$A38&"'!U8")} -> 0 | Y38: {=INDIRECT("'"&$A38&"'!V8")} -> 0 | Z38: {=INDIRECT("'"&$A38&"'!W8")} -> 0 | AA38: {=INDIRECT("'"&$A38&"'!X8")} -> 0 | AB38: {=INDIRECT("'"&$A38&"'!Y8")} -> 0 | AC38: {=INDIRECT("'"&$A38&"'!Z8")} -> 0 | AD38: {=INDIRECT("'"&$A38&"'!AA8")} -> 0 | AE38: {=INDIRECT("'"&$A39&"'!J2")} -> 0 | AF38: {=INDIRECT("'"&$A39&"'!AD1")}
A39: 13 | C39: {=CONCATENATE("粮 ",INDIRECT("'"&$A39&"'!D4"))} -> 粮 26000 | D39: 2队 | E39: {=INDIRECT("'"&$A39&"'!I3")} -> 18 | F39: {=INDIRECT("'"&$A39&"'!C11")} -> 0 | G39: {=INDIRECT("'"&$A39&"'!D11")} -> 0 | H39: {=INDIRECT("'"&$A39&"'!E11")} -> 0 | I39: {=INDIRECT("'"&$A39&"'!F11")} -> 0 | J39: {=INDIRECT("'"&$A39&"'!G11")} -> 0 | K39: {=INDIRECT("'"&$A39&"'!H11")} -> 0 | L39: {=INDIRECT("'"&$A39&"'!I11")} -> 0 | M39: {=INDIRECT("'"&$A39&"'!J11")} -> 0 | N39: {=INDIRECT("'"&$A39&"'!K11")} -> 0 | O39: {=INDIRECT("'"&$A39&"'!L11")} -> 0 | P39: {=INDIRECT("'"&$A39&"'!M11")} -> 0 | Q39: {=INDIRECT("'"&$A39&"'!N11")} -> 0 | R39: {=INDIRECT("'"&$A39&"'!O11")} -> 0 | S39: {=INDIRECT("'"&$A39&"'!P11")} -> 0 | T39: {=INDIRECT("'"&$A39&"'!Q11")} -> 0 | U39: {=INDIRECT("'"&$A39&"'!R11")} -> 0 | V39: {=INDIRECT("'"&$A39&"'!S11")} -> 0 | W39: {=INDIRECT("'"&$A39&"'!T11")} -> 0 | X39: {=INDIRECT("'"&$A39&"'!U11")} -> 0 | Y39: {=INDIRECT("'"&$A39&"'!V11")} -> 0 | Z39: {=INDIRECT("'"&$A39&"'!W11")} -> 0 | AA39: {=INDIRECT("'"&$A39&"'!X11")} -> 0 | AB39: {=INDIRECT("'"&$A39&"'!Y11")} -> 0 | AC39: {=INDIRECT("'"&$A39&"'!Z11")} -> 0 | AD39: {=INDIRECT("'"&$A39&"'!AA11")} -> 0 | AE39: {=INDIRECT("'"&$A39&"'!J3")} -> 0 | AF39: {=INDIRECT("'"&$A39&"'!AC1")}
A40: 13 | C40: {=CONCATENATE("分 ",INDIRECT("'"&$A39&"'!D6"))} -> 分 0 | D40: 3队 | E40: {=INDIRECT("'"&$A39&"'!I4")} -> 18 | F40: {=INDIRECT("'"&$A40&"'!C14")} -> 0 | G40: {=INDIRECT("'"&$A40&"'!D14")} -> 0 | H40: {=INDIRECT("'"&$A40&"'!E14")} -> 0 | I40: {=INDIRECT("'"&$A40&"'!F14")} -> 0 | J40: {=INDIRECT("'"&$A40&"'!G14")} -> 0 | K40: {=INDIRECT("'"&$A40&"'!H14")} -> 0 | L40: {=INDIRECT("'"&$A40&"'!I14")} -> 0 | M40: {=INDIRECT("'"&$A40&"'!J14")} -> 0 | N40: {=INDIRECT("'"&$A40&"'!K14")} -> 0 | O40: {=INDIRECT("'"&$A40&"'!L14")} -> 0 | P40: {=INDIRECT("'"&$A40&"'!M14")} -> 0 | Q40: {=INDIRECT("'"&$A40&"'!N14")} -> 0 | R40: {=INDIRECT("'"&$A40&"'!O14")} -> 0 | S40: {=INDIRECT("'"&$A40&"'!P14")} -> 0 | T40: {=INDIRECT("'"&$A40&"'!Q14")} -> 0 | U40: {=INDIRECT("'"&$A40&"'!R14")} -> 0 | V40: {=INDIRECT("'"&$A40&"'!S14")} -> 0 | W40: {=INDIRECT("'"&$A40&"'!T14")} -> 0 | X40: {=INDIRECT("'"&$A40&"'!U14")} -> 0 | Y40: {=INDIRECT("'"&$A40&"'!V14")} -> 0 | Z40: {=INDIRECT("'"&$A40&"'!W14")} -> 0 | AA40: {=INDIRECT("'"&$A40&"'!X14")} -> 0 | AB40: {=INDIRECT("'"&$A40&"'!Y14")} -> 0 | AC40: {=INDIRECT("'"&$A40&"'!Z14")} -> 0 | AD40: {=INDIRECT("'"&$A40&"'!AA14")} -> 0 | AE40: {=INDIRECT("'"&$A39&"'!J4")} -> 0
...

Sheet data
B1: 粮草 | C1: 经验 | D1: 行动 | E1: 已占领 | G1: day | H1: 张鹏 | I1: date | L1: 兵粮buff | M1: 减粮草 | N1: 战勋buff | O1: 加经验 | R1: 兵粮buff | S1: 减粮草 | T1: 战勋buff | U1: 加经验
A2: 1级 | B2: 150 | C2: 35 | D2: 1 | E2: =COUNTIF(main!$F$2:$AD$271,data!A2) -> 0 | G2: 1 | H2: 300 | I2: 46185 | K2: 1 | L2: 5级 | M2: =IF(L2="",0,(INDEX($B$2:$B$27,MATCH(L2,$A$2:$A$27,0))-50)*(0.4)) -> 56 | N2: 中boss | O2: =IF(N2="",0,INDEX($C$2:$C$27,MATCH(N2,$A$2:$A$27,0))*0.4) -> 200 | Q2: 1 | R2: 2级 | S2: =IF(R2="",0,(INDEX($B$2:$B$27,MATCH(R2,$A$2:$A$27,0))-50)*(0.4)) -> 44 | T2: 历练 | U2: =IF(T2="",0,INDEX($C$2:$C$27,MATCH(T2,$A$2:$A$27,0))*0.4) -> 208
A3: 2级 | B3: 160 | C3: 40 | D3: 1 | E3: =COUNTIF(main!$F$2:$AD$271,data!A3) -> 0 | G3: 2 | H3: 300 | I3: 46186 | K3: 2 | L3: 5级 | M3: =IF(L3="",0,(INDEX($B$2:$B$27,MATCH(L3,$A$2:$A$27,0))-50)*(0.4)) -> 56 | N3: 大boss | O3: =IF(N3="",0,INDEX($C$2:$C$27,MATCH(N3,$A$2:$A$27,0))*0.4) -> 400 | Q3: 2 | R3: 2级 | S3: =IF(R3="",0,(INDEX($B$2:$B$27,MATCH(R3,$A$2:$A$27,0))-50)*(0.4)) -> 44 | U3: =IF(T3="",0,INDEX($C$2:$C$27,MATCH(T3,$A$2:$A$27,0))*0.4) -> 0
A4: 3级 | B4: 170 | C4: 45 | D4: 1 | E4: =COUNTIF(main!$F$2:$AD$271,data!A4) -> 0 | G4: 3 | H4: 300 | I4: 46187 | K4: 3 | L4: 5级 | M4: =IF(L4="",0,(INDEX($B$2:$B$27,MATCH(L4,$A$2:$A$27,0))-50)*(0.4)) -> 56 | N4: 大boss | O4: =IF(N4="",0,INDEX($C$2:$C$27,MATCH(N4,$A$2:$A$27,0))*0.4) -> 400 | Q4: 3 | R4: 2级 | S4: =IF(R4="",0,(INDEX($B$2:$B$27,MATCH(R4,$A$2:$A$27,0))-50)*(0.4)) -> 44 | T4: 3级 | U4: =IF(T4="",0,INDEX($C$2:$C$27,MATCH(T4,$A$2:$A$27,0))*0.4) -> 18
A5: 4级 | B5: 180 | C5: 50 | D5: 1 | E5: =COUNTIF(main!$F$2:$AD$271,data!A5) -> 0 | G5: 4 | H5: 300 | I5: 46188 | K5: 4 | L5: 6级 | M5: =IF(L5="",0,(INDEX($B$2:$B$27,MATCH(L5,$A$2:$A$27,0))-50)*(0.4)) -> 60 | N5: 历练 | O5: =IF(N5="",0,INDEX($C$2:$C$27,MATCH(N5,$A$2:$A$27,0))*0.4) -> 208 | Q5: 4 | R5: 2级 | S5: =IF(R5="",0,(INDEX($B$2:$B$27,MATCH(R5,$A$2:$A$27,0))-50)*(0.4)) -> 44 | T5: 大卦 | U5: =IF(T5="",0,INDEX($C$2:$C$27,MATCH(T5,$A$2:$A$27,0))*0.4) -> 120
A6: 5级 | B6: 190 | C6: 55 | D6: 1 | E6: =COUNTIF(main!$F$2:$AD$271,data!A6) -> 0 | G6: 5 | H6: 300 | I6: 46189 | K6: 5 | L6: 6级 | M6: =IF(L6="",0,(INDEX($B$2:$B$27,MATCH(L6,$A$2:$A$27,0))-50)*(0.4)) -> 60 | N6: 历练 | O6: =IF(N6="",0,INDEX($C$2:$C$27,MATCH(N6,$A$2:$A$27,0))*0.4) -> 208 | Q6: 5 | R6: 草2 | S6: =IF(R6="",0,(INDEX($B$2:$B$27,MATCH(R6,$A$2:$A$27,0))-50)*(0.4)) -> 40 | T6: 3级 | U6: =IF(T6="",0,INDEX($C$2:$C$27,MATCH(T6,$A$2:$A$27,0))*0.4) -> 18
A7: 6级 | B7: 200 | C7: 60 | D7: 1 | E7: =COUNTIF(main!$F$2:$AD$271,data!A7) -> 0 | G7: 6 | H7: 300 | I7: 46190 | K7: 6 | L7: 6级 | M7: =IF(L7="",0,(INDEX($B$2:$B$27,MATCH(L7,$A$2:$A$27,0))-50)*(0.4)) -> 60 | N7: 中boss | O7: =IF(N7="",0,INDEX($C$2:$C$27,MATCH(N7,$A$2:$A$27,0))*0.4) -> 200 | Q7: 6 | S7: =IF(R7="",0,(INDEX($B$2:$B$27,MATCH(R7,$A$2:$A$27,0))-50)*(0.4)) -> 0 | T7: 大卦 | U7: =IF(T7="",0,INDEX($C$2:$C$27,MATCH(T7,$A$2:$A$27,0))*0.4) -> 120
A8: 草1 | B8: 150 | C8: 35 | D8: 1 | E8: =COUNTIF(main!$F$2:$AD$271,data!A8) -> 0 | G8: 7 | H8: 300 | I8: 46191 | K8: 7 | L8: 6级 | M8: =IF(L8="",0,(INDEX($B$2:$B$27,MATCH(L8,$A$2:$A$27,0))-50)*(0.4)) -> 60 | N8: 6级 | O8: =IF(N8="",0,INDEX($C$2:$C$27,MATCH(N8,$A$2:$A$27,0))*0.4) -> 24 | Q8: 7 | S8: =IF(R8="",0,(INDEX($B$2:$B$27,MATCH(R8,$A$2:$A$27,0))-50)*(0.4)) -> 0 | T8: 3级 | U8: =IF(T8="",0,INDEX($C$2:$C$27,MATCH(T8,$A$2:$A$27,0))*0.4) -> 18
A9: 草2 | B9: 150 | C9: 40 | D9: 1 | E9: =COUNTIF(main!$F$2:$AD$271,data!A9) -> 0 | G9: 8 | H9: 300 | I9: 46192 | K9: 8 | L9: 6级 | M9: =IF(L9="",0,(INDEX($B$2:$B$27,MATCH(L9,$A$2:$A$27,0))-50)*(0.4)) -> 60 | N9: 6级 | O9: =IF(N9="",0,INDEX($C$2:$C$27,MATCH(N9,$A$2:$A$27,0))*0.4) -> 24 | Q9: 8 | S9: =IF(R9="",0,(INDEX($B$2:$B$27,MATCH(R9,$A$2:$A$27,0))-50)*(0.4)) -> 0 | T9: 大卦 | U9: =IF(T9="",0,INDEX($C$2:$C$27,MATCH(T9,$A$2:$A$27,0))*0.4) -> 120
A10: 草3 | B10: 150 | C10: 45 | D10: 1 | E10: =COUNTIF(main!$F$2:$AD$271,data!A10) -> 0 | G10: 9 | H10: 300 | I10: 46193 | K10: 9 | L10: 6级 | M10: =IF(L10="",0,(INDEX($B$2:$B$27,MATCH(L10,$A$2:$A$27,0))-50)*(0.4)) -> 60 | O10: =IF(N10="",0,INDEX($C$2:$C$27,MATCH(N10,$A$2:$A$27,0))*0.4) -> 0 | Q10: 9 | S10: =IF(R10="",0,(INDEX($B$2:$B$27,MATCH(R10,$A$2:$A$27,0))-50)*(0.4)) -> 0 | U10: =IF(T10="",0,INDEX($C$2:$C$27,MATCH(T10,$A$2:$A$27,0))*0.4) -> 0
A11: 草4 | B11: 150 | C11: 50 | D11: 1 | E11: =COUNTIF(main!$F$2:$AD$271,data!A11) -> 0 | G11: 10 | H11: 300 | I11: 46194 | K11: 10 | L11: 6级 | M11: =IF(L11="",0,(INDEX($B$2:$B$27,MATCH(L11,$A$2:$A$27,0))-50)*(0.4)) -> 60 | O11: =IF(N11="",0,INDEX($C$2:$C$27,MATCH(N11,$A$2:$A$27,0))*0.4) -> 0 | Q11: 10 | S11: =IF(R11="",0,(INDEX($B$2:$B$27,MATCH(R11,$A$2:$A$27,0))-50)*(0.4)) -> 0 | U11: =IF(T11="",0,INDEX($C$2:$C$27,MATCH(T11,$A$2:$A$27,0))*0.4) -> 0
A12: 草5 | B12: 150 | C12: 55 | D12: 1 | E12: =COUNTIF(main!$F$2:$AD$271,data!A12) -> 0 | G12: 11 | H12: 250 | I12: 46195 | M12: =SUM(M2:M11) -> 588 | O12: =SUM(O2:O11) -> 1664 | S12: =SUM(S2:S11) -> 216 | U12: =SUM(U2:U11) -> 622
A13: 草6 | B13: 150 | C13: 60 | D13: 1 | E13: =COUNTIF(main!$F$2:$AD$271,data!A13) -> 0 | G13: 12 | H13: 250 | I13: 46196 | Q13: 总 | R13: 粮草节省 | S13: =M12+S12 -> 804 | T13: 经验加成 | U13: =O12+U12 -> 2286
A14: 遗迹 | B14: 150 | C14: 40 | D14: 1 | E14: =COUNTIF(main!$F$2:$AD$271,data!A14) -> 0 | G14: 13 | H14: 250 | I14: 46197 | K14: 批量生成分表：Alt+F11, insert Module
A15: 商人 | B15: 50 | C15: 30 | D15: 1 | E15: =COUNTIF(main!$F$2:$AD$271,data!A15) -> 0 | G15: 14 | H15: 250 | I15: 46198 | K15: Sub CopySheetMultipleTimes()
A16: 营地 | B16: -250 | C16: 0 | D16: -1 | E16: =COUNTIF(main!$F$2:$AD$271,data!A16) -> 0 | G16: 15 | H16: 250 | I16: 46199 | K16: Dim i As Integer
A17: 大卦 | B17: 250 | C17: 300 | D17: 1 | E17: =COUNTIF(main!$F$2:$AD$271,data!A17) -> 0 | G17: 16 | H17: 250 | I17: 46200 | K17: Dim n As Integer
A18: 3级卦 | B18: 170 | C18: 45 | D18: 1 | E18: =COUNTIF(main!$F$2:$AD$271,data!A18) -> 0 | G18: 17 | H18: 250 | I18: 46201 | K18: Dim baseName As String
A19: 飞雷 | B19: -50 | C19: 0 | D19: 0 | E19: =COUNTIF(main!$F$2:$AD$271,data!A19) -> 0 | G19: 18 | H19: 250 | I19: 46202
A20: 大boss | B20: 250 | C20: 1000 | D20: 1 | E20: =COUNTIF(main!$F$2:$AD$271,data!A20) -> 0 | G20: 19 | H20: 250 | I20: 46203 | K20: n = 87 ' <-- how many new sheets you want
A21: 中boss | B21: 250 | C21: 500 | D21: 1 | E21: =COUNTIF(main!$F$2:$AD$271,data!A21) -> 0 | G21: 20 | H21: 250 | I21: 46204 | K21: baseName = "3" ' <-- source sheet name
A22: 4级卦 | B22: 180 | C22: 50 | D22: 1 | E22: =COUNTIF(main!$F$2:$AD$271,data!A22) -> 0 | G22: 21 | H22: 200 | I22: 46205
A23: 塔1 | B23: 150 | C23: 35 | D23: 1 | E23: =COUNTIF(main!$F$2:$AD$271,data!A23) -> 0 | G23: 22 | H23: 200 | I23: 46206 | K23: For i = 1 To n
A24: 塔2 | B24: 150 | C24: 40 | D24: 1 | E24: =COUNTIF(main!$F$2:$AD$271,data!A24) -> 0 | G24: 23 | H24: 200 | I24: 46207 | K24: Sheets(baseName).Copy After:=Sheets(Sheets.Count)
A25: 塔3 | B25: 150 | C25: 45 | D25: 1 | E25: =COUNTIF(main!$F$2:$AD$271,data!A25) -> 0 | G25: 24 | H25: 200 | I25: 46208 | K25: ActiveSheet.Name = 3 + i
A26: 空 | B26: 0 | C26: 0 | D26: 0 | E26: =COUNTIF(main!$F$2:$AD$271,data!A26) -> 0 | G26: 25 | H26: 200 | I26: 46209 | K26: Next i
A27: 历练 | B27: 50 | C27: 520 | D27: 0 | E27: =COUNTIF(main!$F$2:$AD$271,data!A27) -> 0 | G27: 26 | H27: 200 | I27: 46210 | K27: End Sub
D28: 经验小计 | E28: {=SUM(C2:C27*E2:E27)} -> 0 | G28: 27 | H28: 200 | I28: 46211
D29: 总经验 | E29: =E28+7000+O12+U12 -> 9286 | G29: 28 | H29: 200 | I29: 46212
G30: 29 | H30: 200 | I30: 46213
G31: 30 | H31: 200 | I31: 46214
G32: 31 | H32: 200 | I32: 46215
G33: 32 | H33: 200 | I33: 46216
G34: 33 | H34: 200 | I34: 46217
G35: 34 | H35: 200 | I35: 46218
G36: 35 | H36: 200 | I36: 46219
G37: 36 | H37: 200 | I37: 46220
G38: 37 | H38: 200 | I38: 46221
G39: 38 | H39: 200 | I39: 46222
G40: 39 | H40: 200 | I40: 46223
...

Sheet 1
A1: Day | B1: Date | D1: =HYPERLINK("#" &(A2+1)& "!A1","明日") -> 明日 | F1: 消耗粮草 | G1: 获得经验 | H1: 初始行动 | I1: 结束行动 | J1: 跳步 | AB1: =HYPERLINK("#Main!A1", "总表") -> 总表 | AC1: =IF(MIN(I2:I4)<0, "行动不足", "") | AD1: =IF(D4<0, "粮草不足", "")
A2: {=MID(CELL("filename",A4),FIND("]",CELL("filename",A4))+1,255)} -> 1 | B2: =INDEX(data!I2:I91,MATCH(A2*1,data!G2:G91,0)) -> 46185 | E2: 一队 | F2: =SUM(C9:AA9) -> 0 | G2: =SUM(C10:AA10) -> 0 | H2: 6 | I2: {=H2-SUM(IFERROR(INDEX(data!$D$2:$D$27,MATCH(C8:AA8,data!$A$2:$A$27,0)),0))} -> 6 | J2: {=SUM(IFERROR(VALUE(MID(IF(LEFT(C8:AA8,1)="跳",C8:AA8,""),2,10)),0))} -> 0
A3: 起始粮草 | B3: 消耗粮草 | C3: 调粮 | D3: 余粮 | E3: 二队 | F3: =SUM(C12:AA12) -> 0 | G3: =SUM(C13:AA13) -> 0 | H3: 6 | I3: {=H3-SUM(IFERROR(INDEX(data!$D$2:$D$27,MATCH(C11:AA11,data!$A$2:$A$27,0)),0))} -> 6 | J3: {=SUM(IFERROR(VALUE(MID(IF(LEFT(C11:AA11,1)="跳",C11:AA11,""),2,10)),0))} -> 0
A4: 6800 | B4: =SUM(F2:F4) -> 0 | C4: 0 | D4: =A4-B4+C4 -> 6800 | E4: 三队 | F4: =SUM(C15:AA15) -> 0 | G4: =SUM(C16:AA16) -> 0 | H4: 6 | I4: {=H4-SUM(IFERROR(INDEX(data!$D$2:$D$27,MATCH(C14:AA14,data!$A$2:$A$27,0)),0))} -> 6 | J4: {=SUM(IFERROR(VALUE(MID(IF(LEFT(C14:AA14,1)="跳",C14:AA14,""),2,10)),0))} -> 0
A5: 起始经验 | B5: 获得经验 | C5: 调分 | D5: 经验
A6: 0 | B6: =SUM(G2:G4) -> 0 | C6: 0 | D6: =A6+B6+C6 -> 0 | AC6: 跳 | AD6: 2
C7: 1 | D7: 2 | E7: 3 | F7: 4 | G7: 5 | H7: 6 | I7: 7 | J7: 8 | K7: 9 | L7: 10 | M7: 11 | N7: 12 | O7: 13 | P7: 14 | Q7: 15 | R7: 16 | S7: 17 | T7: 18 | U7: 19 | V7: 20 | W7: 21 | X7: 22 | Y7: 23 | Z7: 24 | AA7: 25 | AC7: =_xlfn.CONCAT(AC6,AD6) -> 跳2
