Workbook

Sheet main
A1: Day | B1: Date | D1: 队 | E1: 剩步 | F1: 1 | G1: 2 | H1: 3 | I1: 4 | J1: 5 | K1: 6 | L1: 7 | M1: 8 | N1: 9 | O1: 10 | P1: 11 | Q1: 12 | R1: 13 | S1: 14 | T1: 15 | U1: 16 | V1: 17 | W1: 18 | X1: 19 | Y1: 20 | Z1: 21 | AA1: 22 | AB1: 23 | AC1: 24 | AD1: 25 | AE1: 跳 | AF1: Note
A2: 1 | B2: =INDEX(data!$I$2:$I$98,MATCH(A2*1,data!$G$2:$G$98,0)) | C2: =HYPERLINK("#'" & A2 & "'!A1", "编辑") | D2: 1队 | E2: {=INDIRECT("'"&$A3&"'!I2")} | F2: {=INDIRECT("'"&$A2&"'!C8")} | G2: {=INDIRECT("'"&$A2&"'!D8")} | H2: {=INDIRECT("'"&$A2&"'!E8")} | I2: {=INDIRECT("'"&$A2&"'!F8")} | J2: {=INDIRECT("'"&$A2&"'!G8")} | K2: {=INDIRECT("'"&$A2&"'!H8")} | L2: {=INDIRECT("'"&$A2&"'!I8")} | M2: {=INDIRECT("'"&$A2&"'!J8")} | N2: {=INDIRECT("'"&$A2&"'!K8")} | O2: {=INDIRECT("'"&$A2&"'!L8")} | P2: {=INDIRECT("'"&$A2&"'!M8")} | Q2: {=INDIRECT("'"&$A2&"'!N8")} | R2: {=INDIRECT("'"&$A2&"'!O8")} | S2: {=INDIRECT("'"&$A2&"'!P8")} | T2: {=INDIRECT("'"&$A2&"'!Q8")} | U2: {=INDIRECT("'"&$A2&"'!R8")} | V2: {=INDIRECT("'"&$A2&"'!S8")} | W2: {=INDIRECT("'"&$A2&"'!T8")} | X2: {=INDIRECT("'"&$A2&"'!U8")} | Y2: {=INDIRECT("'"&$A2&"'!V8")} | Z2: {=INDIRECT("'"&$A2&"'!W8")} | AA2: {=INDIRECT("'"&$A2&"'!X8")} | AB2: {=INDIRECT("'"&$A2&"'!Y8")} | AC2: {=INDIRECT("'"&$A2&"'!Z8")} | AD2: {=INDIRECT("'"&$A2&"'!AA8")} | AE2: {=INDIRECT("'"&$A3&"'!J2")} | AF2: {=INDIRECT("'"&$A3&"'!AD1")}
A3: 1 | C3: {=CONCATENATE("粮 ",INDIRECT("'"&$A3&"'!D4"))} | D3: 2队 | E3: {=INDIRECT("'"&$A3&"'!I3")} | F3: {=INDIRECT("'"&$A3&"'!C11")} | G3: {=INDIRECT("'"&$A3&"'!D11")} | H3: {=INDIRECT("'"&$A3&"'!E11")} | I3: {=INDIRECT("'"&$A3&"'!F11")} | J3: {=INDIRECT("'"&$A3&"'!G11")} | K3: {=INDIRECT("'"&$A3&"'!H11")} | L3: {=INDIRECT("'"&$A3&"'!I11")} | M3: {=INDIRECT("'"&$A3&"'!J11")} | N3: {=INDIRECT("'"&$A3&"'!K11")} | O3: {=INDIRECT("'"&$A3&"'!L11")} | P3: {=INDIRECT("'"&$A3&"'!M11")} | Q3: {=INDIRECT("'"&$A3&"'!N11")} | R3: {=INDIRECT("'"&$A3&"'!O11")} | S3: {=INDIRECT("'"&$A3&"'!P11")} | T3: {=INDIRECT("'"&$A3&"'!Q11")} | U3: {=INDIRECT("'"&$A3&"'!R11")} | V3: {=INDIRECT("'"&$A3&"'!S11")} | W3: {=INDIRECT("'"&$A3&"'!T11")} | X3: {=INDIRECT("'"&$A3&"'!U11")} | Y3: {=INDIRECT("'"&$A3&"'!V11")} | Z3: {=INDIRECT("'"&$A3&"'!W11")} | AA3: {=INDIRECT("'"&$A3&"'!X11")} | AB3: {=INDIRECT("'"&$A3&"'!Y11")} | AC3: {=INDIRECT("'"&$A3&"'!Z11")} | AD3: {=INDIRECT("'"&$A3&"'!AA11")} | AE3: {=INDIRECT("'"&$A3&"'!J3")} | AF3: {=INDIRECT("'"&$A3&"'!AC1")}
A4: 1 | C4: {=CONCATENATE("分 ",INDIRECT("'"&$A3&"'!D6"))} | D4: 3队 | E4: {=INDIRECT("'"&$A3&"'!I4")} | F4: {=INDIRECT("'"&$A4&"'!C14")} | G4: {=INDIRECT("'"&$A4&"'!D14")} | H4: {=INDIRECT("'"&$A4&"'!E14")} | I4: {=INDIRECT("'"&$A4&"'!F14")} | J4: {=INDIRECT("'"&$A4&"'!G14")} | K4: {=INDIRECT("'"&$A4&"'!H14")} | L4: {=INDIRECT("'"&$A4&"'!I14")} | M4: {=INDIRECT("'"&$A4&"'!J14")} | N4: {=INDIRECT("'"&$A4&"'!K14")} | O4: {=INDIRECT("'"&$A4&"'!L14")} | P4: {=INDIRECT("'"&$A4&"'!M14")} | Q4: {=INDIRECT("'"&$A4&"'!N14")} | R4: {=INDIRECT("'"&$A4&"'!O14")} | S4: {=INDIRECT("'"&$A4&"'!P14")} | T4: {=INDIRECT("'"&$A4&"'!Q14")} | U4: {=INDIRECT("'"&$A4&"'!R14")} | V4: {=INDIRECT("'"&$A4&"'!S14")} | W4: {=INDIRECT("'"&$A4&"'!T14")} | X4: {=INDIRECT("'"&$A4&"'!U14")} | Y4: {=INDIRECT("'"&$A4&"'!V14")} | Z4: {=INDIRECT("'"&$A4&"'!W14")} | AA4: {=INDIRECT("'"&$A4&"'!X14")} | AB4: {=INDIRECT("'"&$A4&"'!Y14")} | AC4: {=INDIRECT("'"&$A4&"'!Z14")} | AD4: {=INDIRECT("'"&$A4&"'!AA14")} | AE4: {=INDIRECT("'"&$A3&"'!J4")}
A5: 2 | B5: =INDEX(data!$I$2:$I$98,MATCH(A5*1,data!$G$2:$G$98,0)) | C5: =HYPERLINK("#'" & A5 & "'!A1", "编辑") | D5: 1队 | E5: {=INDIRECT("'"&$A6&"'!I2")} | F5: {=INDIRECT("'"&$A5&"'!C8")} | G5: {=INDIRECT("'"&$A5&"'!D8")} | H5: {=INDIRECT("'"&$A5&"'!E8")} | I5: {=INDIRECT("'"&$A5&"'!F8")} | J5: {=INDIRECT("'"&$A5&"'!G8")} | K5: {=INDIRECT("'"&$A5&"'!H8")} | L5: {=INDIRECT("'"&$A5&"'!I8")} | M5: {=INDIRECT("'"&$A5&"'!J8")} | N5: {=INDIRECT("'"&$A5&"'!K8")} | O5: {=INDIRECT("'"&$A5&"'!L8")} | P5: {=INDIRECT("'"&$A5&"'!M8")} | Q5: {=INDIRECT("'"&$A5&"'!N8")} | R5: {=INDIRECT("'"&$A5&"'!O8")} | S5: {=INDIRECT("'"&$A5&"'!P8")} | T5: {=INDIRECT("'"&$A5&"'!Q8")} | U5: {=INDIRECT("'"&$A5&"'!R8")} | V5: {=INDIRECT("'"&$A5&"'!S8")} | W5: {=INDIRECT("'"&$A5&"'!T8")} | X5: {=INDIRECT("'"&$A5&"'!U8")} | Y5: {=INDIRECT("'"&$A5&"'!V8")} | Z5: {=INDIRECT("'"&$A5&"'!W8")} | AA5: {=INDIRECT("'"&$A5&"'!X8")} | AB5: {=INDIRECT("'"&$A5&"'!Y8")} | AC5: {=INDIRECT("'"&$A5&"'!Z8")} | AD5: {=INDIRECT("'"&$A5&"'!AA8")} | AE5: {=INDIRECT("'"&$A6&"'!J2")} | AF5: {=INDIRECT("'"&$A6&"'!AD1")}
A6: 2 | C6: {=CONCATENATE("粮 ",INDIRECT("'"&$A6&"'!D4"))} | D6: 2队 | E6: {=INDIRECT("'"&$A6&"'!I3")} | F6: {=INDIRECT("'"&$A6&"'!C11")} | G6: {=INDIRECT("'"&$A6&"'!D11")} | H6: {=INDIRECT("'"&$A6&"'!E11")} | I6: {=INDIRECT("'"&$A6&"'!F11")} | J6: {=INDIRECT("'"&$A6&"'!G11")} | K6: {=INDIRECT("'"&$A6&"'!H11")} | L6: {=INDIRECT("'"&$A6&"'!I11")} | M6: {=INDIRECT("'"&$A6&"'!J11")} | N6: {=INDIRECT("'"&$A6&"'!K11")} | O6: {=INDIRECT("'"&$A6&"'!L11")} | P6: {=INDIRECT("'"&$A6&"'!M11")} | Q6: {=INDIRECT("'"&$A6&"'!N11")} | R6: {=INDIRECT("'"&$A6&"'!O11")} | S6: {=INDIRECT("'"&$A6&"'!P11")} | T6: {=INDIRECT("'"&$A6&"'!Q11")} | U6: {=INDIRECT("'"&$A6&"'!R11")} | V6: {=INDIRECT("'"&$A6&"'!S11")} | W6: {=INDIRECT("'"&$A6&"'!T11")} | X6: {=INDIRECT("'"&$A6&"'!U11")} | Y6: {=INDIRECT("'"&$A6&"'!V11")} | Z6: {=INDIRECT("'"&$A6&"'!W11")} | AA6: {=INDIRECT("'"&$A6&"'!X11")} | AB6: {=INDIRECT("'"&$A6&"'!Y11")} | AC6: {=INDIRECT("'"&$A6&"'!Z11")} | AD6: {=INDIRECT("'"&$A6&"'!AA11")} | AE6: {=INDIRECT("'"&$A6&"'!J3")} | AF6: {=INDIRECT("'"&$A6&"'!AC1")}
A7: 2 | C7: {=CONCATENATE("分 ",INDIRECT("'"&$A6&"'!D6"))} | D7: 3队 | E7: {=INDIRECT("'"&$A6&"'!I4")} | F7: {=INDIRECT("'"&$A7&"'!C14")} | G7: {=INDIRECT("'"&$A7&"'!D14")} | H7: {=INDIRECT("'"&$A7&"'!E14")} | I7: {=INDIRECT("'"&$A7&"'!F14")} | J7: {=INDIRECT("'"&$A7&"'!G14")} | K7: {=INDIRECT("'"&$A7&"'!H14")} | L7: {=INDIRECT("'"&$A7&"'!I14")} | M7: {=INDIRECT("'"&$A7&"'!J14")} | N7: {=INDIRECT("'"&$A7&"'!K14")} | O7: {=INDIRECT("'"&$A7&"'!L14")} | P7: {=INDIRECT("'"&$A7&"'!M14")} | Q7: {=INDIRECT("'"&$A7&"'!N14")} | R7: {=INDIRECT("'"&$A7&"'!O14")} | S7: {=INDIRECT("'"&$A7&"'!P14")} | T7: {=INDIRECT("'"&$A7&"'!Q14")} | U7: {=INDIRECT("'"&$A7&"'!R14")} | V7: {=INDIRECT("'"&$A7&"'!S14")} | W7: {=INDIRECT("'"&$A7&"'!T14")} | X7: {=INDIRECT("'"&$A7&"'!U14")} | Y7: {=INDIRECT("'"&$A7&"'!V14")} | Z7: {=INDIRECT("'"&$A7&"'!W14")} | AA7: {=INDIRECT("'"&$A7&"'!X14")} | AB7: {=INDIRECT("'"&$A7&"'!Y14")} | AC7: {=INDIRECT("'"&$A7&"'!Z14")} | AD7: {=INDIRECT("'"&$A7&"'!AA14")} | AE7: {=INDIRECT("'"&$A6&"'!J4")}
A8: 3 | B8: =INDEX(data!$I$2:$I$98,MATCH(A8*1,data!$G$2:$G$98,0)) | C8: =HYPERLINK("#'" & A8 & "'!A1", "编辑") | D8: 1队 | E8: {=INDIRECT("'"&$A9&"'!I2")} | F8: {=INDIRECT("'"&$A8&"'!C8")} | G8: {=INDIRECT("'"&$A8&"'!D8")} | H8: {=INDIRECT("'"&$A8&"'!E8")} | I8: {=INDIRECT("'"&$A8&"'!F8")} | J8: {=INDIRECT("'"&$A8&"'!G8")} | K8: {=INDIRECT("'"&$A8&"'!H8")} | L8: {=INDIRECT("'"&$A8&"'!I8")} | M8: {=INDIRECT("'"&$A8&"'!J8")} | N8: {=INDIRECT("'"&$A8&"'!K8")} | O8: {=INDIRECT("'"&$A8&"'!L8")} | P8: {=INDIRECT("'"&$A8&"'!M8")} | Q8: {=INDIRECT("'"&$A8&"'!N8")} | R8: {=INDIRECT("'"&$A8&"'!O8")} | S8: {=INDIRECT("'"&$A8&"'!P8")} | T8: {=INDIRECT("'"&$A8&"'!Q8")} | U8: {=INDIRECT("'"&$A8&"'!R8")} | V8: {=INDIRECT("'"&$A8&"'!S8")} | W8: {=INDIRECT("'"&$A8&"'!T8")} | X8: {=INDIRECT("'"&$A8&"'!U8")} | Y8: {=INDIRECT("'"&$A8&"'!V8")} | Z8: {=INDIRECT("'"&$A8&"'!W8")} | AA8: {=INDIRECT("'"&$A8&"'!X8")} | AB8: {=INDIRECT("'"&$A8&"'!Y8")} | AC8: {=INDIRECT("'"&$A8&"'!Z8")} | AD8: {=INDIRECT("'"&$A8&"'!AA8")} | AE8: {=INDIRECT("'"&$A9&"'!J2")} | AF8: {=INDIRECT("'"&$A9&"'!AD1")}
A9: 3 | C9: {=CONCATENATE("粮 ",INDIRECT("'"&$A9&"'!D4"))} | D9: 2队 | E9: {=INDIRECT("'"&$A9&"'!I3")} | F9: {=INDIRECT("'"&$A9&"'!C11")} | G9: {=INDIRECT("'"&$A9&"'!D11")} | H9: {=INDIRECT("'"&$A9&"'!E11")} | I9: {=INDIRECT("'"&$A9&"'!F11")} | J9: {=INDIRECT("'"&$A9&"'!G11")} | K9: {=INDIRECT("'"&$A9&"'!H11")} | L9: {=INDIRECT("'"&$A9&"'!I11")} | M9: {=INDIRECT("'"&$A9&"'!J11")} | N9: {=INDIRECT("'"&$A9&"'!K11")} | O9: {=INDIRECT("'"&$A9&"'!L11")} | P9: {=INDIRECT("'"&$A9&"'!M11")} | Q9: {=INDIRECT("'"&$A9&"'!N11")} | R9: {=INDIRECT("'"&$A9&"'!O11")} | S9: {=INDIRECT("'"&$A9&"'!P11")} | T9: {=INDIRECT("'"&$A9&"'!Q11")} | U9: {=INDIRECT("'"&$A9&"'!R11")} | V9: {=INDIRECT("'"&$A9&"'!S11")} | W9: {=INDIRECT("'"&$A9&"'!T11")} | X9: {=INDIRECT("'"&$A9&"'!U11")} | Y9: {=INDIRECT("'"&$A9&"'!V11")} | Z9: {=INDIRECT("'"&$A9&"'!W11")} | AA9: {=INDIRECT("'"&$A9&"'!X11")} | AB9: {=INDIRECT("'"&$A9&"'!Y11")} | AC9: {=INDIRECT("'"&$A9&"'!Z11")} | AD9: {=INDIRECT("'"&$A9&"'!AA11")} | AE9: {=INDIRECT("'"&$A9&"'!J3")} | AF9: {=INDIRECT("'"&$A9&"'!AC1")}
A10: 3 | C10: {=CONCATENATE("分 ",INDIRECT("'"&$A9&"'!D6"))} | D10: 3队 | E10: {=INDIRECT("'"&$A9&"'!I4")} | F10: {=INDIRECT("'"&$A10&"'!C14")} | G10: {=INDIRECT("'"&$A10&"'!D14")} | H10: {=INDIRECT("'"&$A10&"'!E14")} | I10: {=INDIRECT("'"&$A10&"'!F14")} | J10: {=INDIRECT("'"&$A10&"'!G14")} | K10: {=INDIRECT("'"&$A10&"'!H14")} | L10: {=INDIRECT("'"&$A10&"'!I14")} | M10: {=INDIRECT("'"&$A10&"'!J14")} | N10: {=INDIRECT("'"&$A10&"'!K14")} | O10: {=INDIRECT("'"&$A10&"'!L14")} | P10: {=INDIRECT("'"&$A10&"'!M14")} | Q10: {=INDIRECT("'"&$A10&"'!N14")} | R10: {=INDIRECT("'"&$A10&"'!O14")} | S10: {=INDIRECT("'"&$A10&"'!P14")} | T10: {=INDIRECT("'"&$A10&"'!Q14")} | U10: {=INDIRECT("'"&$A10&"'!R14")} | V10: {=INDIRECT("'"&$A10&"'!S14")} | W10: {=INDIRECT("'"&$A10&"'!T14")} | X10: {=INDIRECT("'"&$A10&"'!U14")} | Y10: {=INDIRECT("'"&$A10&"'!V14")} | Z10: {=INDIRECT("'"&$A10&"'!W14")} | AA10: {=INDIRECT("'"&$A10&"'!X14")} | AB10: {=INDIRECT("'"&$A10&"'!Y14")} | AC10: {=INDIRECT("'"&$A10&"'!Z14")} | AD10: {=INDIRECT("'"&$A10&"'!AA14")} | AE10: {=INDIRECT("'"&$A9&"'!J4")}
A11: 4 | B11: =INDEX(data!$I$2:$I$98,MATCH(A11*1,data!$G$2:$G$98,0)) | C11: =HYPERLINK("#'" & A11 & "'!A1", "编辑") | D11: 1队 | E11: {=INDIRECT("'"&$A12&"'!I2")} | F11: {=INDIRECT("'"&$A11&"'!C8")} | G11: {=INDIRECT("'"&$A11&"'!D8")} | H11: {=INDIRECT("'"&$A11&"'!E8")} | I11: {=INDIRECT("'"&$A11&"'!F8")} | J11: {=INDIRECT("'"&$A11&"'!G8")} | K11: {=INDIRECT("'"&$A11&"'!H8")} | L11: {=INDIRECT("'"&$A11&"'!I8")} | M11: {=INDIRECT("'"&$A11&"'!J8")} | N11: {=INDIRECT("'"&$A11&"'!K8")} | O11: {=INDIRECT("'"&$A11&"'!L8")} | P11: {=INDIRECT("'"&$A11&"'!M8")} | Q11: {=INDIRECT("'"&$A11&"'!N8")} | R11: {=INDIRECT("'"&$A11&"'!O8")} | S11: {=INDIRECT("'"&$A11&"'!P8")} | T11: {=INDIRECT("'"&$A11&"'!Q8")} | U11: {=INDIRECT("'"&$A11&"'!R8")} | V11: {=INDIRECT("'"&$A11&"'!S8")} | W11: {=INDIRECT("'"&$A11&"'!T8")} | X11: {=INDIRECT("'"&$A11&"'!U8")} | Y11: {=INDIRECT("'"&$A11&"'!V8")} | Z11: {=INDIRECT("'"&$A11&"'!W8")} | AA11: {=INDIRECT("'"&$A11&"'!X8")} | AB11: {=INDIRECT("'"&$A11&"'!Y8")} | AC11: {=INDIRECT("'"&$A11&"'!Z8")} | AD11: {=INDIRECT("'"&$A11&"'!AA8")} | AE11: {=INDIRECT("'"&$A12&"'!J2")} | AF11: {=INDIRECT("'"&$A12&"'!AD1")}
A12: 4 | C12: {=CONCATENATE("粮 ",INDIRECT("'"&$A12&"'!D4"))} | D12: 2队 | E12: {=INDIRECT("'"&$A12&"'!I3")} | F12: {=INDIRECT("'"&$A12&"'!C11")} | G12: {=INDIRECT("'"&$A12&"'!D11")} | H12: {=INDIRECT("'"&$A12&"'!E11")} | I12: {=INDIRECT("'"&$A12&"'!F11")} | J12: {=INDIRECT("'"&$A12&"'!G11")} | K12: {=INDIRECT("'"&$A12&"'!H11")} | L12: {=INDIRECT("'"&$A12&"'!I11")} | M12: {=INDIRECT("'"&$A12&"'!J11")} | N12: {=INDIRECT("'"&$A12&"'!K11")} | O12: {=INDIRECT("'"&$A12&"'!L11")} | P12: {=INDIRECT("'"&$A12&"'!M11")} | Q12: {=INDIRECT("'"&$A12&"'!N11")} | R12: {=INDIRECT("'"&$A12&"'!O11")} | S12: {=INDIRECT("'"&$A12&"'!P11")} | T12: {=INDIRECT("'"&$A12&"'!Q11")} | U12: {=INDIRECT("'"&$A12&"'!R11")} | V12: {=INDIRECT("'"&$A12&"'!S11")} | W12: {=INDIRECT("'"&$A12&"'!T11")} | X12: {=INDIRECT("'"&$A12&"'!U11")} | Y12: {=INDIRECT("'"&$A12&"'!V11")} | Z12: {=INDIRECT("'"&$A12&"'!W11")} | AA12: {=INDIRECT("'"&$A12&"'!X11")} | AB12: {=INDIRECT("'"&$A12&"'!Y11")} | AC12: {=INDIRECT("'"&$A12&"'!Z11")} | AD12: {=INDIRECT("'"&$A12&"'!AA11")} | AE12: {=INDIRECT("'"&$A12&"'!J3")} | AF12: {=INDIRECT("'"&$A12&"'!AC1")}
A13: 4 | C13: {=CONCATENATE("分 ",INDIRECT("'"&$A12&"'!D6"))} | D13: 3队 | E13: {=INDIRECT("'"&$A12&"'!I4")} | F13: {=INDIRECT("'"&$A13&"'!C14")} | G13: {=INDIRECT("'"&$A13&"'!D14")} | H13: {=INDIRECT("'"&$A13&"'!E14")} | I13: {=INDIRECT("'"&$A13&"'!F14")} | J13: {=INDIRECT("'"&$A13&"'!G14")} | K13: {=INDIRECT("'"&$A13&"'!H14")} | L13: {=INDIRECT("'"&$A13&"'!I14")} | M13: {=INDIRECT("'"&$A13&"'!J14")} | N13: {=INDIRECT("'"&$A13&"'!K14")} | O13: {=INDIRECT("'"&$A13&"'!L14")} | P13: {=INDIRECT("'"&$A13&"'!M14")} | Q13: {=INDIRECT("'"&$A13&"'!N14")} | R13: {=INDIRECT("'"&$A13&"'!O14")} | S13: {=INDIRECT("'"&$A13&"'!P14")} | T13: {=INDIRECT("'"&$A13&"'!Q14")} | U13: {=INDIRECT("'"&$A13&"'!R14")} | V13: {=INDIRECT("'"&$A13&"'!S14")} | W13: {=INDIRECT("'"&$A13&"'!T14")} | X13: {=INDIRECT("'"&$A13&"'!U14")} | Y13: {=INDIRECT("'"&$A13&"'!V14")} | Z13: {=INDIRECT("'"&$A13&"'!W14")} | AA13: {=INDIRECT("'"&$A13&"'!X14")} | AB13: {=INDIRECT("'"&$A13&"'!Y14")} | AC13: {=INDIRECT("'"&$A13&"'!Z14")} | AD13: {=INDIRECT("'"&$A13&"'!AA14")} | AE13: {=INDIRECT("'"&$A12&"'!J4")}
A14: 5 | B14: =INDEX(data!$I$2:$I$98,MATCH(A14*1,data!$G$2:$G$98,0)) | C14: =HYPERLINK("#'" & A14 & "'!A1", "编辑") | D14: 1队 | E14: {=INDIRECT("'"&$A15&"'!I2")} | F14: {=INDIRECT("'"&$A14&"'!C8")} | G14: {=INDIRECT("'"&$A14&"'!D8")} | H14: {=INDIRECT("'"&$A14&"'!E8")} | I14: {=INDIRECT("'"&$A14&"'!F8")} | J14: {=INDIRECT("'"&$A14&"'!G8")} | K14: {=INDIRECT("'"&$A14&"'!H8")} | L14: {=INDIRECT("'"&$A14&"'!I8")} | M14: {=INDIRECT("'"&$A14&"'!J8")} | N14: {=INDIRECT("'"&$A14&"'!K8")} | O14: {=INDIRECT("'"&$A14&"'!L8")} | P14: {=INDIRECT("'"&$A14&"'!M8")} | Q14: {=INDIRECT("'"&$A14&"'!N8")} | R14: {=INDIRECT("'"&$A14&"'!O8")} | S14: {=INDIRECT("'"&$A14&"'!P8")} | T14: {=INDIRECT("'"&$A14&"'!Q8")} | U14: {=INDIRECT("'"&$A14&"'!R8")} | V14: {=INDIRECT("'"&$A14&"'!S8")} | W14: {=INDIRECT("'"&$A14&"'!T8")} | X14: {=INDIRECT("'"&$A14&"'!U8")} | Y14: {=INDIRECT("'"&$A14&"'!V8")} | Z14: {=INDIRECT("'"&$A14&"'!W8")} | AA14: {=INDIRECT("'"&$A14&"'!X8")} | AB14: {=INDIRECT("'"&$A14&"'!Y8")} | AC14: {=INDIRECT("'"&$A14&"'!Z8")} | AD14: {=INDIRECT("'"&$A14&"'!AA8")} | AE14: {=INDIRECT("'"&$A15&"'!J2")} | AF14: {=INDIRECT("'"&$A15&"'!AD1")}
A15: 5 | C15: {=CONCATENATE("粮 ",INDIRECT("'"&$A15&"'!D4"))} | D15: 2队 | E15: {=INDIRECT("'"&$A15&"'!I3")} | F15: {=INDIRECT("'"&$A15&"'!C11")} | G15: {=INDIRECT("'"&$A15&"'!D11")} | H15: {=INDIRECT("'"&$A15&"'!E11")} | I15: {=INDIRECT("'"&$A15&"'!F11")} | J15: {=INDIRECT("'"&$A15&"'!G11")} | K15: {=INDIRECT("'"&$A15&"'!H11")} | L15: {=INDIRECT("'"&$A15&"'!I11")} | M15: {=INDIRECT("'"&$A15&"'!J11")} | N15: {=INDIRECT("'"&$A15&"'!K11")} | O15: {=INDIRECT("'"&$A15&"'!L11")} | P15: {=INDIRECT("'"&$A15&"'!M11")} | Q15: {=INDIRECT("'"&$A15&"'!N11")} | R15: {=INDIRECT("'"&$A15&"'!O11")} | S15: {=INDIRECT("'"&$A15&"'!P11")} | T15: {=INDIRECT("'"&$A15&"'!Q11")} | U15: {=INDIRECT("'"&$A15&"'!R11")} | V15: {=INDIRECT("'"&$A15&"'!S11")} | W15: {=INDIRECT("'"&$A15&"'!T11")} | X15: {=INDIRECT("'"&$A15&"'!U11")} | Y15: {=INDIRECT("'"&$A15&"'!V11")} | Z15: {=INDIRECT("'"&$A15&"'!W11")} | AA15: {=INDIRECT("'"&$A15&"'!X11")} | AB15: {=INDIRECT("'"&$A15&"'!Y11")} | AC15: {=INDIRECT("'"&$A15&"'!Z11")} | AD15: {=INDIRECT("'"&$A15&"'!AA11")} | AE15: {=INDIRECT("'"&$A15&"'!J3")} | AF15: {=INDIRECT("'"&$A15&"'!AC1")}
A16: 5 | C16: {=CONCATENATE("分 ",INDIRECT("'"&$A15&"'!D6"))} | D16: 3队 | E16: {=INDIRECT("'"&$A15&"'!I4")} | F16: {=INDIRECT("'"&$A16&"'!C14")} | G16: {=INDIRECT("'"&$A16&"'!D14")} | H16: {=INDIRECT("'"&$A16&"'!E14")} | I16: {=INDIRECT("'"&$A16&"'!F14")} | J16: {=INDIRECT("'"&$A16&"'!G14")} | K16: {=INDIRECT("'"&$A16&"'!H14")} | L16: {=INDIRECT("'"&$A16&"'!I14")} | M16: {=INDIRECT("'"&$A16&"'!J14")} | N16: {=INDIRECT("'"&$A16&"'!K14")} | O16: {=INDIRECT("'"&$A16&"'!L14")} | P16: {=INDIRECT("'"&$A16&"'!M14")} | Q16: {=INDIRECT("'"&$A16&"'!N14")} | R16: {=INDIRECT("'"&$A16&"'!O14")} | S16: {=INDIRECT("'"&$A16&"'!P14")} | T16: {=INDIRECT("'"&$A16&"'!Q14")} | U16: {=INDIRECT("'"&$A16&"'!R14")} | V16: {=INDIRECT("'"&$A16&"'!S14")} | W16: {=INDIRECT("'"&$A16&"'!T14")} | X16: {=INDIRECT("'"&$A16&"'!U14")} | Y16: {=INDIRECT("'"&$A16&"'!V14")} | Z16: {=INDIRECT("'"&$A16&"'!W14")} | AA16: {=INDIRECT("'"&$A16&"'!X14")} | AB16: {=INDIRECT("'"&$A16&"'!Y14")} | AC16: {=INDIRECT("'"&$A16&"'!Z14")} | AD16: {=INDIRECT("'"&$A16&"'!AA14")} | AE16: {=INDIRECT("'"&$A15&"'!J4")}
A17: 6 | B17: =INDEX(data!$I$2:$I$98,MATCH(A17*1,data!$G$2:$G$98,0)) | C17: =HYPERLINK("#'" & A17 & "'!A1", "编辑") | D17: 1队 | E17: {=INDIRECT("'"&$A18&"'!I2")} | F17: {=INDIRECT("'"&$A17&"'!C8")} | G17: {=INDIRECT("'"&$A17&"'!D8")} | H17: {=INDIRECT("'"&$A17&"'!E8")} | I17: {=INDIRECT("'"&$A17&"'!F8")} | J17: {=INDIRECT("'"&$A17&"'!G8")} | K17: {=INDIRECT("'"&$A17&"'!H8")} | L17: {=INDIRECT("'"&$A17&"'!I8")} | M17: {=INDIRECT("'"&$A17&"'!J8")} | N17: {=INDIRECT("'"&$A17&"'!K8")} | O17: {=INDIRECT("'"&$A17&"'!L8")} | P17: {=INDIRECT("'"&$A17&"'!M8")} | Q17: {=INDIRECT("'"&$A17&"'!N8")} | R17: {=INDIRECT("'"&$A17&"'!O8")} | S17: {=INDIRECT("'"&$A17&"'!P8")} | T17: {=INDIRECT("'"&$A17&"'!Q8")} | U17: {=INDIRECT("'"&$A17&"'!R8")} | V17: {=INDIRECT("'"&$A17&"'!S8")} | W17: {=INDIRECT("'"&$A17&"'!T8")} | X17: {=INDIRECT("'"&$A17&"'!U8")} | Y17: {=INDIRECT("'"&$A17&"'!V8")} | Z17: {=INDIRECT("'"&$A17&"'!W8")} | AA17: {=INDIRECT("'"&$A17&"'!X8")} | AB17: {=INDIRECT("'"&$A17&"'!Y8")} | AC17: {=INDIRECT("'"&$A17&"'!Z8")} | AD17: {=INDIRECT("'"&$A17&"'!AA8")} | AE17: {=INDIRECT("'"&$A18&"'!J2")} | AF17: {=INDIRECT("'"&$A18&"'!AD1")}
A18: 6 | C18: {=CONCATENATE("粮 ",INDIRECT("'"&$A18&"'!D4"))} | D18: 2队 | E18: {=INDIRECT("'"&$A18&"'!I3")} | F18: {=INDIRECT("'"&$A18&"'!C11")} | G18: {=INDIRECT("'"&$A18&"'!D11")} | H18: {=INDIRECT("'"&$A18&"'!E11")} | I18: {=INDIRECT("'"&$A18&"'!F11")} | J18: {=INDIRECT("'"&$A18&"'!G11")} | K18: {=INDIRECT("'"&$A18&"'!H11")} | L18: {=INDIRECT("'"&$A18&"'!I11")} | M18: {=INDIRECT("'"&$A18&"'!J11")} | N18: {=INDIRECT("'"&$A18&"'!K11")} | O18: {=INDIRECT("'"&$A18&"'!L11")} | P18: {=INDIRECT("'"&$A18&"'!M11")} | Q18: {=INDIRECT("'"&$A18&"'!N11")} | R18: {=INDIRECT("'"&$A18&"'!O11")} | S18: {=INDIRECT("'"&$A18&"'!P11")} | T18: {=INDIRECT("'"&$A18&"'!Q11")} | U18: {=INDIRECT("'"&$A18&"'!R11")} | V18: {=INDIRECT("'"&$A18&"'!S11")} | W18: {=INDIRECT("'"&$A18&"'!T11")} | X18: {=INDIRECT("'"&$A18&"'!U11")} | Y18: {=INDIRECT("'"&$A18&"'!V11")} | Z18: {=INDIRECT("'"&$A18&"'!W11")} | AA18: {=INDIRECT("'"&$A18&"'!X11")} | AB18: {=INDIRECT("'"&$A18&"'!Y11")} | AC18: {=INDIRECT("'"&$A18&"'!Z11")} | AD18: {=INDIRECT("'"&$A18&"'!AA11")} | AE18: {=INDIRECT("'"&$A18&"'!J3")} | AF18: {=INDIRECT("'"&$A18&"'!AC1")}
A19: 6 | C19: {=CONCATENATE("分 ",INDIRECT("'"&$A18&"'!D6"))} | D19: 3队 | E19: {=INDIRECT("'"&$A18&"'!I4")} | F19: {=INDIRECT("'"&$A19&"'!C14")} | G19: {=INDIRECT("'"&$A19&"'!D14")} | H19: {=INDIRECT("'"&$A19&"'!E14")} | I19: {=INDIRECT("'"&$A19&"'!F14")} | J19: {=INDIRECT("'"&$A19&"'!G14")} | K19: {=INDIRECT("'"&$A19&"'!H14")} | L19: {=INDIRECT("'"&$A19&"'!I14")} | M19: {=INDIRECT("'"&$A19&"'!J14")} | N19: {=INDIRECT("'"&$A19&"'!K14")} | O19: {=INDIRECT("'"&$A19&"'!L14")} | P19: {=INDIRECT("'"&$A19&"'!M14")} | Q19: {=INDIRECT("'"&$A19&"'!N14")} | R19: {=INDIRECT("'"&$A19&"'!O14")} | S19: {=INDIRECT("'"&$A19&"'!P14")} | T19: {=INDIRECT("'"&$A19&"'!Q14")} | U19: {=INDIRECT("'"&$A19&"'!R14")} | V19: {=INDIRECT("'"&$A19&"'!S14")} | W19: {=INDIRECT("'"&$A19&"'!T14")} | X19: {=INDIRECT("'"&$A19&"'!U14")} | Y19: {=INDIRECT("'"&$A19&"'!V14")} | Z19: {=INDIRECT("'"&$A19&"'!W14")} | AA19: {=INDIRECT("'"&$A19&"'!X14")} | AB19: {=INDIRECT("'"&$A19&"'!Y14")} | AC19: {=INDIRECT("'"&$A19&"'!Z14")} | AD19: {=INDIRECT("'"&$A19&"'!AA14")} | AE19: {=INDIRECT("'"&$A18&"'!J4")}
A20: 7 | B20: =INDEX(data!$I$2:$I$98,MATCH(A20*1,data!$G$2:$G$98,0)) | C20: =HYPERLINK("#'" & A20 & "'!A1", "编辑") | D20: 1队 | E20: {=INDIRECT("'"&$A21&"'!I2")} | F20: {=INDIRECT("'"&$A20&"'!C8")} | G20: {=INDIRECT("'"&$A20&"'!D8")} | H20: {=INDIRECT("'"&$A20&"'!E8")} | I20: {=INDIRECT("'"&$A20&"'!F8")} | J20: {=INDIRECT("'"&$A20&"'!G8")} | K20: {=INDIRECT("'"&$A20&"'!H8")} | L20: {=INDIRECT("'"&$A20&"'!I8")} | M20: {=INDIRECT("'"&$A20&"'!J8")} | N20: {=INDIRECT("'"&$A20&"'!K8")} | O20: {=INDIRECT("'"&$A20&"'!L8")} | P20: {=INDIRECT("'"&$A20&"'!M8")} | Q20: {=INDIRECT("'"&$A20&"'!N8")} | R20: {=INDIRECT("'"&$A20&"'!O8")} | S20: {=INDIRECT("'"&$A20&"'!P8")} | T20: {=INDIRECT("'"&$A20&"'!Q8")} | U20: {=INDIRECT("'"&$A20&"'!R8")} | V20: {=INDIRECT("'"&$A20&"'!S8")} | W20: {=INDIRECT("'"&$A20&"'!T8")} | X20: {=INDIRECT("'"&$A20&"'!U8")} | Y20: {=INDIRECT("'"&$A20&"'!V8")} | Z20: {=INDIRECT("'"&$A20&"'!W8")} | AA20: {=INDIRECT("'"&$A20&"'!X8")} | AB20: {=INDIRECT("'"&$A20&"'!Y8")} | AC20: {=INDIRECT("'"&$A20&"'!Z8")} | AD20: {=INDIRECT("'"&$A20&"'!AA8")} | AE20: {=INDIRECT("'"&$A21&"'!J2")} | AF20: {=INDIRECT("'"&$A21&"'!AD1")}
A21: 7 | C21: {=CONCATENATE("粮 ",INDIRECT("'"&$A21&"'!D4"))} | D21: 2队 | E21: {=INDIRECT("'"&$A21&"'!I3")} | F21: {=INDIRECT("'"&$A21&"'!C11")} | G21: {=INDIRECT("'"&$A21&"'!D11")} | H21: {=INDIRECT("'"&$A21&"'!E11")} | I21: {=INDIRECT("'"&$A21&"'!F11")} | J21: {=INDIRECT("'"&$A21&"'!G11")} | K21: {=INDIRECT("'"&$A21&"'!H11")} | L21: {=INDIRECT("'"&$A21&"'!I11")} | M21: {=INDIRECT("'"&$A21&"'!J11")} | N21: {=INDIRECT("'"&$A21&"'!K11")} | O21: {=INDIRECT("'"&$A21&"'!L11")} | P21: {=INDIRECT("'"&$A21&"'!M11")} | Q21: {=INDIRECT("'"&$A21&"'!N11")} | R21: {=INDIRECT("'"&$A21&"'!O11")} | S21: {=INDIRECT("'"&$A21&"'!P11")} | T21: {=INDIRECT("'"&$A21&"'!Q11")} | U21: {=INDIRECT("'"&$A21&"'!R11")} | V21: {=INDIRECT("'"&$A21&"'!S11")} | W21: {=INDIRECT("'"&$A21&"'!T11")} | X21: {=INDIRECT("'"&$A21&"'!U11")} | Y21: {=INDIRECT("'"&$A21&"'!V11")} | Z21: {=INDIRECT("'"&$A21&"'!W11")} | AA21: {=INDIRECT("'"&$A21&"'!X11")} | AB21: {=INDIRECT("'"&$A21&"'!Y11")} | AC21: {=INDIRECT("'"&$A21&"'!Z11")} | AD21: {=INDIRECT("'"&$A21&"'!AA11")} | AE21: {=INDIRECT("'"&$A21&"'!J3")} | AF21: {=INDIRECT("'"&$A21&"'!AC1")}
A22: 7 | C22: {=CONCATENATE("分 ",INDIRECT("'"&$A21&"'!D6"))} | D22: 3队 | E22: {=INDIRECT("'"&$A21&"'!I4")} | F22: {=INDIRECT("'"&$A22&"'!C14")} | G22: {=INDIRECT("'"&$A22&"'!D14")} | H22: {=INDIRECT("'"&$A22&"'!E14")} | I22: {=INDIRECT("'"&$A22&"'!F14")} | J22: {=INDIRECT("'"&$A22&"'!G14")} | K22: {=INDIRECT("'"&$A22&"'!H14")} | L22: {=INDIRECT("'"&$A22&"'!I14")} | M22: {=INDIRECT("'"&$A22&"'!J14")} | N22: {=INDIRECT("'"&$A22&"'!K14")} | O22: {=INDIRECT("'"&$A22&"'!L14")} | P22: {=INDIRECT("'"&$A22&"'!M14")} | Q22: {=INDIRECT("'"&$A22&"'!N14")} | R22: {=INDIRECT("'"&$A22&"'!O14")} | S22: {=INDIRECT("'"&$A22&"'!P14")} | T22: {=INDIRECT("'"&$A22&"'!Q14")} | U22: {=INDIRECT("'"&$A22&"'!R14")} | V22: {=INDIRECT("'"&$A22&"'!S14")} | W22: {=INDIRECT("'"&$A22&"'!T14")} | X22: {=INDIRECT("'"&$A22&"'!U14")} | Y22: {=INDIRECT("'"&$A22&"'!V14")} | Z22: {=INDIRECT("'"&$A22&"'!W14")} | AA22: {=INDIRECT("'"&$A22&"'!X14")} | AB22: {=INDIRECT("'"&$A22&"'!Y14")} | AC22: {=INDIRECT("'"&$A22&"'!Z14")} | AD22: {=INDIRECT("'"&$A22&"'!AA14")} | AE22: {=INDIRECT("'"&$A21&"'!J4")}
A23: 8 | B23: =INDEX(data!$I$2:$I$98,MATCH(A23*1,data!$G$2:$G$98,0)) | C23: =HYPERLINK("#'" & A23 & "'!A1", "编辑") | D23: 1队 | E23: {=INDIRECT("'"&$A24&"'!I2")} | F23: {=INDIRECT("'"&$A23&"'!C8")} | G23: {=INDIRECT("'"&$A23&"'!D8")} | H23: {=INDIRECT("'"&$A23&"'!E8")} | I23: {=INDIRECT("'"&$A23&"'!F8")} | J23: {=INDIRECT("'"&$A23&"'!G8")} | K23: {=INDIRECT("'"&$A23&"'!H8")} | L23: {=INDIRECT("'"&$A23&"'!I8")} | M23: {=INDIRECT("'"&$A23&"'!J8")} | N23: {=INDIRECT("'"&$A23&"'!K8")} | O23: {=INDIRECT("'"&$A23&"'!L8")} | P23: {=INDIRECT("'"&$A23&"'!M8")} | Q23: {=INDIRECT("'"&$A23&"'!N8")} | R23: {=INDIRECT("'"&$A23&"'!O8")} | S23: {=INDIRECT("'"&$A23&"'!P8")} | T23: {=INDIRECT("'"&$A23&"'!Q8")} | U23: {=INDIRECT("'"&$A23&"'!R8")} | V23: {=INDIRECT("'"&$A23&"'!S8")} | W23: {=INDIRECT("'"&$A23&"'!T8")} | X23: {=INDIRECT("'"&$A23&"'!U8")} | Y23: {=INDIRECT("'"&$A23&"'!V8")} | Z23: {=INDIRECT("'"&$A23&"'!W8")} | AA23: {=INDIRECT("'"&$A23&"'!X8")} | AB23: {=INDIRECT("'"&$A23&"'!Y8")} | AC23: {=INDIRECT("'"&$A23&"'!Z8")} | AD23: {=INDIRECT("'"&$A23&"'!AA8")} | AE23: {=INDIRECT("'"&$A24&"'!J2")} | AF23: {=INDIRECT("'"&$A24&"'!AD1")}
A24: 8 | C24: {=CONCATENATE("粮 ",INDIRECT("'"&$A24&"'!D4"))} | D24: 2队 | E24: {=INDIRECT("'"&$A24&"'!I3")} | F24: {=INDIRECT("'"&$A24&"'!C11")} | G24: {=INDIRECT("'"&$A24&"'!D11")} | H24: {=INDIRECT("'"&$A24&"'!E11")} | I24: {=INDIRECT("'"&$A24&"'!F11")} | J24: {=INDIRECT("'"&$A24&"'!G11")} | K24: {=INDIRECT("'"&$A24&"'!H11")} | L24: {=INDIRECT("'"&$A24&"'!I11")} | M24: {=INDIRECT("'"&$A24&"'!J11")} | N24: {=INDIRECT("'"&$A24&"'!K11")} | O24: {=INDIRECT("'"&$A24&"'!L11")} | P24: {=INDIRECT("'"&$A24&"'!M11")} | Q24: {=INDIRECT("'"&$A24&"'!N11")} | R24: {=INDIRECT("'"&$A24&"'!O11")} | S24: {=INDIRECT("'"&$A24&"'!P11")} | T24: {=INDIRECT("'"&$A24&"'!Q11")} | U24: {=INDIRECT("'"&$A24&"'!R11")} | V24: {=INDIRECT("'"&$A24&"'!S11")} | W24: {=INDIRECT("'"&$A24&"'!T11")} | X24: {=INDIRECT("'"&$A24&"'!U11")} | Y24: {=INDIRECT("'"&$A24&"'!V11")} | Z24: {=INDIRECT("'"&$A24&"'!W11")} | AA24: {=INDIRECT("'"&$A24&"'!X11")} | AB24: {=INDIRECT("'"&$A24&"'!Y11")} | AC24: {=INDIRECT("'"&$A24&"'!Z11")} | AD24: {=INDIRECT("'"&$A24&"'!AA11")} | AE24: {=INDIRECT("'"&$A24&"'!J3")} | AF24: {=INDIRECT("'"&$A24&"'!AC1")}
A25: 8 | C25: {=CONCATENATE("分 ",INDIRECT("'"&$A24&"'!D6"))} | D25: 3队 | E25: {=INDIRECT("'"&$A24&"'!I4")} | F25: {=INDIRECT("'"&$A25&"'!C14")} | G25: {=INDIRECT("'"&$A25&"'!D14")} | H25: {=INDIRECT("'"&$A25&"'!E14")} | I25: {=INDIRECT("'"&$A25&"'!F14")} | J25: {=INDIRECT("'"&$A25&"'!G14")} | K25: {=INDIRECT("'"&$A25&"'!H14")} | L25: {=INDIRECT("'"&$A25&"'!I14")} | M25: {=INDIRECT("'"&$A25&"'!J14")} | N25: {=INDIRECT("'"&$A25&"'!K14")} | O25: {=INDIRECT("'"&$A25&"'!L14")} | P25: {=INDIRECT("'"&$A25&"'!M14")} | Q25: {=INDIRECT("'"&$A25&"'!N14")} | R25: {=INDIRECT("'"&$A25&"'!O14")} | S25: {=INDIRECT("'"&$A25&"'!P14")} | T25: {=INDIRECT("'"&$A25&"'!Q14")} | U25: {=INDIRECT("'"&$A25&"'!R14")} | V25: {=INDIRECT("'"&$A25&"'!S14")} | W25: {=INDIRECT("'"&$A25&"'!T14")} | X25: {=INDIRECT("'"&$A25&"'!U14")} | Y25: {=INDIRECT("'"&$A25&"'!V14")} | Z25: {=INDIRECT("'"&$A25&"'!W14")} | AA25: {=INDIRECT("'"&$A25&"'!X14")} | AB25: {=INDIRECT("'"&$A25&"'!Y14")} | AC25: {=INDIRECT("'"&$A25&"'!Z14")} | AD25: {=INDIRECT("'"&$A25&"'!AA14")} | AE25: {=INDIRECT("'"&$A24&"'!J4")}
A26: 9 | B26: =INDEX(data!$I$2:$I$98,MATCH(A26*1,data!$G$2:$G$98,0)) | C26: =HYPERLINK("#'" & A26 & "'!A1", "编辑") | D26: 1队 | E26: {=INDIRECT("'"&$A27&"'!I2")} | F26: {=INDIRECT("'"&$A26&"'!C8")} | G26: {=INDIRECT("'"&$A26&"'!D8")} | H26: {=INDIRECT("'"&$A26&"'!E8")} | I26: {=INDIRECT("'"&$A26&"'!F8")} | J26: {=INDIRECT("'"&$A26&"'!G8")} | K26: {=INDIRECT("'"&$A26&"'!H8")} | L26: {=INDIRECT("'"&$A26&"'!I8")} | M26: {=INDIRECT("'"&$A26&"'!J8")} | N26: {=INDIRECT("'"&$A26&"'!K8")} | O26: {=INDIRECT("'"&$A26&"'!L8")} | P26: {=INDIRECT("'"&$A26&"'!M8")} | Q26: {=INDIRECT("'"&$A26&"'!N8")} | R26: {=INDIRECT("'"&$A26&"'!O8")} | S26: {=INDIRECT("'"&$A26&"'!P8")} | T26: {=INDIRECT("'"&$A26&"'!Q8")} | U26: {=INDIRECT("'"&$A26&"'!R8")} | V26: {=INDIRECT("'"&$A26&"'!S8")} | W26: {=INDIRECT("'"&$A26&"'!T8")} | X26: {=INDIRECT("'"&$A26&"'!U8")} | Y26: {=INDIRECT("'"&$A26&"'!V8")} | Z26: {=INDIRECT("'"&$A26&"'!W8")} | AA26: {=INDIRECT("'"&$A26&"'!X8")} | AB26: {=INDIRECT("'"&$A26&"'!Y8")} | AC26: {=INDIRECT("'"&$A26&"'!Z8")} | AD26: {=INDIRECT("'"&$A26&"'!AA8")} | AE26: {=INDIRECT("'"&$A27&"'!J2")} | AF26: {=INDIRECT("'"&$A27&"'!AD1")}
A27: 9 | C27: {=CONCATENATE("粮 ",INDIRECT("'"&$A27&"'!D4"))} | D27: 2队 | E27: {=INDIRECT("'"&$A27&"'!I3")} | F27: {=INDIRECT("'"&$A27&"'!C11")} | G27: {=INDIRECT("'"&$A27&"'!D11")} | H27: {=INDIRECT("'"&$A27&"'!E11")} | I27: {=INDIRECT("'"&$A27&"'!F11")} | J27: {=INDIRECT("'"&$A27&"'!G11")} | K27: {=INDIRECT("'"&$A27&"'!H11")} | L27: {=INDIRECT("'"&$A27&"'!I11")} | M27: {=INDIRECT("'"&$A27&"'!J11")} | N27: {=INDIRECT("'"&$A27&"'!K11")} | O27: {=INDIRECT("'"&$A27&"'!L11")} | P27: {=INDIRECT("'"&$A27&"'!M11")} | Q27: {=INDIRECT("'"&$A27&"'!N11")} | R27: {=INDIRECT("'"&$A27&"'!O11")} | S27: {=INDIRECT("'"&$A27&"'!P11")} | T27: {=INDIRECT("'"&$A27&"'!Q11")} | U27: {=INDIRECT("'"&$A27&"'!R11")} | V27: {=INDIRECT("'"&$A27&"'!S11")} | W27: {=INDIRECT("'"&$A27&"'!T11")} | X27: {=INDIRECT("'"&$A27&"'!U11")} | Y27: {=INDIRECT("'"&$A27&"'!V11")} | Z27: {=INDIRECT("'"&$A27&"'!W11")} | AA27: {=INDIRECT("'"&$A27&"'!X11")} | AB27: {=INDIRECT("'"&$A27&"'!Y11")} | AC27: {=INDIRECT("'"&$A27&"'!Z11")} | AD27: {=INDIRECT("'"&$A27&"'!AA11")} | AE27: {=INDIRECT("'"&$A27&"'!J3")} | AF27: {=INDIRECT("'"&$A27&"'!AC1")}
A28: 9 | C28: {=CONCATENATE("分 ",INDIRECT("'"&$A27&"'!D6"))} | D28: 3队 | E28: {=INDIRECT("'"&$A27&"'!I4")} | F28: {=INDIRECT("'"&$A28&"'!C14")} | G28: {=INDIRECT("'"&$A28&"'!D14")} | H28: {=INDIRECT("'"&$A28&"'!E14")} | I28: {=INDIRECT("'"&$A28&"'!F14")} | J28: {=INDIRECT("'"&$A28&"'!G14")} | K28: {=INDIRECT("'"&$A28&"'!H14")} | L28: {=INDIRECT("'"&$A28&"'!I14")} | M28: {=INDIRECT("'"&$A28&"'!J14")} | N28: {=INDIRECT("'"&$A28&"'!K14")} | O28: {=INDIRECT("'"&$A28&"'!L14")} | P28: {=INDIRECT("'"&$A28&"'!M14")} | Q28: {=INDIRECT("'"&$A28&"'!N14")} | R28: {=INDIRECT("'"&$A28&"'!O14")} | S28: {=INDIRECT("'"&$A28&"'!P14")} | T28: {=INDIRECT("'"&$A28&"'!Q14")} | U28: {=INDIRECT("'"&$A28&"'!R14")} | V28: {=INDIRECT("'"&$A28&"'!S14")} | W28: {=INDIRECT("'"&$A28&"'!T14")} | X28: {=INDIRECT("'"&$A28&"'!U14")} | Y28: {=INDIRECT("'"&$A28&"'!V14")} | Z28: {=INDIRECT("'"&$A28&"'!W14")} | AA28: {=INDIRECT("'"&$A28&"'!X14")} | AB28: {=INDIRECT("'"&$A28&"'!Y14")} | AC28: {=INDIRECT("'"&$A28&"'!Z14")} | AD28: {=INDIRECT("'"&$A28&"'!AA14")} | AE28: {=INDIRECT("'"&$A27&"'!J4")}
A29: 10 | B29: =INDEX(data!$I$2:$I$98,MATCH(A29*1,data!$G$2:$G$98,0)) | C29: =HYPERLINK("#'" & A29 & "'!A1", "编辑") | D29: 1队 | E29: {=INDIRECT("'"&$A30&"'!I2")} | F29: {=INDIRECT("'"&$A29&"'!C8")} | G29: {=INDIRECT("'"&$A29&"'!D8")} | H29: {=INDIRECT("'"&$A29&"'!E8")} | I29: {=INDIRECT("'"&$A29&"'!F8")} | J29: {=INDIRECT("'"&$A29&"'!G8")} | K29: {=INDIRECT("'"&$A29&"'!H8")} | L29: {=INDIRECT("'"&$A29&"'!I8")} | M29: {=INDIRECT("'"&$A29&"'!J8")} | N29: {=INDIRECT("'"&$A29&"'!K8")} | O29: {=INDIRECT("'"&$A29&"'!L8")} | P29: {=INDIRECT("'"&$A29&"'!M8")} | Q29: {=INDIRECT("'"&$A29&"'!N8")} | R29: {=INDIRECT("'"&$A29&"'!O8")} | S29: {=INDIRECT("'"&$A29&"'!P8")} | T29: {=INDIRECT("'"&$A29&"'!Q8")} | U29: {=INDIRECT("'"&$A29&"'!R8")} | V29: {=INDIRECT("'"&$A29&"'!S8")} | W29: {=INDIRECT("'"&$A29&"'!T8")} | X29: {=INDIRECT("'"&$A29&"'!U8")} | Y29: {=INDIRECT("'"&$A29&"'!V8")} | Z29: {=INDIRECT("'"&$A29&"'!W8")} | AA29: {=INDIRECT("'"&$A29&"'!X8")} | AB29: {=INDIRECT("'"&$A29&"'!Y8")} | AC29: {=INDIRECT("'"&$A29&"'!Z8")} | AD29: {=INDIRECT("'"&$A29&"'!AA8")} | AE29: {=INDIRECT("'"&$A30&"'!J2")} | AF29: {=INDIRECT("'"&$A30&"'!AD1")}
A30: 10 | C30: {=CONCATENATE("粮 ",INDIRECT("'"&$A30&"'!D4"))} | D30: 2队 | E30: {=INDIRECT("'"&$A30&"'!I3")} | F30: {=INDIRECT("'"&$A30&"'!C11")} | G30: {=INDIRECT("'"&$A30&"'!D11")} | H30: {=INDIRECT("'"&$A30&"'!E11")} | I30: {=INDIRECT("'"&$A30&"'!F11")} | J30: {=INDIRECT("'"&$A30&"'!G11")} | K30: {=INDIRECT("'"&$A30&"'!H11")} | L30: {=INDIRECT("'"&$A30&"'!I11")} | M30: {=INDIRECT("'"&$A30&"'!J11")} | N30: {=INDIRECT("'"&$A30&"'!K11")} | O30: {=INDIRECT("'"&$A30&"'!L11")} | P30: {=INDIRECT("'"&$A30&"'!M11")} | Q30: {=INDIRECT("'"&$A30&"'!N11")} | R30: {=INDIRECT("'"&$A30&"'!O11")} | S30: {=INDIRECT("'"&$A30&"'!P11")} | T30: {=INDIRECT("'"&$A30&"'!Q11")} | U30: {=INDIRECT("'"&$A30&"'!R11")} | V30: {=INDIRECT("'"&$A30&"'!S11")} | W30: {=INDIRECT("'"&$A30&"'!T11")} | X30: {=INDIRECT("'"&$A30&"'!U11")} | Y30: {=INDIRECT("'"&$A30&"'!V11")} | Z30: {=INDIRECT("'"&$A30&"'!W11")} | AA30: {=INDIRECT("'"&$A30&"'!X11")} | AB30: {=INDIRECT("'"&$A30&"'!Y11")} | AC30: {=INDIRECT("'"&$A30&"'!Z11")} | AD30: {=INDIRECT("'"&$A30&"'!AA11")} | AE30: {=INDIRECT("'"&$A30&"'!J3")} | AF30: {=INDIRECT("'"&$A30&"'!AC1")}
A31: 10 | C31: {=CONCATENATE("分 ",INDIRECT("'"&$A30&"'!D6"))} | D31: 3队 | E31: {=INDIRECT("'"&$A30&"'!I4")} | F31: {=INDIRECT("'"&$A31&"'!C14")} | G31: {=INDIRECT("'"&$A31&"'!D14")} | H31: {=INDIRECT("'"&$A31&"'!E14")} | I31: {=INDIRECT("'"&$A31&"'!F14")} | J31: {=INDIRECT("'"&$A31&"'!G14")} | K31: {=INDIRECT("'"&$A31&"'!H14")} | L31: {=INDIRECT("'"&$A31&"'!I14")} | M31: {=INDIRECT("'"&$A31&"'!J14")} | N31: {=INDIRECT("'"&$A31&"'!K14")} | O31: {=INDIRECT("'"&$A31&"'!L14")} | P31: {=INDIRECT("'"&$A31&"'!M14")} | Q31: {=INDIRECT("'"&$A31&"'!N14")} | R31: {=INDIRECT("'"&$A31&"'!O14")} | S31: {=INDIRECT("'"&$A31&"'!P14")} | T31: {=INDIRECT("'"&$A31&"'!Q14")} | U31: {=INDIRECT("'"&$A31&"'!R14")} | V31: {=INDIRECT("'"&$A31&"'!S14")} | W31: {=INDIRECT("'"&$A31&"'!T14")} | X31: {=INDIRECT("'"&$A31&"'!U14")} | Y31: {=INDIRECT("'"&$A31&"'!V14")} | Z31: {=INDIRECT("'"&$A31&"'!W14")} | AA31: {=INDIRECT("'"&$A31&"'!X14")} | AB31: {=INDIRECT("'"&$A31&"'!Y14")} | AC31: {=INDIRECT("'"&$A31&"'!Z14")} | AD31: {=INDIRECT("'"&$A31&"'!AA14")} | AE31: {=INDIRECT("'"&$A30&"'!J4")}
A32: 11 | B32: =INDEX(data!$I$2:$I$98,MATCH(A32*1,data!$G$2:$G$98,0)) | C32: =HYPERLINK("#'" & A32 & "'!A1", "编辑") | D32: 1队 | E32: {=INDIRECT("'"&$A33&"'!I2")} | F32: {=INDIRECT("'"&$A32&"'!C8")} | G32: {=INDIRECT("'"&$A32&"'!D8")} | H32: {=INDIRECT("'"&$A32&"'!E8")} | I32: {=INDIRECT("'"&$A32&"'!F8")} | J32: {=INDIRECT("'"&$A32&"'!G8")} | K32: {=INDIRECT("'"&$A32&"'!H8")} | L32: {=INDIRECT("'"&$A32&"'!I8")} | M32: {=INDIRECT("'"&$A32&"'!J8")} | N32: {=INDIRECT("'"&$A32&"'!K8")} | O32: {=INDIRECT("'"&$A32&"'!L8")} | P32: {=INDIRECT("'"&$A32&"'!M8")} | Q32: {=INDIRECT("'"&$A32&"'!N8")} | R32: {=INDIRECT("'"&$A32&"'!O8")} | S32: {=INDIRECT("'"&$A32&"'!P8")} | T32: {=INDIRECT("'"&$A32&"'!Q8")} | U32: {=INDIRECT("'"&$A32&"'!R8")} | V32: {=INDIRECT("'"&$A32&"'!S8")} | W32: {=INDIRECT("'"&$A32&"'!T8")} | X32: {=INDIRECT("'"&$A32&"'!U8")} | Y32: {=INDIRECT("'"&$A32&"'!V8")} | Z32: {=INDIRECT("'"&$A32&"'!W8")} | AA32: {=INDIRECT("'"&$A32&"'!X8")} | AB32: {=INDIRECT("'"&$A32&"'!Y8")} | AC32: {=INDIRECT("'"&$A32&"'!Z8")} | AD32: {=INDIRECT("'"&$A32&"'!AA8")} | AE32: {=INDIRECT("'"&$A33&"'!J2")} | AF32: {=INDIRECT("'"&$A33&"'!AD1")}
A33: 11 | C33: {=CONCATENATE("粮 ",INDIRECT("'"&$A33&"'!D4"))} | D33: 2队 | E33: {=INDIRECT("'"&$A33&"'!I3")} | F33: {=INDIRECT("'"&$A33&"'!C11")} | G33: {=INDIRECT("'"&$A33&"'!D11")} | H33: {=INDIRECT("'"&$A33&"'!E11")} | I33: {=INDIRECT("'"&$A33&"'!F11")} | J33: {=INDIRECT("'"&$A33&"'!G11")} | K33: {=INDIRECT("'"&$A33&"'!H11")} | L33: {=INDIRECT("'"&$A33&"'!I11")} | M33: {=INDIRECT("'"&$A33&"'!J11")} | N33: {=INDIRECT("'"&$A33&"'!K11")} | O33: {=INDIRECT("'"&$A33&"'!L11")} | P33: {=INDIRECT("'"&$A33&"'!M11")} | Q33: {=INDIRECT("'"&$A33&"'!N11")} | R33: {=INDIRECT("'"&$A33&"'!O11")} | S33: {=INDIRECT("'"&$A33&"'!P11")} | T33: {=INDIRECT("'"&$A33&"'!Q11")} | U33: {=INDIRECT("'"&$A33&"'!R11")} | V33: {=INDIRECT("'"&$A33&"'!S11")} | W33: {=INDIRECT("'"&$A33&"'!T11")} | X33: {=INDIRECT("'"&$A33&"'!U11")} | Y33: {=INDIRECT("'"&$A33&"'!V11")} | Z33: {=INDIRECT("'"&$A33&"'!W11")} | AA33: {=INDIRECT("'"&$A33&"'!X11")} | AB33: {=INDIRECT("'"&$A33&"'!Y11")} | AC33: {=INDIRECT("'"&$A33&"'!Z11")} | AD33: {=INDIRECT("'"&$A33&"'!AA11")} | AE33: {=INDIRECT("'"&$A33&"'!J3")} | AF33: {=INDIRECT("'"&$A33&"'!AC1")}
A34: 11 | C34: {=CONCATENATE("分 ",INDIRECT("'"&$A33&"'!D6"))} | D34: 3队 | E34: {=INDIRECT("'"&$A33&"'!I4")} | F34: {=INDIRECT("'"&$A34&"'!C14")} | G34: {=INDIRECT("'"&$A34&"'!D14")} | H34: {=INDIRECT("'"&$A34&"'!E14")} | I34: {=INDIRECT("'"&$A34&"'!F14")} | J34: {=INDIRECT("'"&$A34&"'!G14")} | K34: {=INDIRECT("'"&$A34&"'!H14")} | L34: {=INDIRECT("'"&$A34&"'!I14")} | M34: {=INDIRECT("'"&$A34&"'!J14")} | N34: {=INDIRECT("'"&$A34&"'!K14")} | O34: {=INDIRECT("'"&$A34&"'!L14")} | P34: {=INDIRECT("'"&$A34&"'!M14")} | Q34: {=INDIRECT("'"&$A34&"'!N14")} | R34: {=INDIRECT("'"&$A34&"'!O14")} | S34: {=INDIRECT("'"&$A34&"'!P14")} | T34: {=INDIRECT("'"&$A34&"'!Q14")} | U34: {=INDIRECT("'"&$A34&"'!R14")} | V34: {=INDIRECT("'"&$A34&"'!S14")} | W34: {=INDIRECT("'"&$A34&"'!T14")} | X34: {=INDIRECT("'"&$A34&"'!U14")} | Y34: {=INDIRECT("'"&$A34&"'!V14")} | Z34: {=INDIRECT("'"&$A34&"'!W14")} | AA34: {=INDIRECT("'"&$A34&"'!X14")} | AB34: {=INDIRECT("'"&$A34&"'!Y14")} | AC34: {=INDIRECT("'"&$A34&"'!Z14")} | AD34: {=INDIRECT("'"&$A34&"'!AA14")} | AE34: {=INDIRECT("'"&$A33&"'!J4")}
A35: 12 | B35: =INDEX(data!$I$2:$I$98,MATCH(A35*1,data!$G$2:$G$98,0)) | C35: =HYPERLINK("#'" & A35 & "'!A1", "编辑") | D35: 1队 | E35: {=INDIRECT("'"&$A36&"'!I2")} | F35: {=INDIRECT("'"&$A35&"'!C8")} | G35: {=INDIRECT("'"&$A35&"'!D8")} | H35: {=INDIRECT("'"&$A35&"'!E8")} | I35: {=INDIRECT("'"&$A35&"'!F8")} | J35: {=INDIRECT("'"&$A35&"'!G8")} | K35: {=INDIRECT("'"&$A35&"'!H8")} | L35: {=INDIRECT("'"&$A35&"'!I8")} | M35: {=INDIRECT("'"&$A35&"'!J8")} | N35: {=INDIRECT("'"&$A35&"'!K8")} | O35: {=INDIRECT("'"&$A35&"'!L8")} | P35: {=INDIRECT("'"&$A35&"'!M8")} | Q35: {=INDIRECT("'"&$A35&"'!N8")} | R35: {=INDIRECT("'"&$A35&"'!O8")} | S35: {=INDIRECT("'"&$A35&"'!P8")} | T35: {=INDIRECT("'"&$A35&"'!Q8")} | U35: {=INDIRECT("'"&$A35&"'!R8")} | V35: {=INDIRECT("'"&$A35&"'!S8")} | W35: {=INDIRECT("'"&$A35&"'!T8")} | X35: {=INDIRECT("'"&$A35&"'!U8")} | Y35: {=INDIRECT("'"&$A35&"'!V8")} | Z35: {=INDIRECT("'"&$A35&"'!W8")} | AA35: {=INDIRECT("'"&$A35&"'!X8")} | AB35: {=INDIRECT("'"&$A35&"'!Y8")} | AC35: {=INDIRECT("'"&$A35&"'!Z8")} | AD35: {=INDIRECT("'"&$A35&"'!AA8")} | AE35: {=INDIRECT("'"&$A36&"'!J2")} | AF35: {=INDIRECT("'"&$A36&"'!AD1")}
A36: 12 | C36: {=CONCATENATE("粮 ",INDIRECT("'"&$A36&"'!D4"))} | D36: 2队 | E36: {=INDIRECT("'"&$A36&"'!I3")} | F36: {=INDIRECT("'"&$A36&"'!C11")} | G36: {=INDIRECT("'"&$A36&"'!D11")} | H36: {=INDIRECT("'"&$A36&"'!E11")} | I36: {=INDIRECT("'"&$A36&"'!F11")} | J36: {=INDIRECT("'"&$A36&"'!G11")} | K36: {=INDIRECT("'"&$A36&"'!H11")} | L36: {=INDIRECT("'"&$A36&"'!I11")} | M36: {=INDIRECT("'"&$A36&"'!J11")} | N36: {=INDIRECT("'"&$A36&"'!K11")} | O36: {=INDIRECT("'"&$A36&"'!L11")} | P36: {=INDIRECT("'"&$A36&"'!M11")} | Q36: {=INDIRECT("'"&$A36&"'!N11")} | R36: {=INDIRECT("'"&$A36&"'!O11")} | S36: {=INDIRECT("'"&$A36&"'!P11")} | T36: {=INDIRECT("'"&$A36&"'!Q11")} | U36: {=INDIRECT("'"&$A36&"'!R11")} | V36: {=INDIRECT("'"&$A36&"'!S11")} | W36: {=INDIRECT("'"&$A36&"'!T11")} | X36: {=INDIRECT("'"&$A36&"'!U11")} | Y36: {=INDIRECT("'"&$A36&"'!V11")} | Z36: {=INDIRECT("'"&$A36&"'!W11")} | AA36: {=INDIRECT("'"&$A36&"'!X11")} | AB36: {=INDIRECT("'"&$A36&"'!Y11")} | AC36: {=INDIRECT("'"&$A36&"'!Z11")} | AD36: {=INDIRECT("'"&$A36&"'!AA11")} | AE36: {=INDIRECT("'"&$A36&"'!J3")} | AF36: {=INDIRECT("'"&$A36&"'!AC1")}
A37: 12 | C37: {=CONCATENATE("分 ",INDIRECT("'"&$A36&"'!D6"))} | D37: 3队 | E37: {=INDIRECT("'"&$A36&"'!I4")} | F37: {=INDIRECT("'"&$A37&"'!C14")} | G37: {=INDIRECT("'"&$A37&"'!D14")} | H37: {=INDIRECT("'"&$A37&"'!E14")} | I37: {=INDIRECT("'"&$A37&"'!F14")} | J37: {=INDIRECT("'"&$A37&"'!G14")} | K37: {=INDIRECT("'"&$A37&"'!H14")} | L37: {=INDIRECT("'"&$A37&"'!I14")} | M37: {=INDIRECT("'"&$A37&"'!J14")} | N37: {=INDIRECT("'"&$A37&"'!K14")} | O37: {=INDIRECT("'"&$A37&"'!L14")} | P37: {=INDIRECT("'"&$A37&"'!M14")} | Q37: {=INDIRECT("'"&$A37&"'!N14")} | R37: {=INDIRECT("'"&$A37&"'!O14")} | S37: {=INDIRECT("'"&$A37&"'!P14")} | T37: {=INDIRECT("'"&$A37&"'!Q14")} | U37: {=INDIRECT("'"&$A37&"'!R14")} | V37: {=INDIRECT("'"&$A37&"'!S14")} | W37: {=INDIRECT("'"&$A37&"'!T14")} | X37: {=INDIRECT("'"&$A37&"'!U14")} | Y37: {=INDIRECT("'"&$A37&"'!V14")} | Z37: {=INDIRECT("'"&$A37&"'!W14")} | AA37: {=INDIRECT("'"&$A37&"'!X14")} | AB37: {=INDIRECT("'"&$A37&"'!Y14")} | AC37: {=INDIRECT("'"&$A37&"'!Z14")} | AD37: {=INDIRECT("'"&$A37&"'!AA14")} | AE37: {=INDIRECT("'"&$A36&"'!J4")}
A38: 13 | B38: =INDEX(data!$I$2:$I$98,MATCH(A38*1,data!$G$2:$G$98,0)) | C38: =HYPERLINK("#'" & A38 & "'!A1", "编辑") | D38: 1队 | E38: {=INDIRECT("'"&$A39&"'!I2")} | F38: {=INDIRECT("'"&$A38&"'!C8")} | G38: {=INDIRECT("'"&$A38&"'!D8")} | H38: {=INDIRECT("'"&$A38&"'!E8")} | I38: {=INDIRECT("'"&$A38&"'!F8")} | J38: {=INDIRECT("'"&$A38&"'!G8")} | K38: {=INDIRECT("'"&$A38&"'!H8")} | L38: {=INDIRECT("'"&$A38&"'!I8")} | M38: {=INDIRECT("'"&$A38&"'!J8")} | N38: {=INDIRECT("'"&$A38&"'!K8")} | O38: {=INDIRECT("'"&$A38&"'!L8")} | P38: {=INDIRECT("'"&$A38&"'!M8")} | Q38: {=INDIRECT("'"&$A38&"'!N8")} | R38: {=INDIRECT("'"&$A38&"'!O8")} | S38: {=INDIRECT("'"&$A38&"'!P8")} | T38: {=INDIRECT("'"&$A38&"'!Q8")} | U38: {=INDIRECT("'"&$A38&"'!R8")} | V38: {=INDIRECT("'"&$A38&"'!S8")} | W38: {=INDIRECT("'"&$A38&"'!T8")} | X38: {=INDIRECT("'"&$A38&"'!U8")} | Y38: {=INDIRECT("'"&$A38&"'!V8")} | Z38: {=INDIRECT("'"&$A38&"'!W8")} | AA38: {=INDIRECT("'"&$A38&"'!X8")} | AB38: {=INDIRECT("'"&$A38&"'!Y8")} | AC38: {=INDIRECT("'"&$A38&"'!Z8")} | AD38: {=INDIRECT("'"&$A38&"'!AA8")} | AE38: {=INDIRECT("'"&$A39&"'!J2")} | AF38: {=INDIRECT("'"&$A39&"'!AD1")}
A39: 13 | C39: {=CONCATENATE("粮 ",INDIRECT("'"&$A39&"'!D4"))} | D39: 2队 | E39: {=INDIRECT("'"&$A39&"'!I3")} | F39: {=INDIRECT("'"&$A39&"'!C11")} | G39: {=INDIRECT("'"&$A39&"'!D11")} | H39: {=INDIRECT("'"&$A39&"'!E11")} | I39: {=INDIRECT("'"&$A39&"'!F11")} | J39: {=INDIRECT("'"&$A39&"'!G11")} | K39: {=INDIRECT("'"&$A39&"'!H11")} | L39: {=INDIRECT("'"&$A39&"'!I11")} | M39: {=INDIRECT("'"&$A39&"'!J11")} | N39: {=INDIRECT("'"&$A39&"'!K11")} | O39: {=INDIRECT("'"&$A39&"'!L11")} | P39: {=INDIRECT("'"&$A39&"'!M11")} | Q39: {=INDIRECT("'"&$A39&"'!N11")} | R39: {=INDIRECT("'"&$A39&"'!O11")} | S39: {=INDIRECT("'"&$A39&"'!P11")} | T39: {=INDIRECT("'"&$A39&"'!Q11")} | U39: {=INDIRECT("'"&$A39&"'!R11")} | V39: {=INDIRECT("'"&$A39&"'!S11")} | W39: {=INDIRECT("'"&$A39&"'!T11")} | X39: {=INDIRECT("'"&$A39&"'!U11")} | Y39: {=INDIRECT("'"&$A39&"'!V11")} | Z39: {=INDIRECT("'"&$A39&"'!W11")} | AA39: {=INDIRECT("'"&$A39&"'!X11")} | AB39: {=INDIRECT("'"&$A39&"'!Y11")} | AC39: {=INDIRECT("'"&$A39&"'!Z11")} | AD39: {=INDIRECT("'"&$A39&"'!AA11")} | AE39: {=INDIRECT("'"&$A39&"'!J3")} | AF39: {=INDIRECT("'"&$A39&"'!AC1")}
A40: 13 | C40: {=CONCATENATE("分 ",INDIRECT("'"&$A39&"'!D6"))} | D40: 3队 | E40: {=INDIRECT("'"&$A39&"'!I4")} | F40: {=INDIRECT("'"&$A40&"'!C14")} | G40: {=INDIRECT("'"&$A40&"'!D14")} | H40: {=INDIRECT("'"&$A40&"'!E14")} | I40: {=INDIRECT("'"&$A40&"'!F14")} | J40: {=INDIRECT("'"&$A40&"'!G14")} | K40: {=INDIRECT("'"&$A40&"'!H14")} | L40: {=INDIRECT("'"&$A40&"'!I14")} | M40: {=INDIRECT("'"&$A40&"'!J14")} | N40: {=INDIRECT("'"&$A40&"'!K14")} | O40: {=INDIRECT("'"&$A40&"'!L14")} | P40: {=INDIRECT("'"&$A40&"'!M14")} | Q40: {=INDIRECT("'"&$A40&"'!N14")} | R40: {=INDIRECT("'"&$A40&"'!O14")} | S40: {=INDIRECT("'"&$A40&"'!P14")} | T40: {=INDIRECT("'"&$A40&"'!Q14")} | U40: {=INDIRECT("'"&$A40&"'!R14")} | V40: {=INDIRECT("'"&$A40&"'!S14")} | W40: {=INDIRECT("'"&$A40&"'!T14")} | X40: {=INDIRECT("'"&$A40&"'!U14")} | Y40: {=INDIRECT("'"&$A40&"'!V14")} | Z40: {=INDIRECT("'"&$A40&"'!W14")} | AA40: {=INDIRECT("'"&$A40&"'!X14")} | AB40: {=INDIRECT("'"&$A40&"'!Y14")} | AC40: {=INDIRECT("'"&$A40&"'!Z14")} | AD40: {=INDIRECT("'"&$A40&"'!AA14")} | AE40: {=INDIRECT("'"&$A39&"'!J4")}
...

Sheet data
B1: 粮草 | C1: 经验 | D1: 行动 | E1: 已占领 | G1: day | H1: 张鹏 | I1: date | L1: 兵粮buff | M1: 减粮草 | N1: 战勋buff | O1: 加经验 | R1: 兵粮buff | S1: 减粮草 | T1: 战勋buff | U1: 加经验
A2: 1级 | B2: 150 | C2: 35 | D2: 1 | E2: =COUNTIF(main!$F$2:$AD$271,data!A2) | G2: 1 | H2: 300 | I2: 46276 | K2: 1 | M2: =IF(L2="",0,(INDEX($B$2:$B$27,MATCH(L2,$A$2:$A$27,0))-50)*(0.4)) | O2: =IF(N2="",0,INDEX($C$2:$C$27,MATCH(N2,$A$2:$A$27,0))*0.4) | Q2: 1 | S2: =IF(R2="",0,(INDEX($B$2:$B$27,MATCH(R2,$A$2:$A$27,0))-50)*(0.4)) | U2: =IF(T2="",0,INDEX($C$2:$C$27,MATCH(T2,$A$2:$A$27,0))*0.4)
A3: 2级 | B3: 160 | C3: 40 | D3: 1 | E3: =COUNTIF(main!$F$2:$AD$271,data!A3) | G3: 2 | H3: 300 | I3: 46277 | K3: 2 | M3: =IF(L3="",0,(INDEX($B$2:$B$27,MATCH(L3,$A$2:$A$27,0))-50)*(0.4)) | O3: =IF(N3="",0,INDEX($C$2:$C$27,MATCH(N3,$A$2:$A$27,0))*0.4) | Q3: 2 | S3: =IF(R3="",0,(INDEX($B$2:$B$27,MATCH(R3,$A$2:$A$27,0))-50)*(0.4)) | U3: =IF(T3="",0,INDEX($C$2:$C$27,MATCH(T3,$A$2:$A$27,0))*0.4)
A4: 3级 | B4: 170 | C4: 45 | D4: 1 | E4: =COUNTIF(main!$F$2:$AD$271,data!A4) | G4: 3 | H4: 300 | I4: 46278 | K4: 3 | M4: =IF(L4="",0,(INDEX($B$2:$B$27,MATCH(L4,$A$2:$A$27,0))-50)*(0.4)) | O4: =IF(N4="",0,INDEX($C$2:$C$27,MATCH(N4,$A$2:$A$27,0))*0.4) | Q4: 3 | S4: =IF(R4="",0,(INDEX($B$2:$B$27,MATCH(R4,$A$2:$A$27,0))-50)*(0.4)) | U4: =IF(T4="",0,INDEX($C$2:$C$27,MATCH(T4,$A$2:$A$27,0))*0.4)
A5: 4级 | B5: 180 | C5: 50 | D5: 1 | E5: =COUNTIF(main!$F$2:$AD$271,data!A5) | G5: 4 | H5: 300 | I5: 46279 | K5: 4 | M5: =IF(L5="",0,(INDEX($B$2:$B$27,MATCH(L5,$A$2:$A$27,0))-50)*(0.4)) | O5: =IF(N5="",0,INDEX($C$2:$C$27,MATCH(N5,$A$2:$A$27,0))*0.4) | Q5: 4 | S5: =IF(R5="",0,(INDEX($B$2:$B$27,MATCH(R5,$A$2:$A$27,0))-50)*(0.4)) | U5: =IF(T5="",0,INDEX($C$2:$C$27,MATCH(T5,$A$2:$A$27,0))*0.4)
A6: 5级 | B6: 190 | C6: 55 | D6: 1 | E6: =COUNTIF(main!$F$2:$AD$271,data!A6) | G6: 5 | H6: 300 | I6: 46280 | K6: 5 | M6: =IF(L6="",0,(INDEX($B$2:$B$27,MATCH(L6,$A$2:$A$27,0))-50)*(0.4)) | O6: =IF(N6="",0,INDEX($C$2:$C$27,MATCH(N6,$A$2:$A$27,0))*0.4) | Q6: 5 | S6: =IF(R6="",0,(INDEX($B$2:$B$27,MATCH(R6,$A$2:$A$27,0))-50)*(0.4)) | U6: =IF(T6="",0,INDEX($C$2:$C$27,MATCH(T6,$A$2:$A$27,0))*0.4)
A7: 6级 | B7: 200 | C7: 60 | D7: 1 | E7: =COUNTIF(main!$F$2:$AD$271,data!A7) | G7: 6 | H7: 300 | I7: 46281 | K7: 6 | M7: =IF(L7="",0,(INDEX($B$2:$B$27,MATCH(L7,$A$2:$A$27,0))-50)*(0.4)) | O7: =IF(N7="",0,INDEX($C$2:$C$27,MATCH(N7,$A$2:$A$27,0))*0.4) | Q7: 6 | S7: =IF(R7="",0,(INDEX($B$2:$B$27,MATCH(R7,$A$2:$A$27,0))-50)*(0.4)) | U7: =IF(T7="",0,INDEX($C$2:$C$27,MATCH(T7,$A$2:$A$27,0))*0.4)
A8: 草1 | B8: 150 | C8: 35 | D8: 1 | E8: =COUNTIF(main!$F$2:$AD$271,data!A8) | G8: 7 | H8: 300 | I8: 46282 | K8: 7 | M8: =IF(L8="",0,(INDEX($B$2:$B$27,MATCH(L8,$A$2:$A$27,0))-50)*(0.4)) | O8: =IF(N8="",0,INDEX($C$2:$C$27,MATCH(N8,$A$2:$A$27,0))*0.4) | Q8: 7 | S8: =IF(R8="",0,(INDEX($B$2:$B$27,MATCH(R8,$A$2:$A$27,0))-50)*(0.4)) | U8: =IF(T8="",0,INDEX($C$2:$C$27,MATCH(T8,$A$2:$A$27,0))*0.4)
A9: 草2 | B9: 150 | C9: 40 | D9: 1 | E9: =COUNTIF(main!$F$2:$AD$271,data!A9) | G9: 8 | H9: 300 | I9: 46283 | K9: 8 | M9: =IF(L9="",0,(INDEX($B$2:$B$27,MATCH(L9,$A$2:$A$27,0))-50)*(0.4)) | O9: =IF(N9="",0,INDEX($C$2:$C$27,MATCH(N9,$A$2:$A$27,0))*0.4) | Q9: 8 | S9: =IF(R9="",0,(INDEX($B$2:$B$27,MATCH(R9,$A$2:$A$27,0))-50)*(0.4)) | U9: =IF(T9="",0,INDEX($C$2:$C$27,MATCH(T9,$A$2:$A$27,0))*0.4)
A10: 草3 | B10: 150 | C10: 45 | D10: 1 | E10: =COUNTIF(main!$F$2:$AD$271,data!A10) | G10: 9 | H10: 300 | I10: 46284 | K10: 9 | M10: =IF(L10="",0,(INDEX($B$2:$B$27,MATCH(L10,$A$2:$A$27,0))-50)*(0.4)) | O10: =IF(N10="",0,INDEX($C$2:$C$27,MATCH(N10,$A$2:$A$27,0))*0.4) | Q10: 9 | S10: =IF(R10="",0,(INDEX($B$2:$B$27,MATCH(R10,$A$2:$A$27,0))-50)*(0.4)) | U10: =IF(T10="",0,INDEX($C$2:$C$27,MATCH(T10,$A$2:$A$27,0))*0.4)
A11: 草4 | B11: 150 | C11: 50 | D11: 1 | E11: =COUNTIF(main!$F$2:$AD$271,data!A11) | G11: 10 | H11: 300 | I11: 46285 | K11: 10 | M11: =IF(L11="",0,(INDEX($B$2:$B$27,MATCH(L11,$A$2:$A$27,0))-50)*(0.4)) | O11: =IF(N11="",0,INDEX($C$2:$C$27,MATCH(N11,$A$2:$A$27,0))*0.4) | Q11: 10 | S11: =IF(R11="",0,(INDEX($B$2:$B$27,MATCH(R11,$A$2:$A$27,0))-50)*(0.4)) | U11: =IF(T11="",0,INDEX($C$2:$C$27,MATCH(T11,$A$2:$A$27,0))*0.4)
A12: 草5 | B12: 150 | C12: 55 | D12: 1 | E12: =COUNTIF(main!$F$2:$AD$271,data!A12) | G12: 11 | H12: 300 | I12: 46286 | M12: =SUM(M2:M11) | O12: =SUM(O2:O11) | S12: =SUM(S2:S11) | U12: =SUM(U2:U11)
A13: 草6 | B13: 150 | C13: 60 | D13: 1 | E13: =COUNTIF(main!$F$2:$AD$271,data!A13) | G13: 12 | H13: 300 | I13: 46287 | Q13: 总 | R13: 粮草节省 | S13: =M12+S12 | T13: 经验加成 | U13: =O12+U12
A14: 遗迹 | B14: 150 | C14: 40 | D14: 1 | E14: =COUNTIF(main!$F$2:$AD$271,data!A14) | G14: 13 | H14: 300 | I14: 46288 | K14: 批量生成分表：Alt+F11, insert Module
A15: 商人 | B15: 50 | C15: 30 | D15: 1 | E15: =COUNTIF(main!$F$2:$AD$271,data!A15) | G15: 14 | H15: 300 | I15: 46289 | K15: Sub CopySheetMultipleTimes()
A16: 营地 | B16: -250 | C16: 0 | D16: -1 | E16: =COUNTIF(main!$F$2:$AD$271,data!A16) | G16: 15 | H16: 250 | I16: 46290 | K16: Dim i As Integer
A17: 大卦 | B17: 250 | C17: 300 | D17: 1 | E17: =COUNTIF(main!$F$2:$AD$271,data!A17) | G17: 16 | H17: 250 | I17: 46291 | K17: Dim n As Integer
A18: 3级卦 | B18: 170 | C18: 45 | D18: 1 | E18: =COUNTIF(main!$F$2:$AD$271,data!A18) | G18: 17 | H18: 250 | I18: 46292 | K18: Dim baseName As String
A19: 飞雷 | B19: -50 | C19: 0 | D19: 0 | E19: =COUNTIF(main!$F$2:$AD$271,data!A19) | G19: 18 | H19: 250 | I19: 46293
A20: 大boss | B20: 250 | C20: 1000 | D20: 1 | E20: =COUNTIF(main!$F$2:$AD$271,data!A20) | G20: 19 | H20: 250 | I20: 46294 | K20: n = 87 ' <-- how many new sheets you want
A21: 中boss | B21: 250 | C21: 500 | D21: 1 | E21: =COUNTIF(main!$F$2:$AD$271,data!A21) | G21: 20 | H21: 250 | I21: 46295 | K21: baseName = "3" ' <-- source sheet name
A22: 4级卦 | B22: 180 | C22: 50 | D22: 1 | E22: =COUNTIF(main!$F$2:$AD$271,data!A22) | G22: 21 | H22: 250 | I22: 46296
A23: 塔1 | B23: 150 | C23: 35 | D23: 1 | E23: =COUNTIF(main!$F$2:$AD$271,data!A23) | G23: 22 | H23: 250 | I23: 46297 | K23: For i = 1 To n
A24: 塔2 | B24: 150 | C24: 40 | D24: 1 | E24: =COUNTIF(main!$F$2:$AD$271,data!A24) | G24: 23 | H24: 250 | I24: 46298 | K24: Sheets(baseName).Copy After:=Sheets(Sheets.Count)
A25: 塔3 | B25: 150 | C25: 45 | D25: 1 | E25: =COUNTIF(main!$F$2:$AD$271,data!A25) | G25: 24 | H25: 250 | I25: 46299 | K25: ActiveSheet.Name = 3 + i
A26: 空 | B26: 0 | C26: 0 | D26: 0 | E26: =COUNTIF(main!$F$2:$AD$271,data!A26) | G26: 25 | H26: 200 | I26: 46300 | K26: Next i
A27: 历练 | B27: 50 | C27: 520 | D27: 0 | E27: =COUNTIF(main!$F$2:$AD$271,data!A27) | G27: 26 | H27: 200 | I27: 46301 | K27: End Sub
D28: 经验小计 | E28: {=SUM(C2:C27*E2:E27)} | G28: 27 | H28: 200 | I28: 46302
D29: 总经验 | E29: =E28+7000+O12+U12 | G29: 28 | H29: 200 | I29: 46303
G30: 29 | H30: 200 | I30: 46304
G31: 30 | H31: 200 | I31: 46305
G32: 31 | H32: 200 | I32: 46306
G33: 32 | H33: 200 | I33: 46307
G34: 33 | H34: 200 | I34: 46308
G35: 34 | H35: 200 | I35: 46309
G36: 35 | H36: 200 | I36: 46310
G37: 36 | H37: 200 | I37: 46311
G38: 37 | H38: 200 | I38: 46312
G39: 38 | H39: 200 | I39: 46313
G40: 39 | H40: 200 | I40: 46314
...

Sheet 1
A1: Day | B1: Date | D1: =HYPERLINK("#" &(A2+1)& "!A1","明日") | F1: 消耗粮草 | G1: 获得经验 | H1: 初始行动 | I1: 结束行动 | J1: 跳步 | AB1: =HYPERLINK("#Main!A1", "总表") | AC1: =IF(MIN(I2:I4)<0, "行动不足", "") | AD1: =IF(D4<0, "粮草不足", "")
A2: {=MID(CELL("filename",A4),FIND("]",CELL("filename",A4))+1,255)} | B2: =INDEX(data!I2:I91,MATCH(A2*1,data!G2:G91,0)) | E2: 一队 | F2: =SUM(C9:AA9) | G2: =SUM(C10:AA10) | H2: 6 | I2: 0 | J2: {=SUM(IFERROR(VALUE(MID(IF(LEFT(C8:AA8,1)="跳",C8:AA8,""),2,10)),0))}
A3: 起始粮草 | B3: 消耗粮草 | C3: 调粮 | D3: 余粮 | E3: 二队 | F3: =SUM(C12:AA12) | G3: =SUM(C13:AA13) | H3: 6 | I3: 0 | J3: {=SUM(IFERROR(VALUE(MID(IF(LEFT(C11:AA11,1)="跳",C11:AA11,""),2,10)),0))}
A4: 6800 | B4: =SUM(F2:F4) | C4: 0 | D4: =A4-B4+C4 | E4: 三队 | F4: =SUM(C15:AA15) | G4: =SUM(C16:AA16) | H4: 6 | I4: 0 | J4: {=SUM(IFERROR(VALUE(MID(IF(LEFT(C14:AA14,1)="跳",C14:AA14,""),2,10)),0))}
A5: 起始经验 | B5: 获得经验 | C5: 调分 | D5: 经验
A6: 0 | B6: =SUM(G2:G4) | C6: 500 | D6: =A6+B6+C6 | AC6: 跳 | AD6: 2
C7: 1 | D7: 2 | E7: 3 | F7: 4 | G7: 5 | H7: 6 | I7: 7 | J7: 8 | K7: 9 | L7: 10 | M7: 11 | N7: 12 | O7: 13 | P7: 14 | Q7: 15 | R7: 16 | S7: 17 | T7: 18 | U7: 19 | V7: 20 | W7: 21 | X7: 22 | Y7: 23 | Z7: 24 | AA7: 25 | AC7: =_xlfn.CONCAT(AC6,AD6)
A8: 一队 | B8: 操作流 | C8: 1级 | D8: 1级 | E8: 1级 | F8: 1级 | G8: 1级 | H8: 草1 | AC8: 1级
B9: 粮草 | C9: =IF(LEFT(C8,1)="跳",RIGHT(C8,LEN(C8)-1)*10*IF(C$17="是",0.8,1),IF(C8="营地",-INDEX(data!$H$2:$H$91,MATCH($A$2*1,data!$G$2:$G$91,0))+50*IF(C$17="是",0.8,1),IFERROR(INDEX(data!$B$2:$B$27,MATCH(C8,data!$A$2:$A$27,0)),0)*IF(C$17="是",0.8,1))) | D9: =IF(LEFT(D8,1)="跳",RIGHT(D8,LEN(D8)-1)*10*IF(D$17="是",0.8,1),IF(D8="营地",-INDEX(data!$H$2:$H$91,MATCH($A$2*1,data!$G$2:$G$91,0))+50*IF(D$17="是",0.8,1),IFERROR(INDEX(data!$B$2:$B$27,MATCH(D8,data!$A$2:$A$27,0)),0)*IF(D$17="是",0.8,1))) | E9: =IF(LEFT(E8,1)="跳",RIGHT(E8,LEN(E8)-1)*10*IF(E$17="是",0.8,1),IF(E8="营地",-INDEX(data!$H$2:$H$91,MATCH($A$2*1,data!$G$2:$G$91,0))+50*IF(E$17="是",0.8,1),IFERROR(INDEX(data!$B$2:$B$27,MATCH(E8,data!$A$2:$A$27,0)),0)*IF(E$17="是",0.8,1))) | F9: =IF(LEFT(F8,1)="跳",RIGHT(F8,LEN(F8)-1)*10*IF(F$17="是",0.8,1),IF(F8="营地",-INDEX(data!$H$2:$H$91,MATCH($A$2*1,data!$G$2:$G$91,0))+50*IF(F$17="是",0.8,1),IFERROR(INDEX(data!$B$2:$B$27,MATCH(F8,data!$A$2:$A$27,0)),0)*IF(F$17="是",0.8,1))) | G9: =IF(LEFT(G8,1)="跳",RIGHT(G8,LEN(G8)-1)*10*IF(G$17="是",0.8,1),IF(G8="营地",-INDEX(data!$H$2:$H$91,MATCH($A$2*1,data!$G$2:$G$91,0))+50*IF(G$17="是",0.8,1),IFERROR(INDEX(data!$B$2:$B$27,MATCH(G8,data!$A$2:$A$27,0)),0)*IF(G$17="是",0.8,1))) | H9: =IF(LEFT(H8,1)="跳",RIGHT(H8,LEN(H8)-1)*10*IF(H$17="是",0.8,1),IF(H8="营地",-INDEX(data!$H$2:$H$91,MATCH($A$2*1,data!$G$2:$G$91,0))+50*IF(H$17="是",0.8,1),IFERROR(INDEX(data!$B$2:$B$27,MATCH(H8,data!$A$2:$A$27,0)),0)*IF(H$17="是",0.8,1))) | I9: =IF(LEFT(I8,1)="跳",RIGHT(I8,LEN(I8)-1)*10*IF(I$17="是",0.8,1),IF(I8="营地",-INDEX(data!$H$2:$H$91,MATCH($A$2*1,data!$G$2:$G$91,0))+50*IF(I$17="是",0.8,1),IFERROR(INDEX(data!$B$2:$B$27,MATCH(I8,data!$A$2:$A$27,0)),0)*IF(I$17="是",0.8,1))) | J9: =IF(LEFT(J8,1)="跳",RIGHT(J8,LEN(J8)-1)*10*IF(J$17="是",0.8,1),IF(J8="营地",-INDEX(data!$H$2:$H$91,MATCH($A$2*1,data!$G$2:$G$91,0))+50*IF(J$17="是",0.8,1),IFERROR(INDEX(data!$B$2:$B$27,MATCH(J8,data!$A$2:$A$27,0)),0)*IF(J$17="是",0.8,1))) | ... AA9: =IF(LEFT(AA8,1)="跳",RIGHT(AA8,LEN(AA8)-1)*10*IF(AA$17="是",0.8,1),IF(AA8="营地",-INDEX(data!$H$2:$H$91,MATCH($A$2*1,data!$G$2:$G$91,0))+50*IF(AA$17="是",0.8,1),IFERROR(INDEX(data!$B$2:$B$27,MATCH(AA8,data!$A$2:$A$27,0)),0)*IF(AA$17="是",0.8,1))) | AC9: 2级
B10: 经验 | C10: =IFERROR(INDEX(data!$C$2:$C$27,MATCH(C8,data!$A$2:$A$27,0)),0) | D10: =IFERROR(INDEX(data!$C$2:$C$27,MATCH(D8,data!$A$2:$A$27,0)),0) | E10: =IFERROR(INDEX(data!$C$2:$C$27,MATCH(E8,data!$A$2:$A$27,0)),0) | F10: =IFERROR(INDEX(data!$C$2:$C$27,MATCH(F8,data!$A$2:$A$27,0)),0) | G10: =IFERROR(INDEX(data!$C$2:$C$27,MATCH(G8,data!$A$2:$A$27,0)),0) | H10: =IFERROR(INDEX(data!$C$2:$C$27,MATCH(H8,data!$A$2:$A$27,0)),0) | I10: =IFERROR(INDEX(data!$C$2:$C$27,MATCH(I8,data!$A$2:$A$27,0)),0) | J10: =IFERROR(INDEX(data!$C$2:$C$27,MATCH(J8,data!$A$2:$A$27,0)),0) | ... AA10: =IFERROR(INDEX(data!$C$2:$C$27,MATCH(AA8,data!$A$2:$A$27,0)),0) | AC10: 3级
A11: 二队 | B11: 操作流 | C11: 1级 | D11: 商人 | E11: 1级 | F11: 1级 | G11: 1级 | H11: 1级 | AC11: 4级
B12: 粮草 | C12: =IF(LEFT(C11,1)="跳",RIGHT(C11,LEN(C11)-1)*10*IF(C$17="是",0.8,1),IF(C11="营地",-INDEX(data!$H$2:$H$91,MATCH($A$2*1,data!$G$2:$G$91,0))+50*IF(C$17="是",0.8,1),IFERROR(INDEX(data!$B$2:$B$27,MATCH(C11,data!$A$2:$A$27,0)),0)*IF(C$17="是",0.8,1))) | D12: =IF(LEFT(D11,1)="跳",RIGHT(D11,LEN(D11)-1)*10*IF(D$17="是",0.8,1),IF(D11="营地",-INDEX(data!$H$2:$H$91,MATCH($A$2*1,data!$G$2:$G$91,0))+50*IF(D$17="是",0.8,1),IFERROR(INDEX(data!$B$2:$B$27,MATCH(D11,data!$A$2:$A$27,0)),0)*IF(D$17="是",0.8,1))) | E12: =IF(LEFT(E11,1)="跳",RIGHT(E11,LEN(E11)-1)*10*IF(E$17="是",0.8,1),IF(E11="营地",-INDEX(data!$H$2:$H$91,MATCH($A$2*1,data!$G$2:$G$91,0))+50*IF(E$17="是",0.8,1),IFERROR(INDEX(data!$B$2:$B$27,MATCH(E11,data!$A$2:$A$27,0)),0)*IF(E$17="是",0.8,1))) | F12: =IF(LEFT(F11,1)="跳",RIGHT(F11,LEN(F11)-1)*10*IF(F$17="是",0.8,1),IF(F11="营地",-INDEX(data!$H$2:$H$91,MATCH($A$2*1,data!$G$2:$G$91,0))+50*IF(F$17="是",0.8,1),IFERROR(INDEX(data!$B$2:$B$27,MATCH(F11,data!$A$2:$A$27,0)),0)*IF(F$17="是",0.8,1))) | G12: =IF(LEFT(G11,1)="跳",RIGHT(G11,LEN(G11)-1)*10*IF(G$17="是",0.8,1),IF(G11="营地",-INDEX(data!$H$2:$H$91,MATCH($A$2*1,data!$G$2:$G$91,0))+50*IF(G$17="是",0.8,1),IFERROR(INDEX(data!$B$2:$B$27,MATCH(G11,data!$A$2:$A$27,0)),0)*IF(G$17="是",0.8,1))) | H12: =IF(LEFT(H11,1)="跳",RIGHT(H11,LEN(H11)-1)*10*IF(H$17="是",0.8,1),IF(H11="营地",-INDEX(data!$H$2:$H$91,MATCH($A$2*1,data!$G$2:$G$91,0))+50*IF(H$17="是",0.8,1),IFERROR(INDEX(data!$B$2:$B$27,MATCH(H11,data!$A$2:$A$27,0)),0)*IF(H$17="是",0.8,1))) | I12: =IF(LEFT(I11,1)="跳",RIGHT(I11,LEN(I11)-1)*10*IF(I$17="是",0.8,1),IF(I11="营地",-INDEX(data!$H$2:$H$91,MATCH($A$2*1,data!$G$2:$G$91,0))+50*IF(I$17="是",0.8,1),IFERROR(INDEX(data!$B$2:$B$27,MATCH(I11,data!$A$2:$A$27,0)),0)*IF(I$17="是",0.8,1))) | J12: =IF(LEFT(J11,1)="跳",RIGHT(J11,LEN(J11)-1)*10*IF(J$17="是",0.8,1),IF(J11="营地",-INDEX(data!$H$2:$H$91,MATCH($A$2*1,data!$G$2:$G$91,0))+50*IF(J$17="是",0.8,1),IFERROR(INDEX(data!$B$2:$B$27,MATCH(J11,data!$A$2:$A$27,0)),0)*IF(J$17="是",0.8,1))) | ... AA12: =IF(LEFT(AA11,1)="跳",RIGHT(AA11,LEN(AA11)-1)*10*IF(AA$17="是",0.8,1),IF(AA11="营地",-INDEX(data!$H$2:$H$91,MATCH($A$2*1,data!$G$2:$G$91,0))+50*IF(AA$17="是",0.8,1),IFERROR(INDEX(data!$B$2:$B$27,MATCH(AA11,data!$A$2:$A$27,0)),0)*IF(AA$17="是",0.8,1))) | AC12: 5级
B13: 经验 | C13: =IFERROR(INDEX(data!$C$2:$C$27,MATCH(C11,data!$A$2:$A$27,0)),0) | D13: =IFERROR(INDEX(data!$C$2:$C$27,MATCH(D11,data!$A$2:$A$27,0)),0) | E13: =IFERROR(INDEX(data!$C$2:$C$27,MATCH(E11,data!$A$2:$A$27,0)),0) | F13: =IFERROR(INDEX(data!$C$2:$C$27,MATCH(F11,data!$A$2:$A$27,0)),0) | G13: =IFERROR(INDEX(data!$C$2:$C$27,MATCH(G11,data!$A$2:$A$27,0)),0) | H13: =IFERROR(INDEX(data!$C$2:$C$27,MATCH(H11,data!$A$2:$A$27,0)),0) | I13: =IFERROR(INDEX(data!$C$2:$C$27,MATCH(I11,data!$A$2:$A$27,0)),0) | J13: =IFERROR(INDEX(data!$C$2:$C$27,MATCH(J11,data!$A$2:$A$27,0)),0) | ... AA13: =IFERROR(INDEX(data!$C$2:$C$27,MATCH(AA11,data!$A$2:$A$27,0)),0) | AC13: 6级
A14: 三队 | B14: 操作流 | C14: 商人 | D14: 1级 | E14: 1级 | F14: 1级 | G14: 1级 | H14: 草2 | AC14: 草1
B15: 粮草 | C15: =IF(LEFT(C14,1)="跳",RIGHT(C14,LEN(C14)-1)*10*IF(C$17="是",0.8,1),IF(C14="营地",-INDEX(data!$H$2:$H$91,MATCH($A$2*1,data!$G$2:$G$91,0))+50*IF(C$17="是",0.8,1),IFERROR(INDEX(data!$B$2:$B$27,MATCH(C14,data!$A$2:$A$27,0)),0)*IF(C$17="是",0.8,1))) | D15: =IF(LEFT(D14,1)="跳",RIGHT(D14,LEN(D14)-1)*10*IF(D$17="是",0.8,1),IF(D14="营地",-INDEX(data!$H$2:$H$91,MATCH($A$2*1,data!$G$2:$G$91,0))+50*IF(D$17="是",0.8,1),IFERROR(INDEX(data!$B$2:$B$27,MATCH(D14,data!$A$2:$A$27,0)),0)*IF(D$17="是",0.8,1))) | E15: =IF(LEFT(E14,1)="跳",RIGHT(E14,LEN(E14)-1)*10*IF(E$17="是",0.8,1),IF(E14="营地",-INDEX(data!$H$2:$H$91,MATCH($A$2*1,data!$G$2:$G$91,0))+50*IF(E$17="是",0.8,1),IFERROR(INDEX(data!$B$2:$B$27,MATCH(E14,data!$A$2:$A$27,0)),0)*IF(E$17="是",0.8,1))) | F15: =IF(LEFT(F14,1)="跳",RIGHT(F14,LEN(F14)-1)*10*IF(F$17="是",0.8,1),IF(F14="营地",-INDEX(data!$H$2:$H$91,MATCH($A$2*1,data!$G$2:$G$91,0))+50*IF(F$17="是",0.8,1),IFERROR(INDEX(data!$B$2:$B$27,MATCH(F14,data!$A$2:$A$27,0)),0)*IF(F$17="是",0.8,1))) | G15: =IF(LEFT(G14,1)="跳",RIGHT(G14,LEN(G14)-1)*10*IF(G$17="是",0.8,1),IF(G14="营地",-INDEX(data!$H$2:$H$91,MATCH($A$2*1,data!$G$2:$G$91,0))+50*IF(G$17="是",0.8,1),IFERROR(INDEX(data!$B$2:$B$27,MATCH(G14,data!$A$2:$A$27,0)),0)*IF(G$17="是",0.8,1))) | H15: =IF(LEFT(H14,1)="跳",RIGHT(H14,LEN(H14)-1)*10*IF(H$17="是",0.8,1),IF(H14="营地",-INDEX(data!$H$2:$H$91,MATCH($A$2*1,data!$G$2:$G$91,0))+50*IF(H$17="是",0.8,1),IFERROR(INDEX(data!$B$2:$B$27,MATCH(H14,data!$A$2:$A$27,0)),0)*IF(H$17="是",0.8,1))) | I15: =IF(LEFT(I14,1)="跳",RIGHT(I14,LEN(I14)-1)*10*IF(I$17="是",0.8,1),IF(I14="营地",-INDEX(data!$H$2:$H$91,MATCH($A$2*1,data!$G$2:$G$91,0))+50*IF(I$17="是",0.8,1),IFERROR(INDEX(data!$B$2:$B$27,MATCH(I14,data!$A$2:$A$27,0)),0)*IF(I$17="是",0.8,1))) | J15: =IF(LEFT(J14,1)="跳",RIGHT(J14,LEN(J14)-1)*10*IF(J$17="是",0.8,1),IF(J14="营地",-INDEX(data!$H$2:$H$91,MATCH($A$2*1,data!$G$2:$G$91,0))+50*IF(J$17="是",0.8,1),IFERROR(INDEX(data!$B$2:$B$27,MATCH(J14,data!$A$2:$A$27,0)),0)*IF(J$17="是",0.8,1))) | ... AA15: =IF(LEFT(AA14,1)="跳",RIGHT(AA14,LEN(AA14)-1)*10*IF(AA$17="是",0.8,1),IF(AA14="营地",-INDEX(data!$H$2:$H$91,MATCH($A$2*1,data!$G$2:$G$91,0))+50*IF(AA$17="是",0.8,1),IFERROR(INDEX(data!$B$2:$B$27,MATCH(AA14,data!$A$2:$A$27,0)),0)*IF(AA$17="是",0.8,1))) | AC15: 草2
